Workbook

Sheet benchmark
A1: model | B1: run | C1: solver | D1: version | E1: exit_status | F1: exit_code | G1: obj1 | H1: obj2 | I1: iterations | J1: obj_eval | K1: grad_eval | L1: eq_eval | M1: ineq_eval | N1: eq_jac | O1: ineq_jac | P1: hess_eval | Q1: constraint_violation_unscaled | R1: cpu_ipopt | S1: cpu_nlp | T1: total_vars | U1: total_eq | V1: total_ineq | W1: ampl_elapsed_time | X1: ampl_system_time | Y1: ampl_user_time | Z1: ampl_time | AA1: solve_elapsed_time | AB1: solve_system_time | AC1: solve_user_time | AD1: solve_time | AE1: nvars | AF1: snvars | AG1: ncons | AH1: sncons | AI1: tic | AJ1: toc
A2: acrobot | B2: 1 | C2: Ipopt | D2: 3.12.13 | E2: solved | F2: 0 | G2: 69.877642 | I2: 14 | J2: 26 | K2: 15 | L2: 26 | M2: 26 | N2: 15 | O2: 15 | P2: 14 | Q2: 2.8421709e-14 | R2: 0.01 | S2: 0.002 | T2: 132 | U2: 116 | V2: 18 | W2: 0.173 | X2: 0.03125 | Y2: 0 | Z2: 0.03125 | AA2: 0.046 | AB2: 0.015625 | AC2: 0.015625 | AD2: 0.03125 | AE2: 8779 | AF2: 132 | AG2: 8824 | AH2: 134 | AI2: 0.0097078704 | AJ2: 0.0097116898
A3: acrobot | B3: 2 | C3: Ipopt | D3: 3.12.13 | E3: solved | F3: 0 | G3: 69.877642 | I3: 14 | J3: 26 | K3: 15 | L3: 26 | M3: 26 | N3: 15 | O3: 15 | P3: 14 | Q3: 2.8421709e-14 | R3: 0.016 | S3: 0 | T3: 132 | U3: 116 | V3: 18 | W3: 0.187 | X3: 0.015625 | Y3: 0.015625 | Z3: 0.03125 | AA3: 0.063 | AB3: 0.015625 | AC3: 0 | AD3: 0.015625 | AE3: 8779 | AF3: 132 | AG3: 8824 | AH3: 134 | AI3: 0.0097136574 | AJ3: 0.0097184028
A4: acrobot | B4: 3 | C4: Ipopt | D4: 3.12.13 | E4: solved | F4: 0 | G4: 69.877642 | I4: 14 | J4: 26 | K4: 15 | L4: 26 | M4: 26 | N4: 15 | O4: 15 | P4: 14 | Q4: 2.8421709e-14 | R4: 0.01 | S4: 0.004 | T4: 132 | U4: 116 | V4: 18 | W4: 0.234 | X4: 0 | Y4: 0.03125 | Z4: 0.03125 | AA4: 0.032 | AB4: 0.015625 | AC4: 0 | AD4: 0.015625 | AE4: 8779 | AF4: 132 | AG4: 8824 | AH4: 134 | AI4: 0.0097202546 | AJ4: 0.009724537
A5: acrobot | B5: 4 | C5: Ipopt | D5: 3.12.13 | E5: solved | F5: 0 | G5: 69.877642 | I5: 14 | J5: 26 | K5: 15 | L5: 26 | M5: 26 | N5: 15 | O5: 15 | P5: 14 | Q5: 2.8421709e-14 | R5: 0.013 | S5: 0.002 | T5: 132 | U5: 116 | V5: 18 | W5: 0.172 | X5: 0.03125 | Y5: 0.03125 | Z5: 0.0625 | AA5: 0.031 | AB5: 0 | AC5: 0.015625 | AD5: 0.015625 | AE5: 8779 | AF5: 132 | AG5: 8824 | AH5: 134 | AI5: 0.0097263889 | AJ5: 0.0097302083
A6: acrobot | B6: 5 | C6: Ipopt | D6: 3.12.13 | E6: solved | F6: 0 | G6: 69.877642 | I6: 14 | J6: 26 | K6: 15 | L6: 26 | M6: 26 | N6: 15 | O6: 15 | P6: 14 | Q6: 2.8421709e-14 | R6: 0.012 | S6: 0.003 | T6: 132 | U6: 116 | V6: 18 | W6: 0.202 | X6: 0.03125 | Y6: 0 | Z6: 0.03125 | AA6: 0.032 | AB6: 0.015625 | AC6: 0 | AD6: 0.015625 | AE6: 8779 | AF6: 132 | AG6: 8824 | AH6: 134 | AI6: 0.0097319444 | AJ6: 0.0097357639
A7: acrobot | B7: 6 | C7: Ipopt | D7: 3.12.13 | E7: solved | F7: 0 | G7: 69.877642 | I7: 14 | J7: 26 | K7: 15 | L7: 26 | M7: 26 | N7: 15 | O7: 15 | P7: 14 | Q7: 2.8421709e-14 | R7: 0.011 | S7: 0.002 | T7: 132 | U7: 116 | V7: 18 | W7: 0.187 | X7: 0.03125 | Y7: 0.03125 | Z7: 0.0625 | AA7: 0.031 | AB7: 0 | AC7: 0.015625 | AD7: 0.015625 | AE7: 8779 | AF7: 132 | AG7: 8824 | AH7: 134 | AI7: 0.009737963 | AJ7: 0.0097416667
A8: acrobot | B8: 7 | C8: Ipopt | D8: 3.12.13 | E8: solved | F8: 0 | G8: 69.877642 | I8: 14 | J8: 26 | K8: 15 | L8: 26 | M8: 26 | N8: 15 | O8: 15 | P8: 14 | Q8: 2.8421709e-14 | R8: 0.02 | S8: 0.001 | T8: 132 | U8: 116 | V8: 18 | W8: 0.235 | X8: 0.015625 | Y8: 0.03125 | Z8: 0.046875 | AA8: 0.062 | AB8: 0.046875 | AC8: 0 | AD8: 0.046875 | AE8: 8779 | AF8: 132 | AG8: 8824 | AH8: 134 | AI8: 0.0097435185 | AJ8: 0.0097483796
A9: acrobot | B9: 8 | C9: Ipopt | D9: 3.12.13 | E9: solved | F9: 0 | G9: 69.877642 | I9: 14 | J9: 26 | K9: 15 | L9: 26 | M9: 26 | N9: 15 | O9: 15 | P9: 14 | Q9: 2.8421709e-14 | R9: 0.008 | S9: 0.006 | T9: 132 | U9: 116 | V9: 18 | W9: 0.173 | X9: 0 | Y9: 0.03125 | Z9: 0.03125 | AA9: 0.046 | AB9: 0.015625 | AC9: 0 | AD9: 0.015625 | AE9: 8779 | AF9: 132 | AG9: 8824 | AH9: 134 | AI9: 0.0097509259 | AJ9: 0.0097550926
A10: acrobot | B10: 9 | C10: Ipopt | D10: 3.12.13 | E10: solved | F10: 0 | G10: 69.877642 | I10: 14 | J10: 26 | K10: 15 | L10: 26 | M10: 26 | N10: 15 | O10: 15 | P10: 14 | Q10: 2.8421709e-14 | R10: 0.013 | S10: 0.001 | T10: 132 | U10: 116 | V10: 18 | W10: 0.173 | X10: 0 | Y10: 0.046875 | Z10: 0.046875 | AA10: 0.046 | AB10: 0 | AC10: 0.015625 | AD10: 0.015625 | AE10: 8779 | AF10: 132 | AG10: 8824 | AH10: 134 | AI10: 0.0097570602 | AJ10: 0.0097608796
A11: acrobot | B11: 10 | C11: Ipopt | D11: 3.12.13 | E11: solved | F11: 0 | G11: 69.877642 | I11: 14 | J11: 26 | K11: 15 | L11: 26 | M11: 26 | N11: 15 | O11: 15 | P11: 14 | Q11: 2.8421709e-14 | R11: 0.012 | S11: 0.002 | T11: 132 | U11: 116 | V11: 18 | W11: 0.171 | X11: 0 | Y11: 0.078125 | Z11: 0.078125 | AA11: 0.032 | AB11: 0 | AC11: 0.015625 | AD11: 0.015625 | AE11: 8779 | AF11: 132 | AG11: 8824 | AH11: 134 | AI11: 0.0097622685 | AJ11: 0.009766088
A12: cart-pendulum-time | B12: 1 | C12: Ipopt | D12: 3.12.13 | E12: solved | F12: 0 | G12: 1.1459373 | I12: 30 | J12: 50 | K12: 31 | L12: 50 | M12: 0 | N12: 31 | O12: 0 | P12: 30 | Q12: 6.2101435e-12 | R12: 0.017 | S12: 0 | T12: 80 | U12: 74 | V12: 0 | W12: 0.172 | X12: 0.03125 | Y12: 0.015625 | Z12: 0.046875 | AA12: 0.047 | AB12: 0.015625 | AC12: 0 | AD12: 0.015625 | AE12: 4388 | AF12: 80 | AG12: 4413 | AH12: 74 | AI12: 0.0097679398 | AJ12: 0.0097717593
A13: cart-pendulum-time | B13: 2 | C13: Ipopt | D13: 3.12.13 | E13: solved | F13: 0 | G13: 1.1459373 | I13: 30 | J13: 50 | K13: 31 | L13: 50 | M13: 0 | N13: 31 | O13: 0 | P13: 30 | Q13: 6.2101435e-12 | R13: 0.017 | S13: 0 | T13: 80 | U13: 74 | V13: 0 | W13: 0.173 | X13: 0.015625 | Y13: 0 | Z13: 0.015625 | AA13: 0.031 | AB13: 0.015625 | AC13: 0.03125 | AD13: 0.046875 | AE13: 4388 | AF13: 80 | AG13: 4413 | AH13: 74 | AI13: 0.0097736111 | AJ13: 0.0097770833
... A61: five-link-tropic | B61: 10 | C61: Ipopt | D61: 3.12.13 | E61: solved | F61: 0 | G61: 5.7300002 | I61: 206 | J61: 273 | K61: 207 | L61: 273 | M61: 273 | N61: 210 | O61: 210 | P61: 206 | Q61: 1.4438672e-11 | R61: 18.65 | S61: 12.046 | T61: 2345 | U61: 2331 | V61: 206 | W61: 1.344 | X61: 0.25 | Y61: 1 | Z61: 1.25 | AA61: 30.89 | AB61: 0.453125 | AC61: 30.390625 | AD61: 30.84375 | AE61: 371155 | AF61: 2345 | AG61: 372492 | AH61: 2537 | AI61: 0.013629051 | AJ61: 0.014024537
A62: grasp-cbc | B62: 1 | C62: cbc | D62: 2.10.12 | E62: failure | F62: 500 | G62: 0 | W62: 0.187 | X62: 0.015625 | Y62: 0.0625 | Z62: 0.078125 | AA62: 0.016 | AB62: 0.015625 | AC62: 0.015625 | AD62: 0.03125 | AE62: 29729 | AF62: 73 | AG62: 29766 | AH62: 80 | AI62: 0.014026389 | AJ62: 0.014030324
A63: grasp-cbc | B63: 2 | C63: cbc | D63: 2.10.12 | E63: failure | F63: 500 | G63: 0 | W63: 0.25 | X63: 0.015625 | Y63: 0.078125 | Z63: 0.09375 | AA63: 0.016 | AB63: 0 | AC63: 0 | AD63: 0 | AE63: 29729 | AF63: 73 | AG63: 29766 | AH63: 80 | AI63: 0.014032176 | AJ63: 0.014036343
A64: grasp-cbc | B64: 3 | C64: cbc | D64: 2.10.12 | E64: failure | F64: 500 | G64: 0 | W64: 0.187 | X64: 0.046875 | Y64: 0.0625 | Z64: 0.109375 | AA64: 0.031 | AB64: 0 | AC64: 0 | AD64: 0 | AE64: 29729 | AF64: 73 | AG64: 29766 | AH64: 80 | AI64: 0.014038079 | AJ64: 0.014041782
A65: grasp-cbc | B65: 4 | C65: cbc | D65: 2.10.12 | E65: failure | F65: 500 | G65: 0 | W65: 0.234 | X65: 0.046875 | Y65: 0.0625 | Z65: 0.109375 | AA65: 0.032 | AB65: 0.015625 | AC65: 0 | AD65: 0.015625 | AE65: 29729 | AF65: 73 | AG65: 29766 | AH65: 80 | AI65: 0.014043519 | AJ65: 0.014047801
A66: grasp-cbc | B66: 5 | C66: cbc | D66: 2.10.12 | E66: failure | F66: 500 | G66: 0 | W66: 0.219 | X66: 0.03125 | Y66: 0.0625 | Z66: 0.09375 | AA66: 0.016 | AB66: 0.015625 | AC66: 0 | AD66: 0.015625 | AE66: 29729 | AF66: 73 | AG66: 29766 | AH66: 80 | AI66: 0.014049537 | AJ66: 0.014053241
A67: grasp-cbc | B67: 6 | C67: cbc | D67: 2.10.12 | E67: failure | F67: 500 | G67: 0 | W67: 0.249 | X67: 0.046875 | Y67: 0.046875 | Z67: 0.09375 | AA67: 0.032 | AB67: 0.03125 | AC67: 0 | AD67: 0.03125 | AE67: 29729 | AF67: 73 | AG67: 29766 | AH67: 80 | AI67: 0.014055093 | AJ67: 0.014059375
A68: grasp-cbc | B68: 7 | C68: cbc | D68: 2.10.12 | E68: failure | F68: 500 | G68: 0 | W68: 0.203 | X68: 0.015625 | Y68: 0.0625 | Z68: 0.078125 | AA68: 0.032 | AB68: 0 | AC68: 0.03125 | AD68: 0.03125 | AE68: 29729 | AF68: 73 | AG68: 29766 | AH68: 80 | AI68: 0.014061458 | AJ68: 0.014065278
A69: grasp-cbc | B69: 8 | C69: cbc | D69: 2.10.12 | E69: failure | F69: 500 | G69: 0 | W69: 0.172 | X69: 0.046875 | Y69: 0.078125 | Z69: 0.125 | AA69: 0.031 | AB69: 0.015625 | AC69: 0.015625 | AD69: 0.03125 | AE69: 29729 | AF69: 73 | AG69: 29766 | AH69: 80 | AI69: 0.014067014 | AJ69: 0.014070602
A70: grasp-cbc | B70: 9 | C70: cbc | D70: 2.10.12 | E70: failure | F70: 500 | G70: 0 | W70: 0.203 | X70: 0.0625 | Y70: 0.03125 | Z70: 0.09375 | AA70: 0.031 | AB70: 0 | AC70: 0 | AD70: 0 | AE70: 29729 | AF70: 73 | AG70: 29766 | AH70: 80 | AI70: 0.014072685 | AJ70: 0.014076505
A71: grasp-cbc | B71: 10 | C71: cbc | D71: 2.10.12 | E71: failure | F71: 500 | G71: 0 | W71: 0.203 | X71: 0.046875 | Y71: 0.0625 | Z71: 0.109375 | AA71: 0.047 | AB71: 0 | AC71: 0.015625 | AD71: 0.015625 | AE71: 29729 | AF71: 73 | AG71: 29766 | AH71: 80 | AI71: 0.014078356 | AJ71: 0.014082639
A72: grasp-conopt | B72: 1 | E72: solved? | F72: 100 | G72: 6 | W72: 0.188 | X72: 0.03125 | Y72: 0.09375 | Z72: 0.125 | AA72: 0.109 | AB72: 0.015625 | AC72: 0.03125 | AD72: 0.046875 | AE72: 29729 | AF72: 73 | AG72: 29766 | AH72: 80 | AI72: 0.014084606 | AJ72: 0.014089468
A73: grasp-conopt | B73: 2 | E73: solved? | F73: 100 | G73: 6 | W73: 0.219 | X73: 0.03125 | Y73: 0.109375 | Z73: 0.140625 | AA73: 0.078 | AB73: 0 | AC73: 0 | AD73: 0 | AE73: 29729 | AF73: 73 | AG73: 29766 | AH73: 80 | AI73: 0.014091204 | AJ73: 0.014095833
A74: grasp-conopt | B74: 3 | E74: solved? | F74: 100 | G74: 6 | W74: 0.235 | X74: 0.046875 | Y74: 0.078125 | Z74: 0.125 | AA74: 0.125 | AB74: 0.015625 | AC74: 0.015625 | AD74: 0.03125 | AE74: 29729 | AF74: 73 | AG74: 29766 | AH74: 80 | AI74: 0.014097569 | AJ74: 0.014103356
A75: grasp-conopt | B75: 4 | E75: solved? | F75: 100 | G75: 6 | W75: 0.234 | X75: 0.046875 | Y75: 0.0625 | Z75: 0.109375 | AA75: 0.078 | AB75: 0 | AC75: 0 | AD75: 0 | AE75: 29729 | AF75: 73 | AG75: 29766 | AH75: 80 | AI75: 0.014104977 | AJ75: 0.014109375
A76: grasp-conopt | B76: 5 | E76: solved? | F76: 100 | G76: 6 | W76: 0.172 | X76: 0 | Y76: 0.09375 | Z76: 0.09375 | AA76: 0.344 | AB76: 0.015625 | AC76: 0 | AD76: 0.015625 | AE76: 29729 | AF76: 73 | AG76: 29766 | AH76: 80 | AI76: 0.014111806 | AJ76: 0.014118981
A77: grasp-conopt | B77: 6 | E77: solved? | F77: 100 | G77: 6 | W77: 0.234 | X77: 0.03125 | Y77: 0.109375 | Z77: 0.140625 | AA77: 0.188 | AB77: 0 | AC77: 0.03125 | AD77: 0.03125 | AE77: 29729 | AF77: 73 | AG77: 29766 | AH77: 80 | AI77: 0.014120602 | AJ77: 0.014126389
A78: grasp-conopt | B78: 7 | E78: solved? | F78: 100 | G78: 6 | W78: 0.203 | X78: 0.03125 | Y78: 0.0625 | Z78: 0.09375 | AA78: 0.063 | AB78: 0.015625 | AC78: 0.015625 | AD78: 0.03125 | AE78: 29729 | AF78: 73 | AG78: 29766 | AH78: 80 | AI78: 0.014128704 | AJ78: 0.014132755
A79: grasp-conopt | B79: 8 | E79: solved? | F79: 100 | G79: 6 | W79: 0.219 | X79: 0.046875 | Y79: 0.078125 | Z79: 0.125 | AA79: 0.063 | AB79: 0.046875 | AC79: 0.03125 | AD79: 0.078125 | AE79: 29729 | AF79: 73 | AG79: 29766 | AH79: 80 | AI79: 0.014134606 | AJ79: 0.01413912
A80: grasp-conopt | B80: 9 | E80: solved? | F80: 100 | G80: 6 | W80: 0.25 | X80: 0.0625 | Y80: 0.0625 | Z80: 0.125 | AA80: 0.078 | AB80: 0.046875 | AC80: 0.015625 | AD80: 0.0625 | AE80: 29729 | AF80: 73 | AG80: 29766 | AH80: 80 | AI80: 0.014140625 | AJ80: 0.01414537
A81: grasp-conopt | B81: 10 | E81: solved? | F81: 100 | G81: 6 | W81: 0.203 | X81: 0 | Y81: 0.09375 | Z81: 0.09375 | AA81: 0.172 | AB81: 0 | AC81: 0 | AD81: 0 | AE81: 29729 | AF81: 73 | AG81: 29766 | AH81: 80 | AI81: 0.014146875 | AJ81: 0.014152315
A82: grasp-gurobi | B82: 1 | C82: Gurobi | D82: 12.0.3 | E82: solved | F82: 0 | G82: 4 | W82: 0.219 | X82: 0.03125 | Y82: 0.09375 | Z82: 0.125 | AA82: 0.328 | AB82: 0.25 | AC82: 1.671875 | AD82: 1.921875 | AE82: 29729 | AF82: 73 | AG82: 29766 | AH82: 80 | AI82: 0.014154398 | AJ82: 0.014161806
A83: grasp-gurobi | B83: 2 | C83: Gurobi | D83: 12.0.3 | E83: solved | F83: 0 | G83: 4 | W83: 0.203 | X83: 0.03125 | Y83: 0.078125 | Z83: 0.109375 | AA83: 0.265 | AB83: 0.375 | AC83: 1.640625 | AD83: 2.015625 | AE83: 29729 | AF83: 73 | AG83: 29766 | AH83: 80 | AI83: 0.01416331 | AJ83: 0.014170023
A84: grasp-gurobi | B84: 3 | C84: Gurobi | D84: 12.0.3 | E84: solved | F84: 0 | G84: 4 | W84: 0.188 | X84: 0.0625 | Y84: 0.0625 | Z84: 0.125 | AA84: 0.25 | AB84: 0.5 | AC84: 1.546875 | AD84: 2.046875 | AE84: 29729 | AF84: 73 | AG84: 29766 | AH84: 80 | AI84: 0.014171644 | AJ84: 0.014177546
A85: grasp-gurobi | B85: 4 | C85: Gurobi | D85: 12.0.3 | E85: solved | F85: 0 | G85: 4 | W85: 0.251 | X85: 0.015625 | Y85: 0.09375 | Z85: 0.109375 | AA85: 0.265 | AB85: 0.296875 | AC85: 1.75 | AD85: 2.046875 | AE85: 29729 | AF85: 73 | AG85: 29766 | AH85: 80 | AI85: 0.014179514 | AJ85: 0.014186921
A86: grasp-gurobi | B86: 5 | C86: Gurobi | D86: 12.0.3 | E86: solved | F86: 0 | G86: 4 | W86: 0.234 | X86: 0.0625 | Y86: 0.046875 | Z86: 0.109375 | AA86: 0.266 | AB86: 0.296875 | AC86: 1.765625 | AD86: 2.0625 | AE86: 29729 | AF86: 73 | AG86: 29766 | AH86: 80 | AI86: 0.014188426 | AJ86: 0.014195255
A87: grasp-gurobi | B87: 6 | C87: Gurobi | D87: 12.0.3 | E87: solved | F87: 0 | G87: 4 | W87: 0.171 | X87: 0.046875 | Y87: 0.046875 | Z87: 0.09375 | AA87: 0.266 | AB87: 0.3125 | AC87: 1.625 | AD87: 1.9375 | AE87: 29729 | AF87: 73 | AG87: 29766 | AH87: 80 | AI87: 0.014197454 | AJ87: 0.014203588
...

Sheet averages
A1: =benchmark!A1 -> model | B1: =benchmark!B1 -> run | C1: =benchmark!C1 -> solver | D1: =benchmark!D1 -> version | E1: =benchmark!E1 -> exit_status | F1: =benchmark!F1 -> exit_code | G1: =benchmark!G1 -> obj1 | H1: =benchmark!H1 -> obj2 | ... AJ1: =benchmark!AJ1 -> toc | AK1: avg. wall time | AL1: min wall time | AM1: max wall time | AN1: avg. tic-toc | AO1: min tic-toc | AP1: max tic-toc | AQ1: eval. Time | AR1: eval. Time min | AS1: eval. Time max
A2: {=INDEX(benchmark!A:A, (ROW()-2)*$B2+2)} -> acrobot | B2: =COUNTIF(benchmark!A:A, benchmark!A2) -> 10 | C2: {=INDEX(benchmark!C:C, (ROW()-2)*$B2+2)} -> Ipopt | D2: {=INDEX(benchmark!D:D, (ROW()-2)*$B2+2)} -> 3.12.13 | E2: {=INDEX(benchmark!E:E, (ROW()-2)*$B2+2)} -> solved | F2: =IFERROR(AVERAGE(INDEX(benchmark!F:F, (ROW()-2)*$B2+2):INDEX(benchmark!F:F, (ROW()-2)*$B2 + $B2+1)), "") -> 0 | G2: =IFERROR(AVERAGE(INDEX(benchmark!G:G, (ROW()-2)*$B2+2):INDEX(benchmark!G:G, (ROW()-2)*$B2 + $B2+1)), "") -> 69.877642 | H2: =IFERROR(AVERAGE(INDEX(benchmark!H:H, (ROW()-2)*$B2+2):INDEX(benchmark!H:H, (ROW()-2)*$B2 + $B2+1)), "") | I2: =IFERROR(AVERAGE(INDEX(benchmark!I:I, (ROW()-2)*$B2+2):INDEX(benchmark!I:I, (ROW()-2)*$B2 + $B2+1)), "") -> 14 | J2: =IFERROR(AVERAGE(INDEX(benchmark!J:J, (ROW()-2)*$B2+2):INDEX(benchmark!J:J, (ROW()-2)*$B2 + $B2+1)), "") -> 26 | K2: =IFERROR(AVERAGE(INDEX(benchmark!K:K, (ROW()-2)*$B2+2):INDEX(benchmark!K:K, (ROW()-2)*$B2 + $B2+1)), "") -> 15 | L2: =IFERROR(AVERAGE(INDEX(benchmark!L:L, (ROW()-2)*$B2+2):INDEX(benchmark!L:L, (ROW()-2)*$B2 + $B2+1)), "") -> 26 | M2: =IFERROR(AVERAGE(INDEX(benchmark!M:M, (ROW()-2)*$B2+2):INDEX(benchmark!M:M, (ROW()-2)*$B2 + $B2+1)), "") -> 26 | N2: =IFERROR(AVERAGE(INDEX(benchmark!N:N, (ROW()-2)*$B2+2):INDEX(benchmark!N:N, (ROW()-2)*$B2 + $B2+1)), "") -> 15 | O2: =IFERROR(AVERAGE(INDEX(benchmark!O:O, (ROW()-2)*$B2+2):INDEX(benchmark!O:O, (ROW()-2)*$B2 + $B2+1)), "") -> 15 | P2: =IFERROR(AVERAGE(INDEX(benchmark!P:P, (ROW()-2)*$B2+2):INDEX(benchmark!P:P, (ROW()-2)*$B2 + $B2+1)), "") -> 14 | Q2: =IFERROR(AVERAGE(INDEX(benchmark!Q:Q, (ROW()-2)*$B2+2):INDEX(benchmark!Q:Q, (ROW()-2)*$B2 + $B2+1)), "") -> 2.8421709e-14 | R2: =IFERROR(AVERAGE(INDEX(benchmark!R:R, (ROW()-2)*$B2+2):INDEX(benchmark!R:R, (ROW()-2)*$B2 + $B2+1)), "") -> 0.0125 | S2: =IFERROR(AVERAGE(INDEX(benchmark!S:S, (ROW()-2)*$B2+2):INDEX(benchmark!S:S, (ROW()-2)*$B2 + $B2+1)), "") -> 0.0023 | T2: =IFERROR(AVERAGE(INDEX(benchmark!T:T, (ROW()-2)*$B2+2):INDEX(benchmark!T:T, (ROW()-2)*$B2 + $B2+1)), "") -> 132 | U2: =IFERROR(AVERAGE(INDEX(benchmark!U:U, (ROW()-2)*$B2+2):INDEX(benchmark!U:U, (ROW()-2)*$B2 + $B2+1)), "") -> 116 | V2: =IFERROR(AVERAGE(INDEX(benchmark!V:V, (ROW()-2)*$B2+2):INDEX(benchmark!V:V, (ROW()-2)*$B2 + $B2+1)), "") -> 18 | W2: =IFERROR(AVERAGE(INDEX(benchmark!W:W, (ROW()-2)*$B2+2):INDEX(benchmark!W:W, (ROW()-2)*$B2 + $B2+1)), "") -> 0.1907 | X2: =IFERROR(AVERAGE(INDEX(benchmark!X:X, (ROW()-2)*$B2+2):INDEX(benchmark!X:X, (ROW()-2)*$B2 + $B2+1)), "") -> 0.015625 | Y2: =IFERROR(AVERAGE(INDEX(benchmark!Y:Y, (ROW()-2)*$B2+2):INDEX(benchmark!Y:Y, (ROW()-2)*$B2 + $B2+1)), "") -> 0.0296875 | Z2: =IFERROR(AVERAGE(INDEX(benchmark!Z:Z, (ROW()-2)*$B2+2):INDEX(benchmark!Z:Z, (ROW()-2)*$B2 + $B2+1)), "") -> 0.0453125 | AA2: =IFERROR(AVERAGE(INDEX(benchmark!AA:AA, (ROW()-2)*$B2+2):INDEX(benchmark!AA:AA, (ROW()-2)*$B2 + $B2+1)), "") -> 0.0421 | AB2: =IFERROR(AVERAGE(INDEX(benchmark!AB:AB, (ROW()-2)*$B2+2):INDEX(benchmark!AB:AB, (ROW()-2)*$B2 + $B2+1)), "") -> 0.0125 | AC2: =IFERROR(AVERAGE(INDEX(benchmark!AC:AC, (ROW()-2)*$B2+2):INDEX(benchmark!AC:AC, (ROW()-2)*$B2 + $B2+1)), "") -> 0.0078125 | AD2: =IFERROR(AVERAGE(INDEX(benchmark!AD:AD, (ROW()-2)*$B2+2):INDEX(benchmark!AD:AD, (ROW()-2)*$B2 + $B2+1)), "") -> 0.0203125 | AE2: =IFERROR(AVERAGE(INDEX(benchmark!AE:AE, (ROW()-2)*$B2+2):INDEX(benchmark!AE:AE, (ROW()-2)*$B2 + $B2+1)), "") -> 8779 | AF2: =IFERROR(AVERAGE(INDEX(benchmark!AF:AF, (ROW()-2)*$B2+2):INDEX(benchmark!AF:AF, (ROW()-2)*$B2 + $B2+1)), "") -> 132 | AG2: =IFERROR(AVERAGE(INDEX(benchmark!AG:AG, (ROW()-2)*$B2+2):INDEX(benchmark!AG:AG, (ROW()-2)*$B2 + $B2+1)), "") -> 8824 | AH2: =IFERROR(AVERAGE(INDEX(benchmark!AH:AH, (ROW()-2)*$B2+2):INDEX(benchmark!AH:AH, (ROW()-2)*$B2 + $B2+1)), "") -> 134 | AI2: =IFERROR(AVERAGE(INDEX(benchmark!AI:AI, (ROW()-2)*$B2+2):INDEX(benchmark!AI:AI, (ROW()-2)*$B2 + $B2+1)), "") -> 0.0097351852 | AJ2: =IFERROR(AVERAGE(INDEX(benchmark!AJ:AJ, (ROW()-2)*$B2+2):INDEX(benchmark!AJ:AJ, (ROW()-2)*$B2 + $B2+1)), "") -> 0.0097392708 | AK2: {=IFERROR(AVERAGE(INDEX(benchmark!W:W, (ROW()-2)*$B2+2):INDEX(benchmark!W:W, (ROW()-2)*$B2 + $B2+1) + INDEX(benchmark!AA:AA, (ROW()-2)*$B2+2):INDEX(benchmark!AA:AA, (ROW()-2)*$B2 + $B2+1)), "")} -> 0.2328 | AL2: {=IFERROR(MIN(INDEX(benchmark!W:W, (ROW()-2)*$B2+2):INDEX(benchmark!W:W, (ROW()-2)*$B2 + $B2+1) + INDEX(benchmark!AA:AA, (ROW()-2)*$B2+2):INDEX(benchmark!AA:AA, (ROW()-2)*$B2 + $B2+1)), "")} -> 0.203 | AM2: {=IFERROR(MAX(INDEX(benchmark!W:W, (ROW()-2)*$B2+2):INDEX(benchmark!W:W, (ROW()-2)*$B2 + $B2+1) + INDEX(benchmark!AA:AA, (ROW()-2)*$B2+2):INDEX(benchmark!AA:AA, (ROW()-2)*$B2 + $B2+1)), "")} -> 0.297 | AN2: {=IFERROR(AVERAGE(MOD(VALUE(INDEX(benchmark!AJ:AJ, (ROW()-2)*$B2+2):INDEX(benchmark!AJ:AJ, (ROW()-2)*$B2 + $B2+1)) - VALUE(INDEX(benchmark!AI:AI, (ROW()-2)*$B2+2):INDEX(benchmark!AI:AI, (ROW()-2)*$B2 + $B2+1)), 1) * 86400), "")} -> 0.353 | AO2: {=IFERROR(MIN(MOD(VALUE(INDEX(benchmark!AJ:AJ, (ROW()-2)*$B2+2):INDEX(benchmark!AJ:AJ, (ROW()-2)*$B2 + $B2+1)) - VALUE(INDEX(benchmark!AI:AI, (ROW()-2)*$B2+2):INDEX(benchmark!AI:AI, (ROW()-2)*$B2 + $B2+1)), 1) * 86400), "")} -> 0.32 | AP2: {=IFERROR(MAX(MOD(VALUE(INDEX(benchmark!AJ:AJ, (ROW()-2)*$B2+2):INDEX(benchmark!AJ:AJ, (ROW()-2)*$B2 + $B2+1)) - VALUE(INDEX(benchmark!AI:AI, (ROW()-2)*$B2+2):INDEX(benchmark!AI:AI, (ROW()-2)*$B2 + $B2+1)), 1) * 86400), "")} -> 0.42 | AQ2: =IFERROR(AVERAGE(INDEX(benchmark!S:S, (ROW()-2)*$B2+2):INDEX(benchmark!S:S, (ROW()-2)*$B2 + $B2+1)), "") -> 0.0023 | AR2: =IFERROR(MIN(INDEX(benchmark!S:S, (ROW()-2)*$B2+2):INDEX(benchmark!S:S, (ROW()-2)*$B2 + $B2+1)), "") -> 0 | AS2: =IFERROR(MAX(INDEX(benchmark!S:S, (ROW()-2)*$B2+2):INDEX(benchmark!S:S, (ROW()-2)*$B2 + $B2+1)), "") -> 0.006
A3: {=INDEX(benchmark!A:A, (ROW()-2)*$B3+2)} -> cart-pendulum-time | B3: =COUNTIF(benchmark!A:A, benchmark!A3) -> 10 | C3: {=INDEX(benchmark!C:C, (ROW()-2)*$B3+2)} -> Ipopt | D3: {=INDEX(benchmark!D:D, (ROW()-2)*$B3+2)} -> 3.12.13 | E3: {=INDEX(benchmark!E:E, (ROW()-2)*$B3+2)} -> solved | F3: =IFERROR(AVERAGE(INDEX(benchmark!F:F, (ROW()-2)*$B3+2):INDEX(benchmark!F:F, (ROW()-2)*$B3 + $B3+1)), "") -> 0 | G3: =IFERROR(AVERAGE(INDEX(benchmark!G:G, (ROW()-2)*$B3+2):INDEX(benchmark!G:G, (ROW()-2)*$B3 + $B3+1)), "") -> 1.1459373 | H3: =IFERROR(AVERAGE(INDEX(benchmark!H:H, (ROW()-2)*$B3+2):INDEX(benchmark!H:H, (ROW()-2)*$B3 + $B3+1)), "") | I3: =IFERROR(AVERAGE(INDEX(benchmark!I:I, (ROW()-2)*$B3+2):INDEX(benchmark!I:I, (ROW()-2)*$B3 + $B3+1)), "") -> 30 | J3: =IFERROR(AVERAGE(INDEX(benchmark!J:J, (ROW()-2)*$B3+2):INDEX(benchmark!J:J, (ROW()-2)*$B3 + $B3+1)), "") -> 50 | K3: =IFERROR(AVERAGE(INDEX(benchmark!K:K, (ROW()-2)*$B3+2):INDEX(benchmark!K:K, (ROW()-2)*$B3 + $B3+1)), "") -> 31 | L3: =IFERROR(AVERAGE(INDEX(benchmark!L:L, (ROW()-2)*$B3+2):INDEX(benchmark!L:L, (ROW()-2)*$B3 + $B3+1)), "") -> 50 | M3: =IFERROR(AVERAGE(INDEX(benchmark!M:M, (ROW()-2)*$B3+2):INDEX(benchmark!M:M, (ROW()-2)*$B3 + $B3+1)), "") -> 0 | N3: =IFERROR(AVERAGE(INDEX(benchmark!N:N, (ROW()-2)*$B3+2):INDEX(benchmark!N:N, (ROW()-2)*$B3 + $B3+1)), "") -> 31 | O3: =IFERROR(AVERAGE(INDEX(benchmark!O:O, (ROW()-2)*$B3+2):INDEX(benchmark!O:O, (ROW()-2)*$B3 + $B3+1)), "") -> 0 | P3: =IFERROR(AVERAGE(INDEX(benchmark!P:P, (ROW()-2)*$B3+2):INDEX(benchmark!P:P, (ROW()-2)*$B3 + $B3+1)), "") -> 30 | Q3: =IFERROR(AVERAGE(INDEX(benchmark!Q:Q, (ROW()-2)*$B3+2):INDEX(benchmark!Q:Q, (ROW()-2)*$B3 + $B3+1)), "") -> 6.2101435e-12 | R3: =IFERROR(AVERAGE(INDEX(benchmark!R:R, (ROW()-2)*$B3+2):INDEX(benchmark!R:R, (ROW()-2)*$B3 + $B3+1)), "") -> 0.0159 | S3: =IFERROR(AVERAGE(INDEX(benchmark!S:S, (ROW()-2)*$B3+2):INDEX(benchmark!S:S, (ROW()-2)*$B3 + $B3+1)), "") -> 0.0011 | T3: =IFERROR(AVERAGE(INDEX(benchmark!T:T, (ROW()-2)*$B3+2):INDEX(benchmark!T:T, (ROW()-2)*$B3 + $B3+1)), "") -> 80 | U3: =IFERROR(AVERAGE(INDEX(benchmark!U:U, (ROW()-2)*$B3+2):INDEX(benchmark!U:U, (ROW()-2)*$B3 + $B3+1)), "") -> 74 | V3: =IFERROR(AVERAGE(INDEX(benchmark!V:V, (ROW()-2)*$B3+2):INDEX(benchmark!V:V, (ROW()-2)*$B3 + $B3+1)), "") -> 0 | W3: =IFERROR(AVERAGE(INDEX(benchmark!W:W, (ROW()-2)*$B3+2):INDEX(benchmark!W:W, (ROW()-2)*$B3 + $B3+1)), "") -> 0.1797 | X3: =IFERROR(AVERAGE(INDEX(benchmark!X:X, (ROW()-2)*$B3+2):INDEX(benchmark!X:X, (ROW()-2)*$B3 + $B3+1)), "") -> 0.0109375 | Y3: =IFERROR(AVERAGE(INDEX(benchmark!Y:Y, (ROW()-2)*$B3+2):INDEX(benchmark!Y:Y, (ROW()-2)*$B3 + $B3+1)), "") -> 0.015625 | Z3: =IFERROR(AVERAGE(INDEX(benchmark!Z:Z, (ROW()-2)*$B3+2):INDEX(benchmark!Z:Z, (ROW()-2)*$B3 + $B3+1)), "") -> 0.0265625 | AA3: =IFERROR(AVERAGE(INDEX(benchmark!AA:AA, (ROW()-2)*$B3+2):INDEX(benchmark!AA:AA, (ROW()-2)*$B3 + $B3+1)), "") -> 0.039 | AB3: =IFERROR(AVERAGE(INDEX(benchmark!AB:AB, (ROW()-2)*$B3+2):INDEX(benchmark!AB:AB, (ROW()-2)*$B3 + $B3+1)), "") -> 0.0109375 | AC3: =IFERROR(AVERAGE(INDEX(benchmark!AC:AC, (ROW()-2)*$B3+2):INDEX(benchmark!AC:AC, (ROW()-2)*$B3 + $B3+1)), "") -> 0.015625 | AD3: =IFERROR(AVERAGE(INDEX(benchmark!AD:AD, (ROW()-2)*$B3+2):INDEX(benchmark!AD:AD, (ROW()-2)*$B3 + $B3+1)), "") -> 0.0265625 | AE3: =IFERROR(AVERAGE(INDEX(benchmark!AE:AE, (ROW()-2)*$B3+2):INDEX(benchmark!AE:AE, (ROW()-2)*$B3 + $B3+1)), "") -> 4388 | AF3: =IFERROR(AVERAGE(INDEX(benchmark!AF:AF, (ROW()-2)*$B3+2):INDEX(benchmark!AF:AF, (ROW()-2)*$B3 + $B3+1)), "") -> 80 | AG3: =IFERROR(AVERAGE(INDEX(benchmark!AG:AG, (ROW()-2)*$B3+2):INDEX(benchmark!AG:AG, (ROW()-2)*$B3 + $B3+1)), "") -> 4413 | AH3: =IFERROR(AVERAGE(INDEX(benchmark!AH:AH, (ROW()-2)*$B3+2):INDEX(benchmark!AH:AH, (ROW()-2)*$B3 + $B3+1)), "") -> 74 | AI3: =IFERROR(AVERAGE(INDEX(benchmark!AI:AI, (ROW()-2)*$B3+2):INDEX(benchmark!AI:AI, (ROW()-2)*$B3 + $B3+1)), "") -> 0.0097938657 | AJ3: =IFERROR(AVERAGE(INDEX(benchmark!AJ:AJ, (ROW()-2)*$B3+2):INDEX(benchmark!AJ:AJ, (ROW()-2)*$B3 + $B3+1)), "") -> 0.0097976505 | AK3: {=IFERROR(AVERAGE(INDEX(benchmark!W:W, (ROW()-2)*$B3+2):INDEX(benchmark!W:W, (ROW()-2)*$B3 + $B3+1) + INDEX(benchmark!AA:AA, (ROW()-2)*$B3+2):INDEX(benchmark!AA:AA, (ROW()-2)*$B3 + $B3+1)), "")} -> 0.2187 | AL3: {=IFERROR(MIN(INDEX(benchmark!W:W, (ROW()-2)*$B3+2):INDEX(benchmark!W:W, (ROW()-2)*$B3 + $B3+1) + INDEX(benchmark!AA:AA, (ROW()-2)*$B3+2):INDEX(benchmark!AA:AA, (ROW()-2)*$B3 + $B3+1)), "")} -> 0.203 | AM3: {=IFERROR(MAX(INDEX(benchmark!W:W, (ROW()-2)*$B3+2):INDEX(benchmark!W:W, (ROW()-2)*$B3 + $B3+1) + INDEX(benchmark!AA:AA, (ROW()-2)*$B3+2):INDEX(benchmark!AA:AA, (ROW()-2)*$B3 + $B3+1)), "")} -> 0.25 | AN3: {=IFERROR(AVERAGE(MOD(VALUE(INDEX(benchmark!AJ:AJ, (ROW()-2)*$B3+2):INDEX(benchmark!AJ:AJ, (ROW()-2)*$B3 + $B3+1)) - VALUE(INDEX(benchmark!AI:AI, (ROW()-2)*$B3+2):INDEX(benchmark!AI:AI, (ROW()-2)*$B3 + $B3+1)), 1) * 86400), "")} -> 0.327 | AO3: {=IFERROR(MIN(MOD(VALUE(INDEX(benchmark!AJ:AJ, (ROW()-2)*$B3+2):INDEX(benchmark!AJ:AJ, (ROW()-2)*$B3 + $B3+1)) - VALUE(INDEX(benchmark!AI:AI, (ROW()-2)*$B3+2):INDEX(benchmark!AI:AI, (ROW()-2)*$B3 + $B3+1)), 1) * 86400), "")} -> 0.3 | AP3: {=IFERROR(MAX(MOD(VALUE(INDEX(benchmark!AJ:AJ, (ROW()-2)*$B3+2):INDEX(benchmark!AJ:AJ, (ROW()-2)*$B3 + $B3+1)) - VALUE(INDEX(benchmark!AI:AI, (ROW()-2)*$B3+2):INDEX(benchmark!AI:AI, (ROW()-2)*$B3 + $B3+1)), 1) * 86400), "")} -> 0.36 | AQ3: =IFERROR(AVERAGE(INDEX(benchmark!S:S, (ROW()-2)*$B3+2):INDEX(benchmark!S:S, (ROW()-2)*$B3 + $B3+1)), "") -> 0.0011 | AR3: =IFERROR(MIN(INDEX(benchmark!S:S, (ROW()-2)*$B3+2):INDEX(benchmark!S:S, (ROW()-2)*$B3 + $B3+1)), "") -> 0 | AS3: =IFERROR(MAX(INDEX(benchmark!S:S, (ROW()-2)*$B3+2):INDEX(benchmark!S:S, (ROW()-2)*$B3 + $B3+1)), "") -> 0.003
A4: {=INDEX(benchmark!A:A, (ROW()-2)*$B4+2)} -> cart-pendulum-utot | B4: =COUNTIF(benchmark!A:A, benchmark!A4) -> 10 | C4: {=INDEX(benchmark!C:C, (ROW()-2)*$B4+2)} -> Ipopt | D4: {=INDEX(benchmark!D:D, (ROW()-2)*$B4+2)} -> 3.12.13 | E4: {=INDEX(benchmark!E:E, (ROW()-2)*$B4+2)} -> solved | F4: =IFERROR(AVERAGE(INDEX(benchmark!F:F, (ROW()-2)*$B4+2):INDEX(benchmark!F:F, (ROW()-2)*$B4 + $B4+1)), "") -> 0 | G4: =IFERROR(AVERAGE(INDEX(benchmark!G:G, (ROW()-2)*$B4+2):INDEX(benchmark!G:G, (ROW()-2)*$B4 + $B4+1)), "") -> 229.29128 | H4: =IFERROR(AVERAGE(INDEX(benchmark!H:H, (ROW()-2)*$B4+2):INDEX(benchmark!H:H, (ROW()-2)*$B4 + $B4+1)), "") | I4: =IFERROR(AVERAGE(INDEX(benchmark!I:I, (ROW()-2)*$B4+2):INDEX(benchmark!I:I, (ROW()-2)*$B4 + $B4+1)), "") -> 12 | J4: =IFERROR(AVERAGE(INDEX(benchmark!J:J, (ROW()-2)*$B4+2):INDEX(benchmark!J:J, (ROW()-2)*$B4 + $B4+1)), "") -> 15 | K4: =IFERROR(AVERAGE(INDEX(benchmark!K:K, (ROW()-2)*$B4+2):INDEX(benchmark!K:K, (ROW()-2)*$B4 + $B4+1)), "") -> 13 | L4: =IFERROR(AVERAGE(INDEX(benchmark!L:L, (ROW()-2)*$B4+2):INDEX(benchmark!L:L, (ROW()-2)*$B4 + $B4+1)), "") -> 15 | M4: =IFERROR(AVERAGE(INDEX(benchmark!M:M, (ROW()-2)*$B4+2):INDEX(benchmark!M:M, (ROW()-2)*$B4 + $B4+1)), "") -> 0 | N4: =IFERROR(AVERAGE(INDEX(benchmark!N:N, (ROW()-2)*$B4+2):INDEX(benchmark!N:N, (ROW()-2)*$B4 + $B4+1)), "") -> 13 | O4: =IFERROR(AVERAGE(INDEX(benchmark!O:O, (ROW()-2)*$B4+2):INDEX(benchmark!O:O, (ROW()-2)*$B4 + $B4+1)), "") -> 0 | P4: =IFERROR(AVERAGE(INDEX(benchmark!P:P, (ROW()-2)*$B4+2):INDEX(benchmark!P:P, (ROW()-2)*$B4 + $B4+1)), "") -> 12 | Q4: =IFERROR(AVERAGE(INDEX(benchmark!Q:Q, (ROW()-2)*$B4+2):INDEX(benchmark!Q:Q, (ROW()-2)*$B4 + $B4+1)), "") -> 2.8421709e-14 | R4: =IFERROR(AVERAGE(INDEX(benchmark!R:R, (ROW()-2)*$B4+2):INDEX(benchmark!R:R, (ROW()-2)*$B4 + $B4+1)), "") -> 0.0096 | S4: =IFERROR(AVERAGE(INDEX(benchmark!S:S, (ROW()-2)*$B4+2):INDEX(benchmark!S:S, (ROW()-2)*$B4 + $B4+1)), "") -> 0.001 | T4: =IFERROR(AVERAGE(INDEX(benchmark!T:T, (ROW()-2)*$B4+2):INDEX(benchmark!T:T, (ROW()-2)*$B4 + $B4+1)), "") -> 202 | U4: =IFERROR(AVERAGE(INDEX(benchmark!U:U, (ROW()-2)*$B4+2):INDEX(benchmark!U:U, (ROW()-2)*$B4 + $B4+1)), "") -> 176 | V4: =IFERROR(AVERAGE(INDEX(benchmark!V:V, (ROW()-2)*$B4+2):INDEX(benchmark!V:V, (ROW()-2)*$B4 + $B4+1)), "") -> 0 | W4: =IFERROR(AVERAGE(INDEX(benchmark!W:W, (ROW()-2)*$B4+2):INDEX(benchmark!W:W, (ROW()-2)*$B4 + $B4+1)), "") -> 0.1983 | X4: =IFERROR(AVERAGE(INDEX(benchmark!X:X, (ROW()-2)*$B4+2):INDEX(benchmark!X:X, (ROW()-2)*$B4 + $B4+1)), "") -> 0.025 | Y4: =IFERROR(AVERAGE(INDEX(benchmark!Y:Y, (ROW()-2)*$B4+2):INDEX(benchmark!Y:Y, (ROW()-2)*$B4 + $B4+1)), "") -> 0.0265625 | Z4: =IFERROR(AVERAGE(INDEX(benchmark!Z:Z, (ROW()-2)*$B4+2):INDEX(benchmark!Z:Z, (ROW()-2)*$B4 + $B4+1)), "") -> 0.0515625 | AA4: =IFERROR(AVERAGE(INDEX(benchmark!AA:AA, (ROW()-2)*$B4+2):INDEX(benchmark!AA:AA, (ROW()-2)*$B4 + $B4+1)), "") -> 0.03 | AB4: =IFERROR(AVERAGE(INDEX(benchmark!AB:AB, (ROW()-2)*$B4+2):INDEX(benchmark!AB:AB, (ROW()-2)*$B4 + $B4+1)), "") -> 0.0078125 | AC4: =IFERROR(AVERAGE(INDEX(benchmark!AC:AC, (ROW()-2)*$B4+2):INDEX(benchmark!AC:AC, (ROW()-2)*$B4 + $B4+1)), "") -> 0.009375 | AD4: =IFERROR(AVERAGE(INDEX(benchmark!AD:AD, (ROW()-2)*$B4+2):INDEX(benchmark!AD:AD, (ROW()-2)*$B4 + $B4+1)), "") -> 0.0171875 | AE4: =IFERROR(AVERAGE(INDEX(benchmark!AE:AE, (ROW()-2)*$B4+2):INDEX(benchmark!AE:AE, (ROW()-2)*$B4 + $B4+1)), "") -> 13169 | AF4: =IFERROR(AVERAGE(INDEX(benchmark!AF:AF, (ROW()-2)*$B4+2):INDEX(benchmark!AF:AF, (ROW()-2)*$B4 + $B4+1)), "") -> 202 | AG4: =IFERROR(AVERAGE(INDEX(benchmark!AG:AG, (ROW()-2)*$B4+2):INDEX(benchmark!AG:AG, (ROW()-2)*$B4 + $B4+1)), "") -> 13234 | AH4: =IFERROR(AVERAGE(INDEX(benchmark!AH:AH, (ROW()-2)*$B4+2):INDEX(benchmark!AH:AH, (ROW()-2)*$B4 + $B4+1)), "") -> 176 | AI4: =IFERROR(AVERAGE(INDEX(benchmark!AI:AI, (ROW()-2)*$B4+2):INDEX(benchmark!AI:AI, (ROW()-2)*$B4 + $B4+1)), "") -> 0.0098532292 | AJ4: =IFERROR(AVERAGE(INDEX(benchmark!AJ:AJ, (ROW()-2)*$B4+2):INDEX(benchmark!AJ:AJ, (ROW()-2)*$B4 + $B4+1)), "") -> 0.0098571181 | AK4: {=IFERROR(AVERAGE(INDEX(benchmark!W:W, (ROW()-2)*$B4+2):INDEX(benchmark!W:W, (ROW()-2)*$B4 + $B4+1) + INDEX(benchmark!AA:AA, (ROW()-2)*$B4+2):INDEX(benchmark!AA:AA, (ROW()-2)*$B4 + $B4+1)), "")} -> 0.2283 | AL4: {=IFERROR(MIN(INDEX(benchmark!W:W, (ROW()-2)*$B4+2):INDEX(benchmark!W:W, (ROW()-2)*$B4 + $B4+1) + INDEX(benchmark!AA:AA, (ROW()-2)*$B4+2):INDEX(benchmark!AA:AA, (ROW()-2)*$B4 + $B4+1)), "")} -> 0.203 | AM4: {=IFERROR(MAX(INDEX(benchmark!W:W, (ROW()-2)*$B4+2):INDEX(benchmark!W:W, (ROW()-2)*$B4 + $B4+1) + INDEX(benchmark!AA:AA, (ROW()-2)*$B4+2):INDEX(benchmark!AA:AA, (ROW()-2)*$B4 + $B4+1)), "")} -> 0.266 | AN4: {=IFERROR(AVERAGE(MOD(VALUE(INDEX(benchmark!AJ:AJ, (ROW()-2)*$B4+2):INDEX(benchmark!AJ:AJ, (ROW()-2)*$B4 + $B4+1)) - VALUE(INDEX(benchmark!AI:AI, (ROW()-2)*$B4+2):INDEX(benchmark!AI:AI, (ROW()-2)*$B4 + $B4+1)), 1) * 86400), "")} -> 0.336 | AO4: {=IFERROR(MIN(MOD(VALUE(INDEX(benchmark!AJ:AJ, (ROW()-2)*$B4+2):INDEX(benchmark!AJ:AJ, (ROW()-2)*$B4 + $B4+1)) - VALUE(INDEX(benchmark!AI:AI, (ROW()-2)*$B4+2):INDEX(benchmark!AI:AI, (ROW()-2)*$B4 + $B4+1)), 1) * 86400), "")} -> 0.3 | AP4: {=IFERROR(MAX(MOD(VALUE(INDEX(benchmark!AJ:AJ, (ROW()-2)*$B4+2):INDEX(benchmark!AJ:AJ, (ROW()-2)*$B4 + $B4+1)) - VALUE(INDEX(benchmark!AI:AI, (ROW()-2)*$B4+2):INDEX(benchmark!AI:AI, (ROW()-2)*$B4 + $B4+1)), 1) * 86400), "")} -> 0.37 | AQ4: =IFERROR(AVERAGE(INDEX(benchmark!S:S, (ROW()-2)*$B4+2):INDEX(benchmark!S:S, (ROW()-2)*$B4 + $B4+1)), "") -> 0.001 | AR4: =IFERROR(MIN(INDEX(benchmark!S:S, (ROW()-2)*$B4+2):INDEX(benchmark!S:S, (ROW()-2)*$B4 + $B4+1)), "") -> 0 | AS4: =IFERROR(MAX(INDEX(benchmark!S:S, (ROW()-2)*$B4+2):INDEX(benchmark!S:S, (ROW()-2)*$B4 + $B4+1)), "") -> 0.003
A5: {=INDEX(benchmark!A:A, (ROW()-2)*$B5+2)} -> five-link-mc-kelly | B5: =COUNTIF(benchmark!A:A, benchmark!A5) -> 10 | C5: {=INDEX(benchmark!C:C, (ROW()-2)*$B5+2)} -> Ipopt | D5: {=INDEX(benchmark!D:D, (ROW()-2)*$B5+2)} -> 3.12.13 | E5: {=INDEX(benchmark!E:E, (ROW()-2)*$B5+2)} -> solved | F5: =IFERROR(AVERAGE(INDEX(benchmark!F:F, (ROW()-2)*$B5+2):INDEX(benchmark!F:F, (ROW()-2)*$B5 + $B5+1)), "") -> 0 | G5: =IFERROR(AVERAGE(INDEX(benchmark!G:G, (ROW()-2)*$B5+2):INDEX(benchmark!G:G, (ROW()-2)*$B5 + $B5+1)), "") -> 260.43009 | H5: =IFERROR(AVERAGE(INDEX(benchmark!H:H, (ROW()-2)*$B5+2):INDEX(benchmark!H:H, (ROW()-2)*$B5 + $B5+1)), "") | I5: =IFERROR(AVERAGE(INDEX(benchmark!I:I, (ROW()-2)*$B5+2):INDEX(benchmark!I:I, (ROW()-2)*$B5 + $B5+1)), "") -> 11 | J5: =IFERROR(AVERAGE(INDEX(benchmark!J:J, (ROW()-2)*$B5+2):INDEX(benchmark!J:J, (ROW()-2)*$B5 + $B5+1)), "") -> 12 | K5: =IFERROR(AVERAGE(INDEX(benchmark!K:K, (ROW()-2)*$B5+2):INDEX(benchmark!K:K, (ROW()-2)*$B5 + $B5+1)), "") -> 12 | L5: =IFERROR(AVERAGE(INDEX(benchmark!L:L, (ROW()-2)*$B5+2):INDEX(benchmark!L:L, (ROW()-2)*$B5 + $B5+1)), "") -> 12 | M5: =IFERROR(AVERAGE(INDEX(benchmark!M:M, (ROW()-2)*$B5+2):INDEX(benchmark!M:M, (ROW()-2)*$B5 + $B5+1)), "") -> 12 | N5: =IFERROR(AVERAGE(INDEX(benchmark!N:N, (ROW()-2)*$B5+2):INDEX(benchmark!N:N, (ROW()-2)*$B5 + $B5+1)), "") -> 12 | O5: =IFERROR(AVERAGE(INDEX(benchmark!O:O, (ROW()-2)*$B5+2):INDEX(benchmark!O:O, (ROW()-2)*$B5 + $B5+1)), "") -> 12 | P5: =IFERROR(AVERAGE(INDEX(benchmark!P:P, (ROW()-2)*$B5+2):INDEX(benchmark!P:P, (ROW()-2)*$B5 + $B5+1)), "") -> 11 | Q5: =IFERROR(AVERAGE(INDEX(benchmark!Q:Q, (ROW()-2)*$B5+2):INDEX(benchmark!Q:Q, (ROW()-2)*$B5 + $B5+1)), "") -> 1.0587087e-12 | R5: =IFERROR(AVERAGE(INDEX(benchmark!R:R, (ROW()-2)*$B5+2):INDEX(benchmark!R:R, (ROW()-2)*$B5 + $B5+1)), "") -> 0.0254 | S5: =IFERROR(AVERAGE(INDEX(benchmark!S:S, (ROW()-2)*$B5+2):INDEX(benchmark!S:S, (ROW()-2)*$B5 + $B5+1)), "") -> 0.0415 | T5: =IFERROR(AVERAGE(INDEX(benchmark!T:T, (ROW()-2)*$B5+2):INDEX(benchmark!T:T, (ROW()-2)*$B5 + $B5+1)), "") -> 266 | U5: =IFERROR(AVERAGE(INDEX(benchmark!U:U, (ROW()-2)*$B5+2):INDEX(benchmark!U:U, (ROW()-2)*$B5 + $B5+1)), "") -> 212 | V5: =IFERROR(AVERAGE(INDEX(benchmark!V:V, (ROW()-2)*$B5+2):INDEX(benchmark!V:V, (ROW()-2)*$B5 + $B5+1)), "") -> 2 | W5: =IFERROR(AVERAGE(INDEX(benchmark!W:W, (ROW()-2)*$B5+2):INDEX(benchmark!W:W, (ROW()-2)*$B5 + $B5+1)), "") -> 0.3998 | X5: =IFERROR(AVERAGE(INDEX(benchmark!X:X, (ROW()-2)*$B5+2):INDEX(benchmark!X:X, (ROW()-2)*$B5 + $B5+1)), "") -> 0.0515625 | Y5: =IFERROR(AVERAGE(INDEX(benchmark!Y:Y, (ROW()-2)*$B5+2):INDEX(benchmark!Y:Y, (ROW()-2)*$B5 + $B5+1)), "") -> 0.1890625 | Z5: =IFERROR(AVERAGE(INDEX(benchmark!Z:Z, (ROW()-2)*$B5+2):INDEX(benchmark!Z:Z, (ROW()-2)*$B5 + $B5+1)), "") -> 0.240625 | AA5: =IFERROR(AVERAGE(INDEX(benchmark!AA:AA, (ROW()-2)*$B5+2):INDEX(benchmark!AA:AA, (ROW()-2)*$B5 + $B5+1)), "") -> 0.1048 | AB5: =IFERROR(AVERAGE(INDEX(benchmark!AB:AB, (ROW()-2)*$B5+2):INDEX(benchmark!AB:AB, (ROW()-2)*$B5 + $B5+1)), "") -> 0.021875 | AC5: =IFERROR(AVERAGE(INDEX(benchmark!AC:AC, (ROW()-2)*$B5+2):INDEX(benchmark!AC:AC, (ROW()-2)*$B5 + $B5+1)), "") -> 0.065625 | AD5: =IFERROR(AVERAGE(INDEX(benchmark!AD:AD, (ROW()-2)*$B5+2):INDEX(benchmark!AD:AD, (ROW()-2)*$B5 + $B5+1)), "") -> 0.0875 | AE5: =IFERROR(AVERAGE(INDEX(benchmark!AE:AE, (ROW()-2)*$B5+2):INDEX(benchmark!AE:AE, (ROW()-2)*$B5 + $B5+1)), "") -> 99109 | AF5: =IFERROR(AVERAGE(INDEX(benchmark!AF:AF, (ROW()-2)*$B5+2):INDEX(benchmark!AF:AF, (ROW()-2)*$B5 + $B5+1)), "") -> 266 | AG5: =IFERROR(AVERAGE(INDEX(benchmark!AG:AG, (ROW()-2)*$B5+2):INDEX(benchmark!AG:AG, (ROW()-2)*$B5 + $B5+1)), "") -> 98877 | AH5: =IFERROR(AVERAGE(INDEX(benchmark!AH:AH, (ROW()-2)*$B5+2):INDEX(benchmark!AH:AH, (ROW()-2)*$B5 + $B5+1)), "") -> 214 | AI5: =IFERROR(AVERAGE(INDEX(benchmark!AI:AI, (ROW()-2)*$B5+2):INDEX(benchmark!AI:AI, (ROW()-2)*$B5 + $B5+1)), "") -> 0.0099332639 | AJ5: =IFERROR(AVERAGE(INDEX(benchmark!AJ:AJ, (ROW()-2)*$B5+2):INDEX(benchmark!AJ:AJ, (ROW()-2)*$B5 + $B5+1)), "") -> 0.009941169 | AK5: {=IFERROR(AVERAGE(INDEX(benchmark!W:W, (ROW()-2)*$B5+2):INDEX(benchmark!W:W, (ROW()-2)*$B5 + $B5+1) + INDEX(benchmark!AA:AA, (ROW()-2)*$B5+2):INDEX(benchmark!AA:AA, (ROW()-2)*$B5 + $B5+1)), "")} -> 0.5046 | AL5: {=IFERROR(MIN(INDEX(benchmark!W:W, (ROW()-2)*$B5+2):INDEX(benchmark!W:W, (ROW()-2)*$B5 + $B5+1) + INDEX(benchmark!AA:AA, (ROW()-2)*$B5+2):INDEX(benchmark!AA:AA, (ROW()-2)*$B5 + $B5+1)), "")} -> 0.453 | AM5: {=IFERROR(MAX(INDEX(benchmark!W:W, (ROW()-2)*$B5+2):INDEX(benchmark!W:W, (ROW()-2)*$B5 + $B5+1) + INDEX(benchmark!AA:AA, (ROW()-2)*$B5+2):INDEX(benchmark!AA:AA, (ROW()-2)*$B5 + $B5+1)), "")} -> 0.718 | AN5: {=IFERROR(AVERAGE(MOD(VALUE(INDEX(benchmark!AJ:AJ, (ROW()-2)*$B5+2):INDEX(benchmark!AJ:AJ, (ROW()-2)*$B5 + $B5+1)) - VALUE(INDEX(benchmark!AI:AI, (ROW()-2)*$B5+2):INDEX(benchmark!AI:AI, (ROW()-2)*$B5 + $B5+1)), 1) * 86400), "")} -> 0.683 | AO5: {=IFERROR(MIN(MOD(VALUE(INDEX(benchmark!AJ:AJ, (ROW()-2)*$B5+2):INDEX(benchmark!AJ:AJ, (ROW()-2)*$B5 + $B5+1)) - VALUE(INDEX(benchmark!AI:AI, (ROW()-2)*$B5+2):INDEX(benchmark!AI:AI, (ROW()-2)*$B5 + $B5+1)), 1) * 86400), "")} -> 0.56 | AP5: {=IFERROR(MAX(MOD(VALUE(INDEX(benchmark!AJ:AJ, (ROW()-2)*$B5+2):INDEX(benchmark!AJ:AJ, (ROW()-2)*$B5 + $B5+1)) - VALUE(INDEX(benchmark!AI:AI, (ROW()-2)*$B5+2):INDEX(benchmark!AI:AI, (ROW()-2)*$B5 + $B5+1)), 1) * 86400), "")} -> 1.11 | AQ5: =IFERROR(AVERAGE(INDEX(benchmark!S:S, (ROW()-2)*$B5+2):INDEX(benchmark!S:S, (ROW()-2)*$B5 + $B5+1)), "") -> 0.0415 | AR5: =IFERROR(MIN(INDEX(benchmark!S:S, (ROW()-2)*$B5+2):INDEX(benchmark!S:S, (ROW()-2)*$B5 + $B5+1)), "") -> 0.039 | AS5: =IFERROR(MAX(INDEX(benchmark!S:S, (ROW()-2)*$B5+2):INDEX(benchmark!S:S, (ROW()-2)*$B5 + $B5+1)), "") -> 0.046
A6: {=INDEX(benchmark!A:A, (ROW()-2)*$B6+2)} -> five-link-phc-kelly | B6: =COUNTIF(benchmark!A:A, benchmark!A6) -> 10 | C6: {=INDEX(benchmark!C:C, (ROW()-2)*$B6+2)} -> Ipopt | D6: {=INDEX(benchmark!D:D, (ROW()-2)*$B6+2)} -> 3.12.13 | E6: {=INDEX(benchmark!E:E, (ROW()-2)*$B6+2)} -> solved | F6: =IFERROR(AVERAGE(INDEX(benchmark!F:F, (ROW()-2)*$B6+2):INDEX(benchmark!F:F, (ROW()-2)*$B6 + $B6+1)), "") -> 0 | G6: =IFERROR(AVERAGE(INDEX(benchmark!G:G, (ROW()-2)*$B6+2):INDEX(benchmark!G:G, (ROW()-2)*$B6 + $B6+1)), "") -> 443.14228 | H6: =IFERROR(AVERAGE(INDEX(benchmark!H:H, (ROW()-2)*$B6+2):INDEX(benchmark!H:H, (ROW()-2)*$B6 + $B6+1)), "") | I6: =IFERROR(AVERAGE(INDEX(benchmark!I:I, (ROW()-2)*$B6+2):INDEX(benchmark!I:I, (ROW()-2)*$B6 + $B6+1)), "") -> 13 | J6: =IFERROR(AVERAGE(INDEX(benchmark!J:J, (ROW()-2)*$B6+2):INDEX(benchmark!J:J, (ROW()-2)*$B6 + $B6+1)), "") -> 14 | K6: =IFERROR(AVERAGE(INDEX(benchmark!K:K, (ROW()-2)*$B6+2):INDEX(benchmark!K:K, (ROW()-2)*$B6 + $B6+1)), "") -> 14 | L6: =IFERROR(AVERAGE(INDEX(benchmark!L:L, (ROW()-2)*$B6+2):INDEX(benchmark!L:L, (ROW()-2)*$B6 + $B6+1)), "") -> 14 | M6: =IFERROR(AVERAGE(INDEX(benchmark!M:M, (ROW()-2)*$B6+2):INDEX(benchmark!M:M, (ROW()-2)*$B6 + $B6+1)), "") -> 14 | N6: =IFERROR(AVERAGE(INDEX(benchmark!N:N, (ROW()-2)*$B6+2):INDEX(benchmark!N:N, (ROW()-2)*$B6 + $B6+1)), "") -> 14 | O6: =IFERROR(AVERAGE(INDEX(benchmark!O:O, (ROW()-2)*$B6+2):INDEX(benchmark!O:O, (ROW()-2)*$B6 + $B6+1)), "") -> 14 | P6: =IFERROR(AVERAGE(INDEX(benchmark!P:P, (ROW()-2)*$B6+2):INDEX(benchmark!P:P, (ROW()-2)*$B6 + $B6+1)), "") -> 13 | Q6: =IFERROR(AVERAGE(INDEX(benchmark!Q:Q, (ROW()-2)*$B6+2):INDEX(benchmark!Q:Q, (ROW()-2)*$B6 + $B6+1)), "") -> 4.2092552e-10 | R6: =IFERROR(AVERAGE(INDEX(benchmark!R:R, (ROW()-2)*$B6+2):INDEX(benchmark!R:R, (ROW()-2)*$B6 + $B6+1)), "") -> 0.1167 | S6: =IFERROR(AVERAGE(INDEX(benchmark!S:S, (ROW()-2)*$B6+2):INDEX(benchmark!S:S, (ROW()-2)*$B6 + $B6+1)), "") -> 0.0851 | T6: =IFERROR(AVERAGE(INDEX(benchmark!T:T, (ROW()-2)*$B6+2):INDEX(benchmark!T:T, (ROW()-2)*$B6 + $B6+1)), "") -> 326 | U6: =IFERROR(AVERAGE(INDEX(benchmark!U:U, (ROW()-2)*$B6+2):INDEX(benchmark!U:U, (ROW()-2)*$B6 + $B6+1)), "") -> 300 | V6: =IFERROR(AVERAGE(INDEX(benchmark!V:V, (ROW()-2)*$B6+2):INDEX(benchmark!V:V, (ROW()-2)*$B6 + $B6+1)), "") -> 2 | W6: =IFERROR(AVERAGE(INDEX(benchmark!W:W, (ROW()-2)*$B6+2):INDEX(benchmark!W:W, (ROW()-2)*$B6 + $B6+1)), "") -> 0.2815 | X6: =IFERROR(AVERAGE(INDEX(benchmark!X:X, (ROW()-2)*$B6+2):INDEX(benchmark!X:X, (ROW()-2)*$B6 + $B6+1)), "") -> 0.0453125 | Y6: =IFERROR(AVERAGE(INDEX(benchmark!Y:Y, (ROW()-2)*$B6+2):INDEX(benchmark!Y:Y, (ROW()-2)*$B6 + $B6+1)), "") -> 0.109375 | Z6: =IFERROR(AVERAGE(INDEX(benchmark!Z:Z, (ROW()-2)*$B6+2):INDEX(benchmark!Z:Z, (ROW()-2)*$B6 + $B6+1)), "") -> 0.1546875 | AA6: =IFERROR(AVERAGE(INDEX(benchmark!AA:AA, (ROW()-2)*$B6+2):INDEX(benchmark!AA:AA, (ROW()-2)*$B6 + $B6+1)), "") -> 0.2435 | AB6: =IFERROR(AVERAGE(INDEX(benchmark!AB:AB, (ROW()-2)*$B6+2):INDEX(benchmark!AB:AB, (ROW()-2)*$B6 + $B6+1)), "") -> 0.034375 | AC6: =IFERROR(AVERAGE(INDEX(benchmark!AC:AC, (ROW()-2)*$B6+2):INDEX(benchmark!AC:AC, (ROW()-2)*$B6 + $B6+1)), "") -> 0.1921875 | AD6: =IFERROR(AVERAGE(INDEX(benchmark!AD:AD, (ROW()-2)*$B6+2):INDEX(benchmark!AD:AD, (ROW()-2)*$B6 + $B6+1)), "") -> 0.2265625 | AE6: =IFERROR(AVERAGE(INDEX(benchmark!AE:AE, (ROW()-2)*$B6+2):INDEX(benchmark!AE:AE, (ROW()-2)*$B6 + $B6+1)), "") -> 46821 | AF6: =IFERROR(AVERAGE(INDEX(benchmark!AF:AF, (ROW()-2)*$B6+2):INDEX(benchmark!AF:AF, (ROW()-2)*$B6 + $B6+1)), "") -> 326 | AG6: =IFERROR(AVERAGE(INDEX(benchmark!AG:AG, (ROW()-2)*$B6+2):INDEX(benchmark!AG:AG, (ROW()-2)*$B6 + $B6+1)), "") -> 46820 | AH6: =IFERROR(AVERAGE(INDEX(benchmark!AH:AH, (ROW()-2)*$B6+2):INDEX(benchmark!AH:AH, (ROW()-2)*$B6 + $B6+1)), "") -> 302 | AI6: =IFERROR(AVERAGE(INDEX(benchmark!AI:AI, (ROW()-2)*$B6+2):INDEX(benchmark!AI:AI, (ROW()-2)*$B6 + $B6+1)), "") -> 0.01002816 | AJ6: =IFERROR(AVERAGE(INDEX(benchmark!AJ:AJ, (ROW()-2)*$B6+2):INDEX(benchmark!AJ:AJ, (ROW()-2)*$B6 + $B6+1)), "") -> 0.010035417 | AK6: {=IFERROR(AVERAGE(INDEX(benchmark!W:W, (ROW()-2)*$B6+2):INDEX(benchmark!W:W, (ROW()-2)*$B6 + $B6+1) + INDEX(benchmark!AA:AA, (ROW()-2)*$B6+2):INDEX(benchmark!AA:AA, (ROW()-2)*$B6 + $B6+1)), "")} -> 0.525 | AL6: {=IFERROR(MIN(INDEX(benchmark!W:W, (ROW()-2)*$B6+2):INDEX(benchmark!W:W, (ROW()-2)*$B6 + $B6+1) + INDEX(benchmark!AA:AA, (ROW()-2)*$B6+2):INDEX(benchmark!AA:AA, (ROW()-2)*$B6 + $B6+1)), "")} -> 0.485 | AM6: {=IFERROR(MAX(INDEX(benchmark!W:W, (ROW()-2)*$B6+2):INDEX(benchmark!W:W, (ROW()-2)*$B6 + $B6+1) + INDEX(benchmark!AA:AA, (ROW()-2)*$B6+2):INDEX(benchmark!AA:AA, (ROW()-2)*$B6 + $B6+1)), "")} -> 0.578 | AN6: {=IFERROR(AVERAGE(MOD(VALUE(INDEX(benchmark!AJ:AJ, (ROW()-2)*$B6+2):INDEX(benchmark!AJ:AJ, (ROW()-2)*$B6 + $B6+1)) - VALUE(INDEX(benchmark!AI:AI, (ROW()-2)*$B6+2):INDEX(benchmark!AI:AI, (ROW()-2)*$B6 + $B6+1)), 1) * 86400), "")} -> 0.627 | AO6: {=IFERROR(MIN(MOD(VALUE(INDEX(benchmark!AJ:AJ, (ROW()-2)*$B6+2):INDEX(benchmark!AJ:AJ, (ROW()-2)*$B6 + $B6+1)) - VALUE(INDEX(benchmark!AI:AI, (ROW()-2)*$B6+2):INDEX(benchmark!AI:AI, (ROW()-2)*$B6 + $B6+1)), 1) * 86400), "")} -> 0.59 | AP6: {=IFERROR(MAX(MOD(VALUE(INDEX(benchmark!AJ:AJ, (ROW()-2)*$B6+2):INDEX(benchmark!AJ:AJ, (ROW()-2)*$B6 + $B6+1)) - VALUE(INDEX(benchmark!AI:AI, (ROW()-2)*$B6+2):INDEX(benchmark!AI:AI, (ROW()-2)*$B6 + $B6+1)), 1) * 86400), "")} -> 0.68 | AQ6: =IFERROR(AVERAGE(INDEX(benchmark!S:S, (ROW()-2)*$B6+2):INDEX(benchmark!S:S, (ROW()-2)*$B6 + $B6+1)), "") -> 0.0851 | AR6: =IFERROR(MIN(INDEX(benchmark!S:S, (ROW()-2)*$B6+2):INDEX(benchmark!S:S, (ROW()-2)*$B6 + $B6+1)), "") -> 0.077 | AS6: =IFERROR(MAX(INDEX(benchmark!S:S, (ROW()-2)*$B6+2):INDEX(benchmark!S:S, (ROW()-2)*$B6 + $B6+1)), "") -> 0.1
A7: {=INDEX(benchmark!A:A, (ROW()-2)*$B7+2)} -> five-link-tropic | B7: =COUNTIF(benchmark!A:A, benchmark!A7) -> 10 | C7: {=INDEX(benchmark!C:C, (ROW()-2)*$B7+2)} -> Ipopt | D7: {=INDEX(benchmark!D:D, (ROW()-2)*$B7+2)} -> 3.12.13 | E7: {=INDEX(benchmark!E:E, (ROW()-2)*$B7+2)} -> solved | F7: =IFERROR(AVERAGE(INDEX(benchmark!F:F, (ROW()-2)*$B7+2):INDEX(benchmark!F:F, (ROW()-2)*$B7 + $B7+1)), "") -> 0 | G7: =IFERROR(AVERAGE(INDEX(benchmark!G:G, (ROW()-2)*$B7+2):INDEX(benchmark!G:G, (ROW()-2)*$B7 + $B7+1)), "") -> 5.7300002 | H7: =IFERROR(AVERAGE(INDEX(benchmark!H:H, (ROW()-2)*$B7+2):INDEX(benchmark!H:H, (ROW()-2)*$B7 + $B7+1)), "") | I7: =IFERROR(AVERAGE(INDEX(benchmark!I:I, (ROW()-2)*$B7+2):INDEX(benchmark!I:I, (ROW()-2)*$B7 + $B7+1)), "") -> 206 | J7: =IFERROR(AVERAGE(INDEX(benchmark!J:J, (ROW()-2)*$B7+2):INDEX(benchmark!J:J, (ROW()-2)*$B7 + $B7+1)), "") -> 273 | K7: =IFERROR(AVERAGE(INDEX(benchmark!K:K, (ROW()-2)*$B7+2):INDEX(benchmark!K:K, (ROW()-2)*$B7 + $B7+1)), "") -> 207 | L7: =IFERROR(AVERAGE(INDEX(benchmark!L:L, (ROW()-2)*$B7+2):INDEX(benchmark!L:L, (ROW()-2)*$B7 + $B7+1)), "") -> 273 | M7: =IFERROR(AVERAGE(INDEX(benchmark!M:M, (ROW()-2)*$B7+2):INDEX(benchmark!M:M, (ROW()-2)*$B7 + $B7+1)), "") -> 273 | N7: =IFERROR(AVERAGE(INDEX(benchmark!N:N, (ROW()-2)*$B7+2):INDEX(benchmark!N:N, (ROW()-2)*$B7 + $B7+1)), "") -> 210 | O7: =IFERROR(AVERAGE(INDEX(benchmark!O:O, (ROW()-2)*$B7+2):INDEX(benchmark!O:O, (ROW()-2)*$B7 + $B7+1)), "") -> 210 | P7: =IFERROR(AVERAGE(INDEX(benchmark!P:P, (ROW()-2)*$B7+2):INDEX(benchmark!P:P, (ROW()-2)*$B7 + $B7+1)), "") -> 206 | Q7: =IFERROR(AVERAGE(INDEX(benchmark!Q:Q, (ROW()-2)*$B7+2):INDEX(benchmark!Q:Q, (ROW()-2)*$B7 + $B7+1)), "") -> 1.4438672e-11 | R7: =IFERROR(AVERAGE(INDEX(benchmark!R:R, (ROW()-2)*$B7+2):INDEX(benchmark!R:R, (ROW()-2)*$B7 + $B7+1)), "") -> 18.4238 | S7: =IFERROR(AVERAGE(INDEX(benchmark!S:S, (ROW()-2)*$B7+2):INDEX(benchmark!S:S, (ROW()-2)*$B7 + $B7+1)), "") -> 11.9045 | T7: =IFERROR(AVERAGE(INDEX(benchmark!T:T, (ROW()-2)*$B7+2):INDEX(benchmark!T:T, (ROW()-2)*$B7 + $B7+1)), "") -> 2345 | U7: =IFERROR(AVERAGE(INDEX(benchmark!U:U, (ROW()-2)*$B7+2):INDEX(benchmark!U:U, (ROW()-2)*$B7 + $B7+1)), "") -> 2331 | V7: =IFERROR(AVERAGE(INDEX(benchmark!V:V, (ROW()-2)*$B7+2):INDEX(benchmark!V:V, (ROW()-2)*$B7 + $B7+1)), "") -> 206 | W7: =IFERROR(AVERAGE(INDEX(benchmark!W:W, (ROW()-2)*$B7+2):INDEX(benchmark!W:W, (ROW()-2)*$B7 + $B7+1)), "") -> 1.4402 | X7: =IFERROR(AVERAGE(INDEX(benchmark!X:X, (ROW()-2)*$B7+2):INDEX(benchmark!X:X, (ROW()-2)*$B7 + $B7+1)), "") -> 0.228125 | Y7: =IFERROR(AVERAGE(INDEX(benchmark!Y:Y, (ROW()-2)*$B7+2):INDEX(benchmark!Y:Y, (ROW()-2)*$B7 + $B7+1)), "") -> 1.0375 | Z7: =IFERROR(AVERAGE(INDEX(benchmark!Z:Z, (ROW()-2)*$B7+2):INDEX(benchmark!Z:Z, (ROW()-2)*$B7 + $B7+1)), "") -> 1.265625 | AA7: =IFERROR(AVERAGE(INDEX(benchmark!AA:AA, (ROW()-2)*$B7+2):INDEX(benchmark!AA:AA, (ROW()-2)*$B7 + $B7+1)), "") -> 30.5142 | AB7: =IFERROR(AVERAGE(INDEX(benchmark!AB:AB, (ROW()-2)*$B7+2):INDEX(benchmark!AB:AB, (ROW()-2)*$B7 + $B7+1)), "") -> 0.490625 | AC7: =IFERROR(AVERAGE(INDEX(benchmark!AC:AC, (ROW()-2)*$B7+2):INDEX(benchmark!AC:AC, (ROW()-2)*$B7 + $B7+1)), "") -> 29.89375 | AD7: =IFERROR(AVERAGE(INDEX(benchmark!AD:AD, (ROW()-2)*$B7+2):INDEX(benchmark!AD:AD, (ROW()-2)*$B7 + $B7+1)), "") -> 30.384375 | AE7: =IFERROR(AVERAGE(INDEX(benchmark!AE:AE, (ROW()-2)*$B7+2):INDEX(benchmark!AE:AE, (ROW()-2)*$B7 + $B7+1)), "") -> 371155 | AF7: =IFERROR(AVERAGE(INDEX(benchmark!AF:AF, (ROW()-2)*$B7+2):INDEX(benchmark!AF:AF, (ROW()-2)*$B7 + $B7+1)), "") -> 2345 | AG7: =IFERROR(AVERAGE(INDEX(benchmark!AG:AG, (ROW()-2)*$B7+2):INDEX(benchmark!AG:AG, (ROW()-2)*$B7 + $B7+1)), "") -> 372492 | AH7: =IFERROR(AVERAGE(INDEX(benchmark!AH:AH, (ROW()-2)*$B7+2):INDEX(benchmark!AH:AH, (ROW()-2)*$B7 + $B7+1)), "") -> 2537 | AI7: =IFERROR(AVERAGE(INDEX(benchmark!AI:AI, (ROW()-2)*$B7+2):INDEX(benchmark!AI:AI, (ROW()-2)*$B7 + $B7+1)), "") -> 0.011852187 | AJ7: =IFERROR(AVERAGE(INDEX(benchmark!AJ:AJ, (ROW()-2)*$B7+2):INDEX(benchmark!AJ:AJ, (ROW()-2)*$B7 + $B7+1)), "") -> 0.012244965 | AK7: {=IFERROR(AVERAGE(INDEX(benchmark!W:W, (ROW()-2)*$B7+2):INDEX(benchmark!W:W, (ROW()-2)*$B7 + $B7+1) + INDEX(benchmark!AA:AA, (ROW()-2)*$B7+2):INDEX(benchmark!AA:AA, (ROW()-2)*$B7 + $B7+1)), "")} -> 31.9544 | AL7: {=IFERROR(MIN(INDEX(benchmark!W:W, (ROW()-2)*$B7+2):INDEX(benchmark!W:W, (ROW()-2)*$B7 + $B7+1) + INDEX(benchmark!AA:AA, (ROW()-2)*$B7+2):INDEX(benchmark!AA:AA, (ROW()-2)*$B7 + $B7+1)), "")} -> 30.765 | AM7: {=IFERROR(MAX(INDEX(benchmark!W:W, (ROW()-2)*$B7+2):INDEX(benchmark!W:W, (ROW()-2)*$B7 + $B7+1) + INDEX(benchmark!AA:AA, (ROW()-2)*$B7+2):INDEX(benchmark!AA:AA, (ROW()-2)*$B7 + $B7+1)), "")} -> 33.093 | AN7: {=IFERROR(AVERAGE(MOD(VALUE(INDEX(benchmark!AJ:AJ, (ROW()-2)*$B7+2):INDEX(benchmark!AJ:AJ, (ROW()-2)*$B7 + $B7+1)) - VALUE(INDEX(benchmark!AI:AI, (ROW()-2)*$B7+2):INDEX(benchmark!AI:AI, (ROW()-2)*$B7 + $B7+1)), 1) * 86400), "")} -> 33.936 | AO7: {=IFERROR(MIN(MOD(VALUE(INDEX(benchmark!AJ:AJ, (ROW()-2)*$B7+2):INDEX(benchmark!AJ:AJ, (ROW()-2)*$B7 + $B7+1)) - VALUE(INDEX(benchmark!AI:AI, (ROW()-2)*$B7+2):INDEX(benchmark!AI:AI, (ROW()-2)*$B7 + $B7+1)), 1) * 86400), "")} -> 32.89 | AP7: {=IFERROR(MAX(MOD(VALUE(INDEX(benchmark!AJ:AJ, (ROW()-2)*$B7+2):INDEX(benchmark!AJ:AJ, (ROW()-2)*$B7 + $B7+1)) - VALUE(INDEX(benchmark!AI:AI, (ROW()-2)*$B7+2):INDEX(benchmark!AI:AI, (ROW()-2)*$B7 + $B7+1)), 1) * 86400), "")} -> 34.99 | AQ7: =IFERROR(AVERAGE(INDEX(benchmark!S:S, (ROW()-2)*$B7+2):INDEX(benchmark!S:S, (ROW()-2)*$B7 + $B7+1)), "") -> 11.9045 | AR7: =IFERROR(MIN(INDEX(benchmark!S:S, (ROW()-2)*$B7+2):INDEX(benchmark!S:S, (ROW()-2)*$B7 + $B7+1)), "") -> 11.284 | AS7: =IFERROR(MAX(INDEX(benchmark!S:S, (ROW()-2)*$B7+2):INDEX(benchmark!S:S, (ROW()-2)*$B7 + $B7+1)), "") -> 12.42
A8: {=INDEX(benchmark!A:A, (ROW()-2)*$B8+2)} -> grasp-cbc | B8: =COUNTIF(benchmark!A:A, benchmark!A8) -> 10 | C8: {=INDEX(benchmark!C:C, (ROW()-2)*$B8+2)} -> cbc | D8: {=INDEX(benchmark!D:D, (ROW()-2)*$B8+2)} -> 2.10.12 | E8: {=INDEX(benchmark!E:E, (ROW()-2)*$B8+2)} -> failure | F8: =IFERROR(AVERAGE(INDEX(benchmark!F:F, (ROW()-2)*$B8+2):INDEX(benchmark!F:F, (ROW()-2)*$B8 + $B8+1)), "") -> 500 | G8: =IFERROR(AVERAGE(INDEX(benchmark!G:G, (ROW()-2)*$B8+2):INDEX(benchmark!G:G, (ROW()-2)*$B8 + $B8+1)), "") -> 0 | H8: =IFERROR(AVERAGE(INDEX(benchmark!H:H, (ROW()-2)*$B8+2):INDEX(benchmark!H:H, (ROW()-2)*$B8 + $B8+1)), "") | I8: =IFERROR(AVERAGE(INDEX(benchmark!I:I, (ROW()-2)*$B8+2):INDEX(benchmark!I:I, (ROW()-2)*$B8 + $B8+1)), "") | J8: =IFERROR(AVERAGE(INDEX(benchmark!J:J, (ROW()-2)*$B8+2):INDEX(benchmark!J:J, (ROW()-2)*$B8 + $B8+1)), "") | K8: =IFERROR(AVERAGE(INDEX(benchmark!K:K, (ROW()-2)*$B8+2):INDEX(benchmark!K:K, (ROW()-2)*$B8 + $B8+1)), "") | L8: =IFERROR(AVERAGE(INDEX(benchmark!L:L, (ROW()-2)*$B8+2):INDEX(benchmark!L:L, (ROW()-2)*$B8 + $B8+1)), "") | M8: =IFERROR(AVERAGE(INDEX(benchmark!M:M, (ROW()-2)*$B8+2):INDEX(benchmark!M:M, (ROW()-2)*$B8 + $B8+1)), "") | N8: =IFERROR(AVERAGE(INDEX(benchmark!N:N, (ROW()-2)*$B8+2):INDEX(benchmark!N:N, (ROW()-2)*$B8 + $B8+1)), "") | O8: =IFERROR(AVERAGE(INDEX(benchmark!O:O, (ROW()-2)*$B8+2):INDEX(benchmark!O:O, (ROW()-2)*$B8 + $B8+1)), "") | P8: =IFERROR(AVERAGE(INDEX(benchmark!P:P, (ROW()-2)*$B8+2):INDEX(benchmark!P:P, (ROW()-2)*$B8 + $B8+1)), "") | Q8: =IFERROR(AVERAGE(INDEX(benchmark!Q:Q, (ROW()-2)*$B8+2):INDEX(benchmark!Q:Q, (ROW()-2)*$B8 + $B8+1)), "") | R8: =IFERROR(AVERAGE(INDEX(benchmark!R:R, (ROW()-2)*$B8+2):INDEX(benchmark!R:R, (ROW()-2)*$B8 + $B8+1)), "") | S8: =IFERROR(AVERAGE(INDEX(benchmark!S:S, (ROW()-2)*$B8+2):INDEX(benchmark!S:S, (ROW()-2)*$B8 + $B8+1)), "") | T8: =IFERROR(AVERAGE(INDEX(benchmark!T:T, (ROW()-2)*$B8+2):INDEX(benchmark!T:T, (ROW()-2)*$B8 + $B8+1)), "") | U8: =IFERROR(AVERAGE(INDEX(benchmark!U:U, (ROW()-2)*$B8+2):INDEX(benchmark!U:U, (ROW()-2)*$B8 + $B8+1)), "") | V8: =IFERROR(AVERAGE(INDEX(benchmark!V:V, (ROW()-2)*$B8+2):INDEX(benchmark!V:V, (ROW()-2)*$B8 + $B8+1)), "") | W8: =IFERROR(AVERAGE(INDEX(benchmark!W:W, (ROW()-2)*$B8+2):INDEX(benchmark!W:W, (ROW()-2)*$B8 + $B8+1)), "") -> 0.2107 | X8: =IFERROR(AVERAGE(INDEX(benchmark!X:X, (ROW()-2)*$B8+2):INDEX(benchmark!X:X, (ROW()-2)*$B8 + $B8+1)), "") -> 0.0375 | Y8: =IFERROR(AVERAGE(INDEX(benchmark!Y:Y, (ROW()-2)*$B8+2):INDEX(benchmark!Y:Y, (ROW()-2)*$B8 + $B8+1)), "") -> 0.0609375 | Z8: =IFERROR(AVERAGE(INDEX(benchmark!Z:Z, (ROW()-2)*$B8+2):INDEX(benchmark!Z:Z, (ROW()-2)*$B8 + $B8+1)), "") -> 0.0984375 | AA8: =IFERROR(AVERAGE(INDEX(benchmark!AA:AA, (ROW()-2)*$B8+2):INDEX(benchmark!AA:AA, (ROW()-2)*$B8 + $B8+1)), "") -> 0.0284 | AB8: =IFERROR(AVERAGE(INDEX(benchmark!AB:AB, (ROW()-2)*$B8+2):INDEX(benchmark!AB:AB, (ROW()-2)*$B8 + $B8+1)), "") -> 0.009375 | AC8: =IFERROR(AVERAGE(INDEX(benchmark!AC:AC, (ROW()-2)*$B8+2):INDEX(benchmark!AC:AC, (ROW()-2)*$B8 + $B8+1)), "") -> 0.0078125 | AD8: =IFERROR(AVERAGE(INDEX(benchmark!AD:AD, (ROW()-2)*$B8+2):INDEX(benchmark!AD:AD, (ROW()-2)*$B8 + $B8+1)), "") -> 0.0171875 | AE8: =IFERROR(AVERAGE(INDEX(benchmark!AE:AE, (ROW()-2)*$B8+2):INDEX(benchmark!AE:AE, (ROW()-2)*$B8 + $B8+1)), "") -> 29729 | AF8: =IFERROR(AVERAGE(INDEX(benchmark!AF:AF, (ROW()-2)*$B8+2):INDEX(benchmark!AF:AF, (ROW()-2)*$B8 + $B8+1)), "") -> 73 | AG8: =IFERROR(AVERAGE(INDEX(benchmark!AG:AG, (ROW()-2)*$B8+2):INDEX(benchmark!AG:AG, (ROW()-2)*$B8 + $B8+1)), "") -> 29766 | AH8: =IFERROR(AVERAGE(INDEX(benchmark!AH:AH, (ROW()-2)*$B8+2):INDEX(benchmark!AH:AH, (ROW()-2)*$B8 + $B8+1)), "") -> 80 | AI8: =IFERROR(AVERAGE(INDEX(benchmark!AI:AI, (ROW()-2)*$B8+2):INDEX(benchmark!AI:AI, (ROW()-2)*$B8 + $B8+1)), "") -> 0.014052431 | AJ8: =IFERROR(AVERAGE(INDEX(benchmark!AJ:AJ, (ROW()-2)*$B8+2):INDEX(benchmark!AJ:AJ, (ROW()-2)*$B8 + $B8+1)), "") -> 0.014056389 | AK8: {=IFERROR(AVERAGE(INDEX(benchmark!W:W, (ROW()-2)*$B8+2):INDEX(benchmark!W:W, (ROW()-2)*$B8 + $B8+1) + INDEX(benchmark!AA:AA, (ROW()-2)*$B8+2):INDEX(benchmark!AA:AA, (ROW()-2)*$B8 + $B8+1)), "")} -> 0.2391 | AL8: {=IFERROR(MIN(INDEX(benchmark!W:W, (ROW()-2)*$B8+2):INDEX(benchmark!W:W, (ROW()-2)*$B8 + $B8+1) + INDEX(benchmark!AA:AA, (ROW()-2)*$B8+2):INDEX(benchmark!AA:AA, (ROW()-2)*$B8 + $B8+1)), "")} -> 0.203 | AM8: {=IFERROR(MAX(INDEX(benchmark!W:W, (ROW()-2)*$B8+2):INDEX(benchmark!W:W, (ROW()-2)*$B8 + $B8+1) + INDEX(benchmark!AA:AA, (ROW()-2)*$B8+2):INDEX(benchmark!AA:AA, (ROW()-2)*$B8 + $B8+1)), "")} -> 0.281 | AN8: {=IFERROR(AVERAGE(MOD(VALUE(INDEX(benchmark!AJ:AJ, (ROW()-2)*$B8+2):INDEX(benchmark!AJ:AJ, (ROW()-2)*$B8 + $B8+1)) - VALUE(INDEX(benchmark!AI:AI, (ROW()-2)*$B8+2):INDEX(benchmark!AI:AI, (ROW()-2)*$B8 + $B8+1)), 1) * 86400), "")} -> 0.342 | AO8: {=IFERROR(MIN(MOD(VALUE(INDEX(benchmark!AJ:AJ, (ROW()-2)*$B8+2):INDEX(benchmark!AJ:AJ, (ROW()-2)*$B8 + $B8+1)) - VALUE(INDEX(benchmark!AI:AI, (ROW()-2)*$B8+2):INDEX(benchmark!AI:AI, (ROW()-2)*$B8 + $B8+1)), 1) * 86400), "")} -> 0.31 | AP8: {=IFERROR(MAX(MOD(VALUE(INDEX(benchmark!AJ:AJ, (ROW()-2)*$B8+2):INDEX(benchmark!AJ:AJ, (ROW()-2)*$B8 + $B8+1)) - VALUE(INDEX(benchmark!AI:AI, (ROW()-2)*$B8+2):INDEX(benchmark!AI:AI, (ROW()-2)*$B8 + $B8+1)), 1) * 86400), "")} -> 0.37 | AQ8: =IFERROR(AVERAGE(INDEX(benchmark!S:S, (ROW()-2)*$B8+2):INDEX(benchmark!S:S, (ROW()-2)*$B8 + $B8+1)), "") | AR8: =IFERROR(MIN(INDEX(benchmark!S:S, (ROW()-2)*$B8+2):INDEX(benchmark!S:S, (ROW()-2)*$B8 + $B8+1)), "") -> 0 | AS8: =IFERROR(MAX(INDEX(benchmark!S:S, (ROW()-2)*$B8+2):INDEX(benchmark!S:S, (ROW()-2)*$B8 + $B8+1)), "") -> 0
A9: {=INDEX(benchmark!A:A, (ROW()-2)*$B9+2)} -> grasp-conopt | B9: =COUNTIF(benchmark!A:A, benchmark!A9) -> 10 | C9: {=INDEX(benchmark!C:C, (ROW()-2)*$B9+2)} | D9: {=INDEX(benchmark!D:D, (ROW()-2)*$B9+2)} | E9: {=INDEX(benchmark!E:E, (ROW()-2)*$B9+2)} -> solved? | F9: =IFERROR(AVERAGE(INDEX(benchmark!F:F, (ROW()-2)*$B9+2):INDEX(benchmark!F:F, (ROW()-2)*$B9 + $B9+1)), "") -> 100 | G9: =IFERROR(AVERAGE(INDEX(benchmark!G:G, (ROW()-2)*$B9+2):INDEX(benchmark!G:G, (ROW()-2)*$B9 + $B9+1)), "") -> 6 | H9: =IFERROR(AVERAGE(INDEX(benchmark!H:H, (ROW()-2)*$B9+2):INDEX(benchmark!H:H, (ROW()-2)*$B9 + $B9+1)), "") | I9: =IFERROR(AVERAGE(INDEX(benchmark!I:I, (ROW()-2)*$B9+2):INDEX(benchmark!I:I, (ROW()-2)*$B9 + $B9+1)), "") | J9: =IFERROR(AVERAGE(INDEX(benchmark!J:J, (ROW()-2)*$B9+2):INDEX(benchmark!J:J, (ROW()-2)*$B9 + $B9+1)), "") | K9: =IFERROR(AVERAGE(INDEX(benchmark!K:K, (ROW()-2)*$B9+2):INDEX(benchmark!K:K, (ROW()-2)*$B9 + $B9+1)), "") | L9: =IFERROR(AVERAGE(INDEX(benchmark!L:L, (ROW()-2)*$B9+2):INDEX(benchmark!L:L, (ROW()-2)*$B9 + $B9+1)), "") | M9: =IFERROR(AVERAGE(INDEX(benchmark!M:M, (ROW()-2)*$B9+2):INDEX(benchmark!M:M, (ROW()-2)*$B9 + $B9+1)), "") | N9: =IFERROR(AVERAGE(INDEX(benchmark!N:N, (ROW()-2)*$B9+2):INDEX(benchmark!N:N, (ROW()-2)*$B9 + $B9+1)), "") | O9: =IFERROR(AVERAGE(INDEX(benchmark!O:O, (ROW()-2)*$B9+2):INDEX(benchmark!O:O, (ROW()-2)*$B9 + $B9+1)), "") | P9: =IFERROR(AVERAGE(INDEX(benchmark!P:P, (ROW()-2)*$B9+2):INDEX(benchmark!P:P, (ROW()-2)*$B9 + $B9+1)), "") | Q9: =IFERROR(AVERAGE(INDEX(benchmark!Q:Q, (ROW()-2)*$B9+2):INDEX(benchmark!Q:Q, (ROW()-2)*$B9 + $B9+1)), "") | R9: =IFERROR(AVERAGE(INDEX(benchmark!R:R, (ROW()-2)*$B9+2):INDEX(benchmark!R:R, (ROW()-2)*$B9 + $B9+1)), "") | S9: =IFERROR(AVERAGE(INDEX(benchmark!S:S, (ROW()-2)*$B9+2):INDEX(benchmark!S:S, (ROW()-2)*$B9 + $B9+1)), "") | T9: =IFERROR(AVERAGE(INDEX(benchmark!T:T, (ROW()-2)*$B9+2):INDEX(benchmark!T:T, (ROW()-2)*$B9 + $B9+1)), "") | U9: =IFERROR(AVERAGE(INDEX(benchmark!U:U, (ROW()-2)*$B9+2):INDEX(benchmark!U:U, (ROW()-2)*$B9 + $B9+1)), "") | V9: =IFERROR(AVERAGE(INDEX(benchmark!V:V, (ROW()-2)*$B9+2):INDEX(benchmark!V:V, (ROW()-2)*$B9 + $B9+1)), "") | W9: =IFERROR(AVERAGE(INDEX(benchmark!W:W, (ROW()-2)*$B9+2):INDEX(benchmark!W:W, (ROW()-2)*$B9 + $B9+1)), "") -> 0.2157 | X9: =IFERROR(AVERAGE(INDEX(benchmark!X:X, (ROW()-2)*$B9+2):INDEX(benchmark!X:X, (ROW()-2)*$B9 + $B9+1)), "") -> 0.0328125 | Y9: =IFERROR(AVERAGE(INDEX(benchmark!Y:Y, (ROW()-2)*$B9+2):INDEX(benchmark!Y:Y, (ROW()-2)*$B9 + $B9+1)), "") -> 0.084375 | Z9: =IFERROR(AVERAGE(INDEX(benchmark!Z:Z, (ROW()-2)*$B9+2):INDEX(benchmark!Z:Z, (ROW()-2)*$B9 + $B9+1)), "") -> 0.1171875 | AA9: =IFERROR(AVERAGE(INDEX(benchmark!AA:AA, (ROW()-2)*$B9+2):INDEX(benchmark!AA:AA, (ROW()-2)*$B9 + $B9+1)), "") -> 0.1298 | AB9: =IFERROR(AVERAGE(INDEX(benchmark!AB:AB, (ROW()-2)*$B9+2):INDEX(benchmark!AB:AB, (ROW()-2)*$B9 + $B9+1)), "") -> 0.015625 | AC9: =IFERROR(AVERAGE(INDEX(benchmark!AC:AC, (ROW()-2)*$B9+2):INDEX(benchmark!AC:AC, (ROW()-2)*$B9 + $B9+1)), "") -> 0.0140625 | AD9: =IFERROR(AVERAGE(INDEX(benchmark!AD:AD, (ROW()-2)*$B9+2):INDEX(benchmark!AD:AD, (ROW()-2)*$B9 + $B9+1)), "") -> 0.0296875 | AE9: =IFERROR(AVERAGE(INDEX(benchmark!AE:AE, (ROW()-2)*$B9+2):INDEX(benchmark!AE:AE, (ROW()-2)*$B9 + $B9+1)), "") -> 29729 | AF9: =IFERROR(AVERAGE(INDEX(benchmark!AF:AF, (ROW()-2)*$B9+2):INDEX(benchmark!AF:AF, (ROW()-2)*$B9 + $B9+1)), "") -> 73 | AG9: =IFERROR(AVERAGE(INDEX(benchmark!AG:AG, (ROW()-2)*$B9+2):INDEX(benchmark!AG:AG, (ROW()-2)*$B9 + $B9+1)), "") -> 29766 | AH9: =IFERROR(AVERAGE(INDEX(benchmark!AH:AH, (ROW()-2)*$B9+2):INDEX(benchmark!AH:AH, (ROW()-2)*$B9 + $B9+1)), "") -> 80 | AI9: =IFERROR(AVERAGE(INDEX(benchmark!AI:AI, (ROW()-2)*$B9+2):INDEX(benchmark!AI:AI, (ROW()-2)*$B9 + $B9+1)), "") -> 0.014116157 | AJ9: =IFERROR(AVERAGE(INDEX(benchmark!AJ:AJ, (ROW()-2)*$B9+2):INDEX(benchmark!AJ:AJ, (ROW()-2)*$B9 + $B9+1)), "") -> 0.014121296 | AK9: {=IFERROR(AVERAGE(INDEX(benchmark!W:W, (ROW()-2)*$B9+2):INDEX(benchmark!W:W, (ROW()-2)*$B9 + $B9+1) + INDEX(benchmark!AA:AA, (ROW()-2)*$B9+2):INDEX(benchmark!AA:AA, (ROW()-2)*$B9 + $B9+1)), "")} -> 0.3455 | AL9: {=IFERROR(MIN(INDEX(benchmark!W:W, (ROW()-2)*$B9+2):INDEX(benchmark!W:W, (ROW()-2)*$B9 + $B9+1) + INDEX(benchmark!AA:AA, (ROW()-2)*$B9+2):INDEX(benchmark!AA:AA, (ROW()-2)*$B9 + $B9+1)), "")} -> 0.266 | AM9: {=IFERROR(MAX(INDEX(benchmark!W:W, (ROW()-2)*$B9+2):INDEX(benchmark!W:W, (ROW()-2)*$B9 + $B9+1) + INDEX(benchmark!AA:AA, (ROW()-2)*$B9+2):INDEX(benchmark!AA:AA, (ROW()-2)*$B9 + $B9+1)), "")} -> 0.516 | AN9: {=IFERROR(AVERAGE(MOD(VALUE(INDEX(benchmark!AJ:AJ, (ROW()-2)*$B9+2):INDEX(benchmark!AJ:AJ, (ROW()-2)*$B9 + $B9+1)) - VALUE(INDEX(benchmark!AI:AI, (ROW()-2)*$B9+2):INDEX(benchmark!AI:AI, (ROW()-2)*$B9 + $B9+1)), 1) * 86400), "")} -> 0.444 | AO9: {=IFERROR(MIN(MOD(VALUE(INDEX(benchmark!AJ:AJ, (ROW()-2)*$B9+2):INDEX(benchmark!AJ:AJ, (ROW()-2)*$B9 + $B9+1)) - VALUE(INDEX(benchmark!AI:AI, (ROW()-2)*$B9+2):INDEX(benchmark!AI:AI, (ROW()-2)*$B9 + $B9+1)), 1) * 86400), "")} -> 0.35 | AP9: {=IFERROR(MAX(MOD(VALUE(INDEX(benchmark!AJ:AJ, (ROW()-2)*$B9+2):INDEX(benchmark!AJ:AJ, (ROW()-2)*$B9 + $B9+1)) - VALUE(INDEX(benchmark!AI:AI, (ROW()-2)*$B9+2):INDEX(benchmark!AI:AI, (ROW()-2)*$B9 + $B9+1)), 1) * 86400), "")} -> 0.62 | AQ9: =IFERROR(AVERAGE(INDEX(benchmark!S:S, (ROW()-2)*$B9+2):INDEX(benchmark!S:S, (ROW()-2)*$B9 + $B9+1)), "") | AR9: =IFERROR(MIN(INDEX(benchmark!S:S, (ROW()-2)*$B9+2):INDEX(benchmark!S:S, (ROW()-2)*$B9 + $B9+1)), "") -> 0 | AS9: =IFERROR(MAX(INDEX(benchmark!S:S, (ROW()-2)*$B9+2):INDEX(benchmark!S:S, (ROW()-2)*$B9 + $B9+1)), "") -> 0
