Workbook

Sheet neos_benchmark
A1: model | B1: run | C1: solver | D1: version | E1: exit_status | F1: exit_code | G1: obj1 | H1: obj2 | I1: iterations | J1: obj_eval | K1: grad_eval | L1: eq_eval | M1: ineq_eval | N1: eq_jac | O1: ineq_jac | P1: hess_eval | Q1: constraint_violation_unscaled | R1: cpu_ipopt | S1: cpu_nlp | T1: total_vars | U1: total_eq | V1: total_ineq | W1: ampl_elapsed_time | X1: ampl_system_time | Y1: ampl_user_time | Z1: ampl_time | AA1: solve_elapsed_time | AB1: solve_system_time | AC1: solve_user_time | AD1: solve_time | AE1: nvars | AF1: snvars | AG1: ncons | AH1: sncons | AI1: tic | AJ1: toc
A2: acrobot | B2: 1 | C2: Ipopt | D2: 3.14.12 | E2: solved | F2: 0 | G2: 69.877642 | I2: 14 | J2: 26 | K2: 15 | L2: 26 | M2: 26 | N2: 15 | O2: 15 | P2: 14 | Q2: 1.4210855e-14 | R2: 0.018 | S2: 0.006 | T2: 132 | U2: 116 | V2: 18 | W2: 0.038211 | X2: 0.01416 | Y2: 0.027291 | Z2: 0.041451 | AA2: 0.031125 | AB2: 0.002807 | AC2: 0.027783 | AD2: 0.03059 | AE2: 8779 | AF2: 132 | AG2: 8824 | AH2: 134 | AI2: 32920 | AJ2: 44187
A3: acrobot | B3: 2 | C3: Ipopt | D3: 3.14.12 | E3: solved | F3: 0 | G3: 69.877642 | I3: 14 | J3: 26 | K3: 15 | L3: 26 | M3: 26 | N3: 15 | O3: 15 | P3: 14 | Q3: 1.4210855e-14 | R3: 0.017 | S3: 0.004 | T3: 132 | U3: 116 | V3: 18 | W3: 0.037901 | X3: 0.014852 | Y3: 0.026756 | Z3: 0.041608 | AA3: 0.029714 | AB3: 0.004004 | AC3: 0.024964 | AD3: 0.028968 | AE3: 8779 | AF3: 132 | AG3: 8824 | AH3: 134 | AI3: 41485 | AJ3: 61666
A4: acrobot | B4: 3 | C4: Ipopt | D4: 3.14.12 | E4: solved | F4: 0 | G4: 69.877642 | I4: 14 | J4: 26 | K4: 15 | L4: 26 | M4: 26 | N4: 15 | O4: 15 | P4: 14 | Q4: 1.4210855e-14 | R4: 0.032 | S4: 0.009 | T4: 132 | U4: 116 | V4: 18 | W4: 0.053498 | X4: 0.015087 | Y4: 0.043291 | Z4: 0.058378 | AA4: 0.051543 | AB4: 0.004097 | AC4: 0.046618 | AD4: 0.050715 | AE4: 8779 | AF4: 132 | AG4: 8824 | AH4: 134 | AI4: 81147 | AJ4: 85112
A5: acrobot | B5: 4 | C5: Ipopt | D5: 3.14.12 | E5: solved | F5: 0 | G5: 69.877642 | I5: 14 | J5: 26 | K5: 15 | L5: 26 | M5: 26 | N5: 15 | O5: 15 | P5: 14 | Q5: 1.4210855e-14 | R5: 0.032 | S5: 0.009 | T5: 132 | U5: 116 | V5: 18 | W5: 0.056793 | X5: 0.01204 | Y5: 0.049242 | Z5: 0.061282 | AA5: 0.052472 | AB5: 0.009855 | AC5: 0.04137 | AD5: 0.051225 | AE5: 8779 | AF5: 132 | AG5: 8824 | AH5: 134 | AI5: 98738 | AJ5: 352965
A6: acrobot | B6: 5 | C6: Ipopt | D6: 3.14.12 | E6: solved | F6: 0 | G6: 69.877642 | I6: 14 | J6: 26 | K6: 15 | L6: 26 | M6: 26 | N6: 15 | O6: 15 | P6: 14 | Q6: 1.4210855e-14 | R6: 0.018 | S6: 0.005 | T6: 132 | U6: 116 | V6: 18 | W6: 0.039805 | X6: 0.014773 | Y6: 0.028559 | Z6: 0.043332 | AA6: 0.030536 | AB6: 0.004101 | AC6: 0.025622 | AD6: 0.029723 | AE6: 8779 | AF6: 132 | AG6: 8824 | AH6: 134 | AI6: 102311 | AJ6: 354627
A7: acrobot | B7: 6 | C7: Ipopt | D7: 3.14.12 | E7: solved | F7: 0 | G7: 69.877642 | I7: 14 | J7: 26 | K7: 15 | L7: 26 | M7: 26 | N7: 15 | O7: 15 | P7: 14 | Q7: 1.4210855e-14 | R7: 0.018 | S7: 0.005 | T7: 132 | U7: 116 | V7: 18 | W7: 0.04189 | X7: 0.01299 | Y7: 0.032975 | Z7: 0.045965 | AA7: 0.031031 | AB7: 0.006076 | AC7: 0.02414 | AD7: 0.030216 | AE7: 8779 | AF7: 132 | AG7: 8824 | AH7: 134 | AI7: 641339 | AJ7: 655878
A8: acrobot | B8: 7 | C8: Ipopt | D8: 3.14.12 | E8: solved | F8: 0 | G8: 69.877642 | I8: 14 | J8: 26 | K8: 15 | L8: 26 | M8: 26 | N8: 15 | O8: 15 | P8: 14 | Q8: 1.4210855e-14 | R8: 0.019 | S8: 0.007 | T8: 132 | U8: 116 | V8: 18 | W8: 0.040088 | X8: 0.015018 | Y8: 0.029009 | Z8: 0.044027 | AA8: 0.034499 | AB8: 0.007947 | AC8: 0.025802 | AD8: 0.033749 | AE8: 8779 | AF8: 132 | AG8: 8824 | AH8: 134 | AI8: 642853 | AJ8: 655941
A9: acrobot | B9: 8 | C9: Ipopt | D9: 3.14.12 | E9: solved | F9: 0 | G9: 69.877642 | I9: 14 | J9: 26 | K9: 15 | L9: 26 | M9: 26 | N9: 15 | O9: 15 | P9: 14 | Q9: 1.4210855e-14 | R9: 0.021 | S9: 0.007 | T9: 132 | U9: 116 | V9: 18 | W9: 0.042942 | X9: 0.012916 | Y9: 0.033779 | Z9: 0.046695 | AA9: 0.035668 | AB9: 0.005265 | AC9: 0.029795 | AD9: 0.03506 | AE9: 8779 | AF9: 132 | AG9: 8824 | AH9: 134 | AI9: 919653 | AJ9: 924481
A10: acrobot | B10: 9 | C10: Ipopt | D10: 3.14.12 | E10: solved | F10: 0 | G10: 69.877642 | I10: 14 | J10: 26 | K10: 15 | L10: 26 | M10: 26 | N10: 15 | O10: 15 | P10: 14 | Q10: 1.4210855e-14 | R10: 0.016 | S10: 0.004 | T10: 132 | U10: 116 | V10: 18 | W10: 0.03306 | X10: 0.015026 | Y10: 0.021013 | Z10: 0.036039 | AA10: 0.027373 | AB10: 0.004293 | AC10: 0.022561 | AD10: 0.026854 | AE10: 8779 | AF10: 132 | AG10: 8824 | AH10: 134 | AI10: 920163 | AJ10: 930915
A11: acrobot | B11: 10 | C11: Ipopt | D11: 3.14.12 | E11: solved | F11: 0 | G11: 69.877642 | I11: 14 | J11: 26 | K11: 15 | L11: 26 | M11: 26 | N11: 15 | O11: 15 | P11: 14 | Q11: 1.4210855e-14 | R11: 0.018 | S11: 0.005 | T11: 132 | U11: 116 | V11: 18 | W11: 0.041002 | X11: 0.012942 | Y11: 0.031884 | Z11: 0.044826 | AA11: 0.031231 | AB11: 0.003037 | AC11: 0.027618 | AD11: 0.030655 | AE11: 8779 | AF11: 132 | AG11: 8824 | AH11: 134 | AI11: 1278576 | AJ11: 1309409
A12: cart-pendulum-time | B12: 1 | C12: Ipopt | D12: 3.14.12 | E12: solved | F12: 0 | G12: 1.1459373 | I12: 43 | J12: 59 | K12: 44 | L12: 59 | M12: 0 | N12: 44 | O12: 0 | P12: 43 | Q12: 5.8264504e-12 | R12: 0.042 | S12: 0.003 | T12: 80 | U12: 74 | V12: 0 | W12: 0.019386 | X12: 0.004097 | Y12: 0.01845 | Z12: 0.022547 | AA12: 0.050745 | AB12: 0.00573 | AC12: 0.044317 | AD12: 0.050047 | AE12: 4388 | AF12: 80 | AG12: 4413 | AH12: 74 | AI12: 32921 | AJ12: 41066
A13: cart-pendulum-time | B13: 2 | C13: Ipopt | D13: 3.14.12 | E13: solved | F13: 0 | G13: 1.1459373 | I13: 43 | J13: 59 | K13: 44 | L13: 59 | M13: 0 | N13: 44 | O13: 0 | P13: 43 | Q13: 5.8264504e-12 | R13: 0.052 | S13: 0.004 | T13: 80 | U13: 74 | V13: 0 | W13: 0.02113 | X13: 0.005844 | Y13: 0.019105 | Z13: 0.024949 | AA13: 0.063163 | AB13: 0.011086 | AC13: 0.051406 | AD13: 0.062492 | AE13: 4388 | AF13: 80 | AG13: 4413 | AH13: 74 | AI13: 44495 | AJ13: 61605
... A61: five-link-tropic | B61: 10 | C61: Ipopt | D61: 3.14.12 | E61: solved | F61: 0 | G61: 5.7300002 | I61: 161 | J61: 186 | K61: 162 | L61: 186 | M61: 186 | N61: 164 | O61: 164 | P61: 161 | Q61: 4.8149573e-10 | R61: 13.235 | S61: 19.77 | T61: 2345 | U61: 2331 | V61: 206 | W61: 2.824127 | X61: 0.358226 | Y61: 2.474052 | Z61: 2.832278 | AA61: 33.345775 | AB61: 0.093748 | AC61: 33.162352 | AD61: 33.2561 | AE61: 371155 | AF61: 2345 | AG61: 372492 | AH61: 2537 | AI61: 1221459 | AJ61: 1311980
A62: grasp-cbc | B62: 1 | C62: CBC | D62: 2.10.10 | AI62: 32921 | AJ62: 45819
A63: grasp-cbc | B63: 2 | C63: CBC | D63: 2.10.10 | AI63: 448261 | AJ63: 474579
A64: grasp-cbc | B64: 3 | C64: CBC | D64: 2.10.10 | AI64: 474988 | AJ64: 514456
A65: grasp-cbc | B65: 4 | C65: CBC | D65: 2.10.10 | AI65: 792636 | AJ65: 837576
A66: grasp-cbc | B66: 5 | C66: CBC | D66: 2.10.10 | AI66: 838577 | AJ66: 895438
A67: grasp-cbc | B67: 6 | C67: CBC | D67: 2.10.10 | AI67: 855390 | AJ67: 906382
A68: grasp-cbc | B68: 7 | C68: CBC | D68: 2.10.10 | AI68: 1244212 | AJ68: 1275671
A69: grasp-cbc | B69: 8 | C69: CBC | D69: 2.10.10 | AI69: 1244715 | AJ69: 1276043
A70: grasp-cbc | B70: 9 | C70: CBC | D70: 2.10.10 | AI70: 1338177 | AJ70: 1411599
A71: grasp-cbc | B71: 10 | C71: CBC | D71: 2.10.10 | AI71: 1372854 | AJ71: 1411657
A72: grasp-conopt | B72: 1 | C72: CONOPT | D72: 4.38.1 | E72: solved? | F72: 100 | G72: 6 | W72: 0.124119 | X72: 0.023983 | Y72: 0.102934 | Z72: 0.126917 | AA72: 0.005573 | AB72: 0.002014 | AC72: 0.003024 | AD72: 0.005038 | AE72: 29729 | AF72: 73 | AG72: 29766 | AH72: 80 | AI72: 32921 | AJ72: 44187
A73: grasp-conopt | B73: 2 | C73: CONOPT | D73: 4.38.1 | E73: solved? | F73: 100 | G73: 6 | W73: 0.14917 | X73: 0.027839 | Y73: 0.125239 | Z73: 0.153078 | AA73: 0.006883 | AB73: 0.001999 | AC73: 0.004003 | AD73: 0.006002 | AE73: 29729 | AF73: 73 | AG73: 29766 | AH73: 80 | AI73: 452307 | AJ73: 474630
A74: grasp-conopt | B74: 3 | C74: CONOPT | D74: 4.38.1 | E74: solved? | F74: 100 | G74: 6 | W74: 0.152169 | X74: 0.015925 | Y74: 0.140364 | Z74: 0.156289 | AA74: 0.007 | AB74: 0.003033 | AC74: 0.003035 | AD74: 0.006068 | AE74: 29729 | AF74: 73 | AG74: 29766 | AH74: 80 | AI74: 500284 | AJ74: 534640
A75: grasp-conopt | B75: 4 | C75: CONOPT | D75: 4.38.1 | E75: solved? | F75: 100 | G75: 6 | W75: 0.11801 | X75: 0.018029 | Y75: 0.103149 | Z75: 0.121178 | AA75: 0.006465 | AB75: 0.003607 | AC75: 0.001802 | AD75: 0.005409 | AE75: 29729 | AF75: 73 | AG75: 29766 | AH75: 80 | AI75: 504832 | AJ75: 540381
A76: grasp-conopt | B76: 5 | C76: CONOPT | D76: 4.38.1 | E76: solved? | F76: 100 | G76: 6 | W76: 0.145595 | X76: 0.032802 | Y76: 0.11652 | Z76: 0.149322 | AA76: 0.00779 | AB76: 0.002188 | AC76: 0.004381 | AD76: 0.006569 | AE76: 29729 | AF76: 73 | AG76: 29766 | AH76: 80 | AI76: 540646 | AJ76: 548123
A77: grasp-conopt | B77: 6 | C77: CONOPT | D77: 4.38.1 | E77: solved? | F77: 100 | G77: 6 | W77: 0.144662 | X77: 0.02391 | Y77: 0.124558 | Z77: 0.148468 | AA77: 0.007798 | AB77: 0.002217 | AC77: 0.004447 | AD77: 0.006664 | AE77: 29729 | AF77: 73 | AG77: 29766 | AH77: 80 | AI77: 544180 | AJ77: 552463
A78: grasp-conopt | B78: 7 | C78: CONOPT | D78: 4.38.1 | E78: solved? | F78: 100 | G78: 6 | W78: 0.120047 | X78: 0.01894 | Y78: 0.104646 | Z78: 0.123586 | AA78: 0.006226 | AB78: 0.003156 | AC78: 0.002098 | AD78: 0.005254 | AE78: 29729 | AF78: 73 | AG78: 29766 | AH78: 80 | AI78: 587016 | AJ78: 591734
A79: grasp-conopt | B79: 8 | C79: CONOPT | D79: 4.38.1 | E79: solved? | F79: 100 | G79: 6 | W79: 0.215372 | X79: 0.025657 | Y79: 0.194829 | Z79: 0.220486 | AA79: 0.146006 | AB79: 0.007425 | AC79: 0.004625 | AD79: 0.01205 | AE79: 29729 | AF79: 73 | AG79: 29766 | AH79: 80 | AI79: 590530 | AJ79: 595715
A80: grasp-conopt | B80: 9 | C80: CONOPT | D80: 4.38.1 | E80: solved? | F80: 100 | G80: 6 | W80: 0.218618 | X80: 0.027936 | Y80: 0.19565 | Z80: 0.223586 | AA80: 0.01133 | AB80: 0.003929 | AC80: 0.005894 | AD80: 0.009823 | AE80: 29729 | AF80: 73 | AG80: 29766 | AH80: 80 | AI80: 592042 | AJ80: 597223
A81: grasp-conopt | B81: 10 | C81: CONOPT | D81: 4.38.1 | E81: solved? | F81: 100 | G81: 6 | W81: 0.116789 | X81: 0.013123 | Y81: 0.107022 | Z81: 0.120145 | AA81: 0.00652 | AB81: 0.002737 | AC81: 0.002733 | AD81: 0.00547 | AE81: 29729 | AF81: 73 | AG81: 29766 | AH81: 80 | AI81: 594568 | AJ81: 606212
A82: grasp-gurobi | B82: 1 | E82: XML-RPC rejected | AI82: 32921 | AJ82: 45817
A83: grasp-gurobi | B83: 2 | E83: XML-RPC rejected | AI83: 514648 | AJ83: 540434
A84: grasp-gurobi | B84: 3 | E84: XML-RPC rejected | AI84: 534600 | AJ84: 540472
A85: grasp-gurobi | B85: 4 | E85: XML-RPC rejected | AI85: 539171 | AJ85: 541901
A86: grasp-gurobi | B86: 5 | E86: XML-RPC rejected | AI86: 541679 | AJ86: 544073
A87: grasp-gurobi | B87: 6 | E87: XML-RPC rejected | AI87: 551213 | AJ87: 554123
...

Sheet averages
A1: =neos_benchmark!A1 -> model | B1: =neos_benchmark!B1 -> run | C1: =neos_benchmark!C1 -> solver | D1: =neos_benchmark!D1 -> version | E1: =neos_benchmark!E1 -> exit_status | F1: =neos_benchmark!F1 -> exit_code | G1: =neos_benchmark!G1 -> obj1 | H1: =neos_benchmark!H1 -> obj2 | ... AJ1: =neos_benchmark!AJ1 -> toc | AK1: avg. elapsed time | AL1: min elapsed time | AM1: max elapsed time | AN1: avg. tic-toc | AO1: min tic-toc | AP1: max tic-toc
A2: {=INDEX(neos_benchmark!A:A, (ROW()-2)*$B2+2)} -> acrobot | B2: =COUNTIF(neos_benchmark!A:A, neos_benchmark!A2) -> 10 | C2: {=INDEX(neos_benchmark!C:C, (ROW()-2)*$B2+2)} -> Ipopt | D2: {=INDEX(neos_benchmark!D:D, (ROW()-2)*$B2+2)} -> 3.14.12 | E2: {=INDEX(neos_benchmark!E:E, (ROW()-2)*$B2+2)} -> solved | F2: =IFERROR(AVERAGE(INDEX(neos_benchmark!F:F, (ROW()-2)*$B2+2):INDEX(neos_benchmark!F:F, (ROW()-2)*$B2 + $B2+1)), "") -> 0 | G2: =IFERROR(AVERAGE(INDEX(neos_benchmark!G:G, (ROW()-2)*$B2+2):INDEX(neos_benchmark!G:G, (ROW()-2)*$B2 + $B2+1)), "") -> 69.877642 | H2: =IFERROR(AVERAGE(INDEX(neos_benchmark!H:H, (ROW()-2)*$B2+2):INDEX(neos_benchmark!H:H, (ROW()-2)*$B2 + $B2+1)), "") | I2: =IFERROR(AVERAGE(INDEX(neos_benchmark!I:I, (ROW()-2)*$B2+2):INDEX(neos_benchmark!I:I, (ROW()-2)*$B2 + $B2+1)), "") -> 14 | J2: =IFERROR(AVERAGE(INDEX(neos_benchmark!J:J, (ROW()-2)*$B2+2):INDEX(neos_benchmark!J:J, (ROW()-2)*$B2 + $B2+1)), "") -> 26 | K2: =IFERROR(AVERAGE(INDEX(neos_benchmark!K:K, (ROW()-2)*$B2+2):INDEX(neos_benchmark!K:K, (ROW()-2)*$B2 + $B2+1)), "") -> 15 | L2: =IFERROR(AVERAGE(INDEX(neos_benchmark!L:L, (ROW()-2)*$B2+2):INDEX(neos_benchmark!L:L, (ROW()-2)*$B2 + $B2+1)), "") -> 26 | M2: =IFERROR(AVERAGE(INDEX(neos_benchmark!M:M, (ROW()-2)*$B2+2):INDEX(neos_benchmark!M:M, (ROW()-2)*$B2 + $B2+1)), "") -> 26 | N2: =IFERROR(AVERAGE(INDEX(neos_benchmark!N:N, (ROW()-2)*$B2+2):INDEX(neos_benchmark!N:N, (ROW()-2)*$B2 + $B2+1)), "") -> 15 | O2: =IFERROR(AVERAGE(INDEX(neos_benchmark!O:O, (ROW()-2)*$B2+2):INDEX(neos_benchmark!O:O, (ROW()-2)*$B2 + $B2+1)), "") -> 15 | P2: =IFERROR(AVERAGE(INDEX(neos_benchmark!P:P, (ROW()-2)*$B2+2):INDEX(neos_benchmark!P:P, (ROW()-2)*$B2 + $B2+1)), "") -> 14 | Q2: =IFERROR(AVERAGE(INDEX(neos_benchmark!Q:Q, (ROW()-2)*$B2+2):INDEX(neos_benchmark!Q:Q, (ROW()-2)*$B2 + $B2+1)), "") -> 1.4210855e-14 | R2: =IFERROR(AVERAGE(INDEX(neos_benchmark!R:R, (ROW()-2)*$B2+2):INDEX(neos_benchmark!R:R, (ROW()-2)*$B2 + $B2+1)), "") -> 0.0209 | S2: =IFERROR(AVERAGE(INDEX(neos_benchmark!S:S, (ROW()-2)*$B2+2):INDEX(neos_benchmark!S:S, (ROW()-2)*$B2 + $B2+1)), "") -> 0.0061 | T2: =IFERROR(AVERAGE(INDEX(neos_benchmark!T:T, (ROW()-2)*$B2+2):INDEX(neos_benchmark!T:T, (ROW()-2)*$B2 + $B2+1)), "") -> 132 | U2: =IFERROR(AVERAGE(INDEX(neos_benchmark!U:U, (ROW()-2)*$B2+2):INDEX(neos_benchmark!U:U, (ROW()-2)*$B2 + $B2+1)), "") -> 116 | V2: =IFERROR(AVERAGE(INDEX(neos_benchmark!V:V, (ROW()-2)*$B2+2):INDEX(neos_benchmark!V:V, (ROW()-2)*$B2 + $B2+1)), "") -> 18 | W2: =IFERROR(AVERAGE(INDEX(neos_benchmark!W:W, (ROW()-2)*$B2+2):INDEX(neos_benchmark!W:W, (ROW()-2)*$B2 + $B2+1)), "") -> 0.042519 | X2: =IFERROR(AVERAGE(INDEX(neos_benchmark!X:X, (ROW()-2)*$B2+2):INDEX(neos_benchmark!X:X, (ROW()-2)*$B2 + $B2+1)), "") -> 0.0139804 | Y2: =IFERROR(AVERAGE(INDEX(neos_benchmark!Y:Y, (ROW()-2)*$B2+2):INDEX(neos_benchmark!Y:Y, (ROW()-2)*$B2 + $B2+1)), "") -> 0.0323799 | Z2: =IFERROR(AVERAGE(INDEX(neos_benchmark!Z:Z, (ROW()-2)*$B2+2):INDEX(neos_benchmark!Z:Z, (ROW()-2)*$B2 + $B2+1)), "") -> 0.0463603 | AA2: =IFERROR(AVERAGE(INDEX(neos_benchmark!AA:AA, (ROW()-2)*$B2+2):INDEX(neos_benchmark!AA:AA, (ROW()-2)*$B2 + $B2+1)), "") -> 0.0355192 | AB2: =IFERROR(AVERAGE(INDEX(neos_benchmark!AB:AB, (ROW()-2)*$B2+2):INDEX(neos_benchmark!AB:AB, (ROW()-2)*$B2 + $B2+1)), "") -> 0.0051482 | AC2: =IFERROR(AVERAGE(INDEX(neos_benchmark!AC:AC, (ROW()-2)*$B2+2):INDEX(neos_benchmark!AC:AC, (ROW()-2)*$B2 + $B2+1)), "") -> 0.0296273 | AD2: =IFERROR(AVERAGE(INDEX(neos_benchmark!AD:AD, (ROW()-2)*$B2+2):INDEX(neos_benchmark!AD:AD, (ROW()-2)*$B2 + $B2+1)), "") -> 0.0347755 | AE2: =IFERROR(AVERAGE(INDEX(neos_benchmark!AE:AE, (ROW()-2)*$B2+2):INDEX(neos_benchmark!AE:AE, (ROW()-2)*$B2 + $B2+1)), "") -> 8779 | AF2: =IFERROR(AVERAGE(INDEX(neos_benchmark!AF:AF, (ROW()-2)*$B2+2):INDEX(neos_benchmark!AF:AF, (ROW()-2)*$B2 + $B2+1)), "") -> 132 | AG2: =IFERROR(AVERAGE(INDEX(neos_benchmark!AG:AG, (ROW()-2)*$B2+2):INDEX(neos_benchmark!AG:AG, (ROW()-2)*$B2 + $B2+1)), "") -> 8824 | AH2: =IFERROR(AVERAGE(INDEX(neos_benchmark!AH:AH, (ROW()-2)*$B2+2):INDEX(neos_benchmark!AH:AH, (ROW()-2)*$B2 + $B2+1)), "") -> 134 | AI2: =IFERROR(AVERAGE(INDEX(neos_benchmark!AI:AI, (ROW()-2)*$B2+2):INDEX(neos_benchmark!AI:AI, (ROW()-2)*$B2 + $B2+1)), "") -> 475918.5 | AJ2: =IFERROR(AVERAGE(INDEX(neos_benchmark!AJ:AJ, (ROW()-2)*$B2+2):INDEX(neos_benchmark!AJ:AJ, (ROW()-2)*$B2 + $B2+1)), "") -> 537518.1 | AK2: {=IFERROR(AVERAGE(INDEX(neos_benchmark!W:W, (ROW()-2)*$B2+2):INDEX(neos_benchmark!W:W, (ROW()-2)*$B2 + $B2+1) + INDEX(neos_benchmark!AA:AA, (ROW()-2)*$B2+2):INDEX(neos_benchmark!AA:AA, (ROW()-2)*$B2 + $B2+1)), "")} -> 0.0780382 | AL2: {=IFERROR(MIN(INDEX(neos_benchmark!W:W, (ROW()-2)*$B2+2):INDEX(neos_benchmark!W:W, (ROW()-2)*$B2 + $B2+1) + INDEX(neos_benchmark!AA:AA, (ROW()-2)*$B2+2):INDEX(neos_benchmark!AA:AA, (ROW()-2)*$B2 + $B2+1)), "")} -> 0.060433 | AM2: {=IFERROR(MAX(INDEX(neos_benchmark!W:W, (ROW()-2)*$B2+2):INDEX(neos_benchmark!W:W, (ROW()-2)*$B2 + $B2+1) + INDEX(neos_benchmark!AA:AA, (ROW()-2)*$B2+2):INDEX(neos_benchmark!AA:AA, (ROW()-2)*$B2 + $B2+1)), "")} -> 0.109265 | AN2: {=IFERROR(AVERAGE((INDEX(neos_benchmark!AJ:AJ, (ROW()-2)*$B2+2):INDEX(neos_benchmark!AJ:AJ, (ROW()-2)*$B2 + $B2+1) - INDEX(neos_benchmark!AI:AI, (ROW()-2)*$B2+2):INDEX(neos_benchmark!AI:AI, (ROW()-2)*$B2 + $B2+1)) / 1000), "")} -> 61.5996 | AO2: {=IFERROR(MIN((INDEX(neos_benchmark!AJ:AJ, (ROW()-2)*$B2+2):INDEX(neos_benchmark!AJ:AJ, (ROW()-2)*$B2 + $B2+1) - INDEX(neos_benchmark!AI:AI, (ROW()-2)*$B2+2):INDEX(neos_benchmark!AI:AI, (ROW()-2)*$B2 + $B2+1)) / 1000), "")} -> 3.965 | AP2: {=IFERROR(MAX((INDEX(neos_benchmark!AJ:AJ, (ROW()-2)*$B2+2):INDEX(neos_benchmark!AJ:AJ, (ROW()-2)*$B2 + $B2+1) - INDEX(neos_benchmark!AI:AI, (ROW()-2)*$B2+2):INDEX(neos_benchmark!AI:AI, (ROW()-2)*$B2 + $B2+1)) / 1000), "")} -> 254.227
A3: {=INDEX(neos_benchmark!A:A, (ROW()-2)*$B3+2)} -> cart-pendulum-time | B3: =COUNTIF(neos_benchmark!A:A, neos_benchmark!A3) -> 10 | C3: {=INDEX(neos_benchmark!C:C, (ROW()-2)*$B3+2)} -> Ipopt | D3: {=INDEX(neos_benchmark!D:D, (ROW()-2)*$B3+2)} -> 3.14.12 | E3: {=INDEX(neos_benchmark!E:E, (ROW()-2)*$B3+2)} -> solved | F3: =IFERROR(AVERAGE(INDEX(neos_benchmark!F:F, (ROW()-2)*$B3+2):INDEX(neos_benchmark!F:F, (ROW()-2)*$B3 + $B3+1)), "") -> 0 | G3: =IFERROR(AVERAGE(INDEX(neos_benchmark!G:G, (ROW()-2)*$B3+2):INDEX(neos_benchmark!G:G, (ROW()-2)*$B3 + $B3+1)), "") -> 1.1459373 | H3: =IFERROR(AVERAGE(INDEX(neos_benchmark!H:H, (ROW()-2)*$B3+2):INDEX(neos_benchmark!H:H, (ROW()-2)*$B3 + $B3+1)), "") | I3: =IFERROR(AVERAGE(INDEX(neos_benchmark!I:I, (ROW()-2)*$B3+2):INDEX(neos_benchmark!I:I, (ROW()-2)*$B3 + $B3+1)), "") -> 43 | J3: =IFERROR(AVERAGE(INDEX(neos_benchmark!J:J, (ROW()-2)*$B3+2):INDEX(neos_benchmark!J:J, (ROW()-2)*$B3 + $B3+1)), "") -> 59 | K3: =IFERROR(AVERAGE(INDEX(neos_benchmark!K:K, (ROW()-2)*$B3+2):INDEX(neos_benchmark!K:K, (ROW()-2)*$B3 + $B3+1)), "") -> 44 | L3: =IFERROR(AVERAGE(INDEX(neos_benchmark!L:L, (ROW()-2)*$B3+2):INDEX(neos_benchmark!L:L, (ROW()-2)*$B3 + $B3+1)), "") -> 59 | M3: =IFERROR(AVERAGE(INDEX(neos_benchmark!M:M, (ROW()-2)*$B3+2):INDEX(neos_benchmark!M:M, (ROW()-2)*$B3 + $B3+1)), "") -> 0 | N3: =IFERROR(AVERAGE(INDEX(neos_benchmark!N:N, (ROW()-2)*$B3+2):INDEX(neos_benchmark!N:N, (ROW()-2)*$B3 + $B3+1)), "") -> 44 | O3: =IFERROR(AVERAGE(INDEX(neos_benchmark!O:O, (ROW()-2)*$B3+2):INDEX(neos_benchmark!O:O, (ROW()-2)*$B3 + $B3+1)), "") -> 0 | P3: =IFERROR(AVERAGE(INDEX(neos_benchmark!P:P, (ROW()-2)*$B3+2):INDEX(neos_benchmark!P:P, (ROW()-2)*$B3 + $B3+1)), "") -> 43 | Q3: =IFERROR(AVERAGE(INDEX(neos_benchmark!Q:Q, (ROW()-2)*$B3+2):INDEX(neos_benchmark!Q:Q, (ROW()-2)*$B3 + $B3+1)), "") -> 5.8264504e-12 | R3: =IFERROR(AVERAGE(INDEX(neos_benchmark!R:R, (ROW()-2)*$B3+2):INDEX(neos_benchmark!R:R, (ROW()-2)*$B3 + $B3+1)), "") -> 0.0443 | S3: =IFERROR(AVERAGE(INDEX(neos_benchmark!S:S, (ROW()-2)*$B3+2):INDEX(neos_benchmark!S:S, (ROW()-2)*$B3 + $B3+1)), "") -> 0.0032 | T3: =IFERROR(AVERAGE(INDEX(neos_benchmark!T:T, (ROW()-2)*$B3+2):INDEX(neos_benchmark!T:T, (ROW()-2)*$B3 + $B3+1)), "") -> 80 | U3: =IFERROR(AVERAGE(INDEX(neos_benchmark!U:U, (ROW()-2)*$B3+2):INDEX(neos_benchmark!U:U, (ROW()-2)*$B3 + $B3+1)), "") -> 74 | V3: =IFERROR(AVERAGE(INDEX(neos_benchmark!V:V, (ROW()-2)*$B3+2):INDEX(neos_benchmark!V:V, (ROW()-2)*$B3 + $B3+1)), "") -> 0 | W3: =IFERROR(AVERAGE(INDEX(neos_benchmark!W:W, (ROW()-2)*$B3+2):INDEX(neos_benchmark!W:W, (ROW()-2)*$B3 + $B3+1)), "") -> 0.0191089 | X3: =IFERROR(AVERAGE(INDEX(neos_benchmark!X:X, (ROW()-2)*$B3+2):INDEX(neos_benchmark!X:X, (ROW()-2)*$B3 + $B3+1)), "") -> 0.0072645 | Y3: =IFERROR(AVERAGE(INDEX(neos_benchmark!Y:Y, (ROW()-2)*$B3+2):INDEX(neos_benchmark!Y:Y, (ROW()-2)*$B3 + $B3+1)), "") -> 0.0150399 | Z3: =IFERROR(AVERAGE(INDEX(neos_benchmark!Z:Z, (ROW()-2)*$B3+2):INDEX(neos_benchmark!Z:Z, (ROW()-2)*$B3 + $B3+1)), "") -> 0.0223044 | AA3: =IFERROR(AVERAGE(INDEX(neos_benchmark!AA:AA, (ROW()-2)*$B3+2):INDEX(neos_benchmark!AA:AA, (ROW()-2)*$B3 + $B3+1)), "") -> 0.0531001 | AB3: =IFERROR(AVERAGE(INDEX(neos_benchmark!AB:AB, (ROW()-2)*$B3+2):INDEX(neos_benchmark!AB:AB, (ROW()-2)*$B3 + $B3+1)), "") -> 0.0058382 | AC3: =IFERROR(AVERAGE(INDEX(neos_benchmark!AC:AC, (ROW()-2)*$B3+2):INDEX(neos_benchmark!AC:AC, (ROW()-2)*$B3 + $B3+1)), "") -> 0.0466557 | AD3: =IFERROR(AVERAGE(INDEX(neos_benchmark!AD:AD, (ROW()-2)*$B3+2):INDEX(neos_benchmark!AD:AD, (ROW()-2)*$B3 + $B3+1)), "") -> 0.0524939 | AE3: =IFERROR(AVERAGE(INDEX(neos_benchmark!AE:AE, (ROW()-2)*$B3+2):INDEX(neos_benchmark!AE:AE, (ROW()-2)*$B3 + $B3+1)), "") -> 4388 | AF3: =IFERROR(AVERAGE(INDEX(neos_benchmark!AF:AF, (ROW()-2)*$B3+2):INDEX(neos_benchmark!AF:AF, (ROW()-2)*$B3 + $B3+1)), "") -> 80 | AG3: =IFERROR(AVERAGE(INDEX(neos_benchmark!AG:AG, (ROW()-2)*$B3+2):INDEX(neos_benchmark!AG:AG, (ROW()-2)*$B3 + $B3+1)), "") -> 4413 | AH3: =IFERROR(AVERAGE(INDEX(neos_benchmark!AH:AH, (ROW()-2)*$B3+2):INDEX(neos_benchmark!AH:AH, (ROW()-2)*$B3 + $B3+1)), "") -> 74 | AI3: =IFERROR(AVERAGE(INDEX(neos_benchmark!AI:AI, (ROW()-2)*$B3+2):INDEX(neos_benchmark!AI:AI, (ROW()-2)*$B3 + $B3+1)), "") -> 537109 | AJ3: =IFERROR(AVERAGE(INDEX(neos_benchmark!AJ:AJ, (ROW()-2)*$B3+2):INDEX(neos_benchmark!AJ:AJ, (ROW()-2)*$B3 + $B3+1)), "") -> 564523.2 | AK3: {=IFERROR(AVERAGE(INDEX(neos_benchmark!W:W, (ROW()-2)*$B3+2):INDEX(neos_benchmark!W:W, (ROW()-2)*$B3 + $B3+1) + INDEX(neos_benchmark!AA:AA, (ROW()-2)*$B3+2):INDEX(neos_benchmark!AA:AA, (ROW()-2)*$B3 + $B3+1)), "")} -> 0.072209 | AL3: {=IFERROR(MIN(INDEX(neos_benchmark!W:W, (ROW()-2)*$B3+2):INDEX(neos_benchmark!W:W, (ROW()-2)*$B3 + $B3+1) + INDEX(neos_benchmark!AA:AA, (ROW()-2)*$B3+2):INDEX(neos_benchmark!AA:AA, (ROW()-2)*$B3 + $B3+1)), "")} -> 0.064511 | AM3: {=IFERROR(MAX(INDEX(neos_benchmark!W:W, (ROW()-2)*$B3+2):INDEX(neos_benchmark!W:W, (ROW()-2)*$B3 + $B3+1) + INDEX(neos_benchmark!AA:AA, (ROW()-2)*$B3+2):INDEX(neos_benchmark!AA:AA, (ROW()-2)*$B3 + $B3+1)), "")} -> 0.086952 | AN3: {=IFERROR(AVERAGE((INDEX(neos_benchmark!AJ:AJ, (ROW()-2)*$B3+2):INDEX(neos_benchmark!AJ:AJ, (ROW()-2)*$B3 + $B3+1) - INDEX(neos_benchmark!AI:AI, (ROW()-2)*$B3+2):INDEX(neos_benchmark!AI:AI, (ROW()-2)*$B3 + $B3+1)) / 1000), "")} -> 27.4142 | AO3: {=IFERROR(MIN((INDEX(neos_benchmark!AJ:AJ, (ROW()-2)*$B3+2):INDEX(neos_benchmark!AJ:AJ, (ROW()-2)*$B3 + $B3+1) - INDEX(neos_benchmark!AI:AI, (ROW()-2)*$B3+2):INDEX(neos_benchmark!AI:AI, (ROW()-2)*$B3 + $B3+1)) / 1000), "")} -> 4.605 | AP3: {=IFERROR(MAX((INDEX(neos_benchmark!AJ:AJ, (ROW()-2)*$B3+2):INDEX(neos_benchmark!AJ:AJ, (ROW()-2)*$B3 + $B3+1) - INDEX(neos_benchmark!AI:AI, (ROW()-2)*$B3+2):INDEX(neos_benchmark!AI:AI, (ROW()-2)*$B3 + $B3+1)) / 1000), "")} -> 102.771
A4: {=INDEX(neos_benchmark!A:A, (ROW()-2)*$B4+2)} -> cart-pendulum-utot | B4: =COUNTIF(neos_benchmark!A:A, neos_benchmark!A4) -> 10 | C4: {=INDEX(neos_benchmark!C:C, (ROW()-2)*$B4+2)} -> Ipopt | D4: {=INDEX(neos_benchmark!D:D, (ROW()-2)*$B4+2)} -> 3.14.12 | E4: {=INDEX(neos_benchmark!E:E, (ROW()-2)*$B4+2)} -> solved | F4: =IFERROR(AVERAGE(INDEX(neos_benchmark!F:F, (ROW()-2)*$B4+2):INDEX(neos_benchmark!F:F, (ROW()-2)*$B4 + $B4+1)), "") -> 0 | G4: =IFERROR(AVERAGE(INDEX(neos_benchmark!G:G, (ROW()-2)*$B4+2):INDEX(neos_benchmark!G:G, (ROW()-2)*$B4 + $B4+1)), "") -> 229.29128 | H4: =IFERROR(AVERAGE(INDEX(neos_benchmark!H:H, (ROW()-2)*$B4+2):INDEX(neos_benchmark!H:H, (ROW()-2)*$B4 + $B4+1)), "") | I4: =IFERROR(AVERAGE(INDEX(neos_benchmark!I:I, (ROW()-2)*$B4+2):INDEX(neos_benchmark!I:I, (ROW()-2)*$B4 + $B4+1)), "") -> 12 | J4: =IFERROR(AVERAGE(INDEX(neos_benchmark!J:J, (ROW()-2)*$B4+2):INDEX(neos_benchmark!J:J, (ROW()-2)*$B4 + $B4+1)), "") -> 15 | K4: =IFERROR(AVERAGE(INDEX(neos_benchmark!K:K, (ROW()-2)*$B4+2):INDEX(neos_benchmark!K:K, (ROW()-2)*$B4 + $B4+1)), "") -> 13 | L4: =IFERROR(AVERAGE(INDEX(neos_benchmark!L:L, (ROW()-2)*$B4+2):INDEX(neos_benchmark!L:L, (ROW()-2)*$B4 + $B4+1)), "") -> 15 | M4: =IFERROR(AVERAGE(INDEX(neos_benchmark!M:M, (ROW()-2)*$B4+2):INDEX(neos_benchmark!M:M, (ROW()-2)*$B4 + $B4+1)), "") -> 0 | N4: =IFERROR(AVERAGE(INDEX(neos_benchmark!N:N, (ROW()-2)*$B4+2):INDEX(neos_benchmark!N:N, (ROW()-2)*$B4 + $B4+1)), "") -> 13 | O4: =IFERROR(AVERAGE(INDEX(neos_benchmark!O:O, (ROW()-2)*$B4+2):INDEX(neos_benchmark!O:O, (ROW()-2)*$B4 + $B4+1)), "") -> 0 | P4: =IFERROR(AVERAGE(INDEX(neos_benchmark!P:P, (ROW()-2)*$B4+2):INDEX(neos_benchmark!P:P, (ROW()-2)*$B4 + $B4+1)), "") -> 12 | Q4: =IFERROR(AVERAGE(INDEX(neos_benchmark!Q:Q, (ROW()-2)*$B4+2):INDEX(neos_benchmark!Q:Q, (ROW()-2)*$B4 + $B4+1)), "") -> 2.8421709e-14 | R4: =IFERROR(AVERAGE(INDEX(neos_benchmark!R:R, (ROW()-2)*$B4+2):INDEX(neos_benchmark!R:R, (ROW()-2)*$B4 + $B4+1)), "") -> 0.0206 | S4: =IFERROR(AVERAGE(INDEX(neos_benchmark!S:S, (ROW()-2)*$B4+2):INDEX(neos_benchmark!S:S, (ROW()-2)*$B4 + $B4+1)), "") -> 0.0028 | T4: =IFERROR(AVERAGE(INDEX(neos_benchmark!T:T, (ROW()-2)*$B4+2):INDEX(neos_benchmark!T:T, (ROW()-2)*$B4 + $B4+1)), "") -> 202 | U4: =IFERROR(AVERAGE(INDEX(neos_benchmark!U:U, (ROW()-2)*$B4+2):INDEX(neos_benchmark!U:U, (ROW()-2)*$B4 + $B4+1)), "") -> 176 | V4: =IFERROR(AVERAGE(INDEX(neos_benchmark!V:V, (ROW()-2)*$B4+2):INDEX(neos_benchmark!V:V, (ROW()-2)*$B4 + $B4+1)), "") -> 0 | W4: =IFERROR(AVERAGE(INDEX(neos_benchmark!W:W, (ROW()-2)*$B4+2):INDEX(neos_benchmark!W:W, (ROW()-2)*$B4 + $B4+1)), "") -> 0.0582422 | X4: =IFERROR(AVERAGE(INDEX(neos_benchmark!X:X, (ROW()-2)*$B4+2):INDEX(neos_benchmark!X:X, (ROW()-2)*$B4 + $B4+1)), "") -> 0.0192288 | Y4: =IFERROR(AVERAGE(INDEX(neos_benchmark!Y:Y, (ROW()-2)*$B4+2):INDEX(neos_benchmark!Y:Y, (ROW()-2)*$B4 + $B4+1)), "") -> 0.0427763 | Z4: =IFERROR(AVERAGE(INDEX(neos_benchmark!Z:Z, (ROW()-2)*$B4+2):INDEX(neos_benchmark!Z:Z, (ROW()-2)*$B4 + $B4+1)), "") -> 0.0620051 | AA4: =IFERROR(AVERAGE(INDEX(neos_benchmark!AA:AA, (ROW()-2)*$B4+2):INDEX(neos_benchmark!AA:AA, (ROW()-2)*$B4 + $B4+1)), "") -> 0.0318301 | AB4: =IFERROR(AVERAGE(INDEX(neos_benchmark!AB:AB, (ROW()-2)*$B4+2):INDEX(neos_benchmark!AB:AB, (ROW()-2)*$B4 + $B4+1)), "") -> 0.0048311 | AC4: =IFERROR(AVERAGE(INDEX(neos_benchmark!AC:AC, (ROW()-2)*$B4+2):INDEX(neos_benchmark!AC:AC, (ROW()-2)*$B4 + $B4+1)), "") -> 0.0260395 | AD4: =IFERROR(AVERAGE(INDEX(neos_benchmark!AD:AD, (ROW()-2)*$B4+2):INDEX(neos_benchmark!AD:AD, (ROW()-2)*$B4 + $B4+1)), "") -> 0.0308706 | AE4: =IFERROR(AVERAGE(INDEX(neos_benchmark!AE:AE, (ROW()-2)*$B4+2):INDEX(neos_benchmark!AE:AE, (ROW()-2)*$B4 + $B4+1)), "") -> 13169 | AF4: =IFERROR(AVERAGE(INDEX(neos_benchmark!AF:AF, (ROW()-2)*$B4+2):INDEX(neos_benchmark!AF:AF, (ROW()-2)*$B4 + $B4+1)), "") -> 202 | AG4: =IFERROR(AVERAGE(INDEX(neos_benchmark!AG:AG, (ROW()-2)*$B4+2):INDEX(neos_benchmark!AG:AG, (ROW()-2)*$B4 + $B4+1)), "") -> 13234 | AH4: =IFERROR(AVERAGE(INDEX(neos_benchmark!AH:AH, (ROW()-2)*$B4+2):INDEX(neos_benchmark!AH:AH, (ROW()-2)*$B4 + $B4+1)), "") -> 176 | AI4: =IFERROR(AVERAGE(INDEX(neos_benchmark!AI:AI, (ROW()-2)*$B4+2):INDEX(neos_benchmark!AI:AI, (ROW()-2)*$B4 + $B4+1)), "") -> 577777.1 | AJ4: =IFERROR(AVERAGE(INDEX(neos_benchmark!AJ:AJ, (ROW()-2)*$B4+2):INDEX(neos_benchmark!AJ:AJ, (ROW()-2)*$B4 + $B4+1)), "") -> 600161.5 | AK4: {=IFERROR(AVERAGE(INDEX(neos_benchmark!W:W, (ROW()-2)*$B4+2):INDEX(neos_benchmark!W:W, (ROW()-2)*$B4 + $B4+1) + INDEX(neos_benchmark!AA:AA, (ROW()-2)*$B4+2):INDEX(neos_benchmark!AA:AA, (ROW()-2)*$B4 + $B4+1)), "")} -> 0.0900723 | AL4: {=IFERROR(MIN(INDEX(neos_benchmark!W:W, (ROW()-2)*$B4+2):INDEX(neos_benchmark!W:W, (ROW()-2)*$B4 + $B4+1) + INDEX(neos_benchmark!AA:AA, (ROW()-2)*$B4+2):INDEX(neos_benchmark!AA:AA, (ROW()-2)*$B4 + $B4+1)), "")} -> 0.072109 | AM4: {=IFERROR(MAX(INDEX(neos_benchmark!W:W, (ROW()-2)*$B4+2):INDEX(neos_benchmark!W:W, (ROW()-2)*$B4 + $B4+1) + INDEX(neos_benchmark!AA:AA, (ROW()-2)*$B4+2):INDEX(neos_benchmark!AA:AA, (ROW()-2)*$B4 + $B4+1)), "")} -> 0.127163 | AN4: {=IFERROR(AVERAGE((INDEX(neos_benchmark!AJ:AJ, (ROW()-2)*$B4+2):INDEX(neos_benchmark!AJ:AJ, (ROW()-2)*$B4 + $B4+1) - INDEX(neos_benchmark!AI:AI, (ROW()-2)*$B4+2):INDEX(neos_benchmark!AI:AI, (ROW()-2)*$B4 + $B4+1)) / 1000), "")} -> 22.3844 | AO4: {=IFERROR(MIN((INDEX(neos_benchmark!AJ:AJ, (ROW()-2)*$B4+2):INDEX(neos_benchmark!AJ:AJ, (ROW()-2)*$B4 + $B4+1) - INDEX(neos_benchmark!AI:AI, (ROW()-2)*$B4+2):INDEX(neos_benchmark!AI:AI, (ROW()-2)*$B4 + $B4+1)) / 1000), "")} -> 4.453 | AP4: {=IFERROR(MAX((INDEX(neos_benchmark!AJ:AJ, (ROW()-2)*$B4+2):INDEX(neos_benchmark!AJ:AJ, (ROW()-2)*$B4 + $B4+1) - INDEX(neos_benchmark!AI:AI, (ROW()-2)*$B4+2):INDEX(neos_benchmark!AI:AI, (ROW()-2)*$B4 + $B4+1)) / 1000), "")} -> 136.307
A5: {=INDEX(neos_benchmark!A:A, (ROW()-2)*$B5+2)} -> five-link-mc-kelly | B5: =COUNTIF(neos_benchmark!A:A, neos_benchmark!A5) -> 10 | C5: {=INDEX(neos_benchmark!C:C, (ROW()-2)*$B5+2)} -> Ipopt | D5: {=INDEX(neos_benchmark!D:D, (ROW()-2)*$B5+2)} -> 3.14.12 | E5: {=INDEX(neos_benchmark!E:E, (ROW()-2)*$B5+2)} -> solved | F5: =IFERROR(AVERAGE(INDEX(neos_benchmark!F:F, (ROW()-2)*$B5+2):INDEX(neos_benchmark!F:F, (ROW()-2)*$B5 + $B5+1)), "") -> 0 | G5: =IFERROR(AVERAGE(INDEX(neos_benchmark!G:G, (ROW()-2)*$B5+2):INDEX(neos_benchmark!G:G, (ROW()-2)*$B5 + $B5+1)), "") -> 260.43009 | H5: =IFERROR(AVERAGE(INDEX(neos_benchmark!H:H, (ROW()-2)*$B5+2):INDEX(neos_benchmark!H:H, (ROW()-2)*$B5 + $B5+1)), "") | I5: =IFERROR(AVERAGE(INDEX(neos_benchmark!I:I, (ROW()-2)*$B5+2):INDEX(neos_benchmark!I:I, (ROW()-2)*$B5 + $B5+1)), "") -> 11 | J5: =IFERROR(AVERAGE(INDEX(neos_benchmark!J:J, (ROW()-2)*$B5+2):INDEX(neos_benchmark!J:J, (ROW()-2)*$B5 + $B5+1)), "") -> 12 | K5: =IFERROR(AVERAGE(INDEX(neos_benchmark!K:K, (ROW()-2)*$B5+2):INDEX(neos_benchmark!K:K, (ROW()-2)*$B5 + $B5+1)), "") -> 12 | L5: =IFERROR(AVERAGE(INDEX(neos_benchmark!L:L, (ROW()-2)*$B5+2):INDEX(neos_benchmark!L:L, (ROW()-2)*$B5 + $B5+1)), "") -> 12 | M5: =IFERROR(AVERAGE(INDEX(neos_benchmark!M:M, (ROW()-2)*$B5+2):INDEX(neos_benchmark!M:M, (ROW()-2)*$B5 + $B5+1)), "") -> 12 | N5: =IFERROR(AVERAGE(INDEX(neos_benchmark!N:N, (ROW()-2)*$B5+2):INDEX(neos_benchmark!N:N, (ROW()-2)*$B5 + $B5+1)), "") -> 12 | O5: =IFERROR(AVERAGE(INDEX(neos_benchmark!O:O, (ROW()-2)*$B5+2):INDEX(neos_benchmark!O:O, (ROW()-2)*$B5 + $B5+1)), "") -> 12 | P5: =IFERROR(AVERAGE(INDEX(neos_benchmark!P:P, (ROW()-2)*$B5+2):INDEX(neos_benchmark!P:P, (ROW()-2)*$B5 + $B5+1)), "") -> 11 | Q5: =IFERROR(AVERAGE(INDEX(neos_benchmark!Q:Q, (ROW()-2)*$B5+2):INDEX(neos_benchmark!Q:Q, (ROW()-2)*$B5 + $B5+1)), "") -> 1.0452084e-12 | R5: =IFERROR(AVERAGE(INDEX(neos_benchmark!R:R, (ROW()-2)*$B5+2):INDEX(neos_benchmark!R:R, (ROW()-2)*$B5 + $B5+1)), "") -> 0.0359 | S5: =IFERROR(AVERAGE(INDEX(neos_benchmark!S:S, (ROW()-2)*$B5+2):INDEX(neos_benchmark!S:S, (ROW()-2)*$B5 + $B5+1)), "") -> 0.0942 | T5: =IFERROR(AVERAGE(INDEX(neos_benchmark!T:T, (ROW()-2)*$B5+2):INDEX(neos_benchmark!T:T, (ROW()-2)*$B5 + $B5+1)), "") -> 266 | U5: =IFERROR(AVERAGE(INDEX(neos_benchmark!U:U, (ROW()-2)*$B5+2):INDEX(neos_benchmark!U:U, (ROW()-2)*$B5 + $B5+1)), "") -> 212 | V5: =IFERROR(AVERAGE(INDEX(neos_benchmark!V:V, (ROW()-2)*$B5+2):INDEX(neos_benchmark!V:V, (ROW()-2)*$B5 + $B5+1)), "") -> 2 | W5: =IFERROR(AVERAGE(INDEX(neos_benchmark!W:W, (ROW()-2)*$B5+2):INDEX(neos_benchmark!W:W, (ROW()-2)*$B5 + $B5+1)), "") -> 0.5183703 | X5: =IFERROR(AVERAGE(INDEX(neos_benchmark!X:X, (ROW()-2)*$B5+2):INDEX(neos_benchmark!X:X, (ROW()-2)*$B5 + $B5+1)), "") -> 0.0794248 | Y5: =IFERROR(AVERAGE(INDEX(neos_benchmark!Y:Y, (ROW()-2)*$B5+2):INDEX(neos_benchmark!Y:Y, (ROW()-2)*$B5 + $B5+1)), "") -> 0.4433167 | Z5: =IFERROR(AVERAGE(INDEX(neos_benchmark!Z:Z, (ROW()-2)*$B5+2):INDEX(neos_benchmark!Z:Z, (ROW()-2)*$B5 + $B5+1)), "") -> 0.5227415 | AA5: =IFERROR(AVERAGE(INDEX(neos_benchmark!AA:AA, (ROW()-2)*$B5+2):INDEX(neos_benchmark!AA:AA, (ROW()-2)*$B5 + $B5+1)), "") -> 0.1684638 | AB5: =IFERROR(AVERAGE(INDEX(neos_benchmark!AB:AB, (ROW()-2)*$B5+2):INDEX(neos_benchmark!AB:AB, (ROW()-2)*$B5 + $B5+1)), "") -> 0.0128779 | AC5: =IFERROR(AVERAGE(INDEX(neos_benchmark!AC:AC, (ROW()-2)*$B5+2):INDEX(neos_benchmark!AC:AC, (ROW()-2)*$B5 + $B5+1)), "") -> 0.1522315 | AD5: =IFERROR(AVERAGE(INDEX(neos_benchmark!AD:AD, (ROW()-2)*$B5+2):INDEX(neos_benchmark!AD:AD, (ROW()-2)*$B5 + $B5+1)), "") -> 0.1651094 | AE5: =IFERROR(AVERAGE(INDEX(neos_benchmark!AE:AE, (ROW()-2)*$B5+2):INDEX(neos_benchmark!AE:AE, (ROW()-2)*$B5 + $B5+1)), "") -> 99109 | AF5: =IFERROR(AVERAGE(INDEX(neos_benchmark!AF:AF, (ROW()-2)*$B5+2):INDEX(neos_benchmark!AF:AF, (ROW()-2)*$B5 + $B5+1)), "") -> 266 | AG5: =IFERROR(AVERAGE(INDEX(neos_benchmark!AG:AG, (ROW()-2)*$B5+2):INDEX(neos_benchmark!AG:AG, (ROW()-2)*$B5 + $B5+1)), "") -> 98877 | AH5: =IFERROR(AVERAGE(INDEX(neos_benchmark!AH:AH, (ROW()-2)*$B5+2):INDEX(neos_benchmark!AH:AH, (ROW()-2)*$B5 + $B5+1)), "") -> 214 | AI5: =IFERROR(AVERAGE(INDEX(neos_benchmark!AI:AI, (ROW()-2)*$B5+2):INDEX(neos_benchmark!AI:AI, (ROW()-2)*$B5 + $B5+1)), "") -> 573076.1 | AJ5: =IFERROR(AVERAGE(INDEX(neos_benchmark!AJ:AJ, (ROW()-2)*$B5+2):INDEX(neos_benchmark!AJ:AJ, (ROW()-2)*$B5 + $B5+1)), "") -> 583232.5 | AK5: {=IFERROR(AVERAGE(INDEX(neos_benchmark!W:W, (ROW()-2)*$B5+2):INDEX(neos_benchmark!W:W, (ROW()-2)*$B5 + $B5+1) + INDEX(neos_benchmark!AA:AA, (ROW()-2)*$B5+2):INDEX(neos_benchmark!AA:AA, (ROW()-2)*$B5 + $B5+1)), "")} -> 0.6868341 | AL5: {=IFERROR(MIN(INDEX(neos_benchmark!W:W, (ROW()-2)*$B5+2):INDEX(neos_benchmark!W:W, (ROW()-2)*$B5 + $B5+1) + INDEX(neos_benchmark!AA:AA, (ROW()-2)*$B5+2):INDEX(neos_benchmark!AA:AA, (ROW()-2)*$B5 + $B5+1)), "")} -> 0.511757 | AM5: {=IFERROR(MAX(INDEX(neos_benchmark!W:W, (ROW()-2)*$B5+2):INDEX(neos_benchmark!W:W, (ROW()-2)*$B5 + $B5+1) + INDEX(neos_benchmark!AA:AA, (ROW()-2)*$B5+2):INDEX(neos_benchmark!AA:AA, (ROW()-2)*$B5 + $B5+1)), "")} -> 0.934226 | AN5: {=IFERROR(AVERAGE((INDEX(neos_benchmark!AJ:AJ, (ROW()-2)*$B5+2):INDEX(neos_benchmark!AJ:AJ, (ROW()-2)*$B5 + $B5+1) - INDEX(neos_benchmark!AI:AI, (ROW()-2)*$B5+2):INDEX(neos_benchmark!AI:AI, (ROW()-2)*$B5 + $B5+1)) / 1000), "")} -> 10.1564 | AO5: {=IFERROR(MIN((INDEX(neos_benchmark!AJ:AJ, (ROW()-2)*$B5+2):INDEX(neos_benchmark!AJ:AJ, (ROW()-2)*$B5 + $B5+1) - INDEX(neos_benchmark!AI:AI, (ROW()-2)*$B5+2):INDEX(neos_benchmark!AI:AI, (ROW()-2)*$B5 + $B5+1)) / 1000), "")} -> 5.603 | AP5: {=IFERROR(MAX((INDEX(neos_benchmark!AJ:AJ, (ROW()-2)*$B5+2):INDEX(neos_benchmark!AJ:AJ, (ROW()-2)*$B5 + $B5+1) - INDEX(neos_benchmark!AI:AI, (ROW()-2)*$B5+2):INDEX(neos_benchmark!AI:AI, (ROW()-2)*$B5 + $B5+1)) / 1000), "")} -> 21.165
A6: {=INDEX(neos_benchmark!A:A, (ROW()-2)*$B6+2)} -> five-link-phc-kelly | B6: =COUNTIF(neos_benchmark!A:A, neos_benchmark!A6) -> 10 | C6: {=INDEX(neos_benchmark!C:C, (ROW()-2)*$B6+2)} -> Ipopt | D6: {=INDEX(neos_benchmark!D:D, (ROW()-2)*$B6+2)} -> 3.14.12 | E6: {=INDEX(neos_benchmark!E:E, (ROW()-2)*$B6+2)} -> solved | F6: =IFERROR(AVERAGE(INDEX(neos_benchmark!F:F, (ROW()-2)*$B6+2):INDEX(neos_benchmark!F:F, (ROW()-2)*$B6 + $B6+1)), "") -> 0 | G6: =IFERROR(AVERAGE(INDEX(neos_benchmark!G:G, (ROW()-2)*$B6+2):INDEX(neos_benchmark!G:G, (ROW()-2)*$B6 + $B6+1)), "") -> 443.14228 | H6: =IFERROR(AVERAGE(INDEX(neos_benchmark!H:H, (ROW()-2)*$B6+2):INDEX(neos_benchmark!H:H, (ROW()-2)*$B6 + $B6+1)), "") | I6: =IFERROR(AVERAGE(INDEX(neos_benchmark!I:I, (ROW()-2)*$B6+2):INDEX(neos_benchmark!I:I, (ROW()-2)*$B6 + $B6+1)), "") -> 14 | J6: =IFERROR(AVERAGE(INDEX(neos_benchmark!J:J, (ROW()-2)*$B6+2):INDEX(neos_benchmark!J:J, (ROW()-2)*$B6 + $B6+1)), "") -> 15 | K6: =IFERROR(AVERAGE(INDEX(neos_benchmark!K:K, (ROW()-2)*$B6+2):INDEX(neos_benchmark!K:K, (ROW()-2)*$B6 + $B6+1)), "") -> 15 | L6: =IFERROR(AVERAGE(INDEX(neos_benchmark!L:L, (ROW()-2)*$B6+2):INDEX(neos_benchmark!L:L, (ROW()-2)*$B6 + $B6+1)), "") -> 15 | M6: =IFERROR(AVERAGE(INDEX(neos_benchmark!M:M, (ROW()-2)*$B6+2):INDEX(neos_benchmark!M:M, (ROW()-2)*$B6 + $B6+1)), "") -> 15 | N6: =IFERROR(AVERAGE(INDEX(neos_benchmark!N:N, (ROW()-2)*$B6+2):INDEX(neos_benchmark!N:N, (ROW()-2)*$B6 + $B6+1)), "") -> 15 | O6: =IFERROR(AVERAGE(INDEX(neos_benchmark!O:O, (ROW()-2)*$B6+2):INDEX(neos_benchmark!O:O, (ROW()-2)*$B6 + $B6+1)), "") -> 15 | P6: =IFERROR(AVERAGE(INDEX(neos_benchmark!P:P, (ROW()-2)*$B6+2):INDEX(neos_benchmark!P:P, (ROW()-2)*$B6 + $B6+1)), "") -> 14 | Q6: =IFERROR(AVERAGE(INDEX(neos_benchmark!Q:Q, (ROW()-2)*$B6+2):INDEX(neos_benchmark!Q:Q, (ROW()-2)*$B6 + $B6+1)), "") -> 1.4551915e-11 | R6: =IFERROR(AVERAGE(INDEX(neos_benchmark!R:R, (ROW()-2)*$B6+2):INDEX(neos_benchmark!R:R, (ROW()-2)*$B6 + $B6+1)), "") -> 0.1011 | S6: =IFERROR(AVERAGE(INDEX(neos_benchmark!S:S, (ROW()-2)*$B6+2):INDEX(neos_benchmark!S:S, (ROW()-2)*$B6 + $B6+1)), "") -> 0.2022 | T6: =IFERROR(AVERAGE(INDEX(neos_benchmark!T:T, (ROW()-2)*$B6+2):INDEX(neos_benchmark!T:T, (ROW()-2)*$B6 + $B6+1)), "") -> 326 | U6: =IFERROR(AVERAGE(INDEX(neos_benchmark!U:U, (ROW()-2)*$B6+2):INDEX(neos_benchmark!U:U, (ROW()-2)*$B6 + $B6+1)), "") -> 300 | V6: =IFERROR(AVERAGE(INDEX(neos_benchmark!V:V, (ROW()-2)*$B6+2):INDEX(neos_benchmark!V:V, (ROW()-2)*$B6 + $B6+1)), "") -> 2 | W6: =IFERROR(AVERAGE(INDEX(neos_benchmark!W:W, (ROW()-2)*$B6+2):INDEX(neos_benchmark!W:W, (ROW()-2)*$B6 + $B6+1)), "") -> 0.3052884 | X6: =IFERROR(AVERAGE(INDEX(neos_benchmark!X:X, (ROW()-2)*$B6+2):INDEX(neos_benchmark!X:X, (ROW()-2)*$B6 + $B6+1)), "") -> 0.0548487 | Y6: =IFERROR(AVERAGE(INDEX(neos_benchmark!Y:Y, (ROW()-2)*$B6+2):INDEX(neos_benchmark!Y:Y, (ROW()-2)*$B6 + $B6+1)), "") -> 0.2550113 | Z6: =IFERROR(AVERAGE(INDEX(neos_benchmark!Z:Z, (ROW()-2)*$B6+2):INDEX(neos_benchmark!Z:Z, (ROW()-2)*$B6 + $B6+1)), "") -> 0.30986 | AA6: =IFERROR(AVERAGE(INDEX(neos_benchmark!AA:AA, (ROW()-2)*$B6+2):INDEX(neos_benchmark!AA:AA, (ROW()-2)*$B6 + $B6+1)), "") -> 0.3563615 | AB6: =IFERROR(AVERAGE(INDEX(neos_benchmark!AB:AB, (ROW()-2)*$B6+2):INDEX(neos_benchmark!AB:AB, (ROW()-2)*$B6 + $B6+1)), "") -> 0.0128023 | AC6: =IFERROR(AVERAGE(INDEX(neos_benchmark!AC:AC, (ROW()-2)*$B6+2):INDEX(neos_benchmark!AC:AC, (ROW()-2)*$B6 + $B6+1)), "") -> 0.3364702 | AD6: =IFERROR(AVERAGE(INDEX(neos_benchmark!AD:AD, (ROW()-2)*$B6+2):INDEX(neos_benchmark!AD:AD, (ROW()-2)*$B6 + $B6+1)), "") -> 0.3492725 | AE6: =IFERROR(AVERAGE(INDEX(neos_benchmark!AE:AE, (ROW()-2)*$B6+2):INDEX(neos_benchmark!AE:AE, (ROW()-2)*$B6 + $B6+1)), "") -> 46821 | AF6: =IFERROR(AVERAGE(INDEX(neos_benchmark!AF:AF, (ROW()-2)*$B6+2):INDEX(neos_benchmark!AF:AF, (ROW()-2)*$B6 + $B6+1)), "") -> 326 | AG6: =IFERROR(AVERAGE(INDEX(neos_benchmark!AG:AG, (ROW()-2)*$B6+2):INDEX(neos_benchmark!AG:AG, (ROW()-2)*$B6 + $B6+1)), "") -> 46820 | AH6: =IFERROR(AVERAGE(INDEX(neos_benchmark!AH:AH, (ROW()-2)*$B6+2):INDEX(neos_benchmark!AH:AH, (ROW()-2)*$B6 + $B6+1)), "") -> 302 | AI6: =IFERROR(AVERAGE(INDEX(neos_benchmark!AI:AI, (ROW()-2)*$B6+2):INDEX(neos_benchmark!AI:AI, (ROW()-2)*$B6 + $B6+1)), "") -> 568841.4 | AJ6: =IFERROR(AVERAGE(INDEX(neos_benchmark!AJ:AJ, (ROW()-2)*$B6+2):INDEX(neos_benchmark!AJ:AJ, (ROW()-2)*$B6 + $B6+1)), "") -> 581257.1 | AK6: {=IFERROR(AVERAGE(INDEX(neos_benchmark!W:W, (ROW()-2)*$B6+2):INDEX(neos_benchmark!W:W, (ROW()-2)*$B6 + $B6+1) + INDEX(neos_benchmark!AA:AA, (ROW()-2)*$B6+2):INDEX(neos_benchmark!AA:AA, (ROW()-2)*$B6 + $B6+1)), "")} -> 0.6616499 | AL6: {=IFERROR(MIN(INDEX(neos_benchmark!W:W, (ROW()-2)*$B6+2):INDEX(neos_benchmark!W:W, (ROW()-2)*$B6 + $B6+1) + INDEX(neos_benchmark!AA:AA, (ROW()-2)*$B6+2):INDEX(neos_benchmark!AA:AA, (ROW()-2)*$B6 + $B6+1)), "")} -> 0.447201 | AM6: {=IFERROR(MAX(INDEX(neos_benchmark!W:W, (ROW()-2)*$B6+2):INDEX(neos_benchmark!W:W, (ROW()-2)*$B6 + $B6+1) + INDEX(neos_benchmark!AA:AA, (ROW()-2)*$B6+2):INDEX(neos_benchmark!AA:AA, (ROW()-2)*$B6 + $B6+1)), "")} -> 0.917913 | AN6: {=IFERROR(AVERAGE((INDEX(neos_benchmark!AJ:AJ, (ROW()-2)*$B6+2):INDEX(neos_benchmark!AJ:AJ, (ROW()-2)*$B6 + $B6+1) - INDEX(neos_benchmark!AI:AI, (ROW()-2)*$B6+2):INDEX(neos_benchmark!AI:AI, (ROW()-2)*$B6 + $B6+1)) / 1000), "")} -> 12.4157 | AO6: {=IFERROR(MIN((INDEX(neos_benchmark!AJ:AJ, (ROW()-2)*$B6+2):INDEX(neos_benchmark!AJ:AJ, (ROW()-2)*$B6 + $B6+1) - INDEX(neos_benchmark!AI:AI, (ROW()-2)*$B6+2):INDEX(neos_benchmark!AI:AI, (ROW()-2)*$B6 + $B6+1)) / 1000), "")} -> 6.426 | AP6: {=IFERROR(MAX((INDEX(neos_benchmark!AJ:AJ, (ROW()-2)*$B6+2):INDEX(neos_benchmark!AJ:AJ, (ROW()-2)*$B6 + $B6+1) - INDEX(neos_benchmark!AI:AI, (ROW()-2)*$B6+2):INDEX(neos_benchmark!AI:AI, (ROW()-2)*$B6 + $B6+1)) / 1000), "")} -> 17.665
A7: {=INDEX(neos_benchmark!A:A, (ROW()-2)*$B7+2)} -> five-link-tropic | B7: =COUNTIF(neos_benchmark!A:A, neos_benchmark!A7) -> 10 | C7: {=INDEX(neos_benchmark!C:C, (ROW()-2)*$B7+2)} -> Ipopt | D7: {=INDEX(neos_benchmark!D:D, (ROW()-2)*$B7+2)} -> 3.14.12 | E7: {=INDEX(neos_benchmark!E:E, (ROW()-2)*$B7+2)} -> solved | F7: =IFERROR(AVERAGE(INDEX(neos_benchmark!F:F, (ROW()-2)*$B7+2):INDEX(neos_benchmark!F:F, (ROW()-2)*$B7 + $B7+1)), "") -> 0 | G7: =IFERROR(AVERAGE(INDEX(neos_benchmark!G:G, (ROW()-2)*$B7+2):INDEX(neos_benchmark!G:G, (ROW()-2)*$B7 + $B7+1)), "") -> 5.7300002 | H7: =IFERROR(AVERAGE(INDEX(neos_benchmark!H:H, (ROW()-2)*$B7+2):INDEX(neos_benchmark!H:H, (ROW()-2)*$B7 + $B7+1)), "") | I7: =IFERROR(AVERAGE(INDEX(neos_benchmark!I:I, (ROW()-2)*$B7+2):INDEX(neos_benchmark!I:I, (ROW()-2)*$B7 + $B7+1)), "") -> 161 | J7: =IFERROR(AVERAGE(INDEX(neos_benchmark!J:J, (ROW()-2)*$B7+2):INDEX(neos_benchmark!J:J, (ROW()-2)*$B7 + $B7+1)), "") -> 186 | K7: =IFERROR(AVERAGE(INDEX(neos_benchmark!K:K, (ROW()-2)*$B7+2):INDEX(neos_benchmark!K:K, (ROW()-2)*$B7 + $B7+1)), "") -> 162 | L7: =IFERROR(AVERAGE(INDEX(neos_benchmark!L:L, (ROW()-2)*$B7+2):INDEX(neos_benchmark!L:L, (ROW()-2)*$B7 + $B7+1)), "") -> 186 | M7: =IFERROR(AVERAGE(INDEX(neos_benchmark!M:M, (ROW()-2)*$B7+2):INDEX(neos_benchmark!M:M, (ROW()-2)*$B7 + $B7+1)), "") -> 186 | N7: =IFERROR(AVERAGE(INDEX(neos_benchmark!N:N, (ROW()-2)*$B7+2):INDEX(neos_benchmark!N:N, (ROW()-2)*$B7 + $B7+1)), "") -> 164 | O7: =IFERROR(AVERAGE(INDEX(neos_benchmark!O:O, (ROW()-2)*$B7+2):INDEX(neos_benchmark!O:O, (ROW()-2)*$B7 + $B7+1)), "") -> 164 | P7: =IFERROR(AVERAGE(INDEX(neos_benchmark!P:P, (ROW()-2)*$B7+2):INDEX(neos_benchmark!P:P, (ROW()-2)*$B7 + $B7+1)), "") -> 161 | Q7: =IFERROR(AVERAGE(INDEX(neos_benchmark!Q:Q, (ROW()-2)*$B7+2):INDEX(neos_benchmark!Q:Q, (ROW()-2)*$B7 + $B7+1)), "") -> 4.8149573e-10 | R7: =IFERROR(AVERAGE(INDEX(neos_benchmark!R:R, (ROW()-2)*$B7+2):INDEX(neos_benchmark!R:R, (ROW()-2)*$B7 + $B7+1)), "") -> 13.4734 | S7: =IFERROR(AVERAGE(INDEX(neos_benchmark!S:S, (ROW()-2)*$B7+2):INDEX(neos_benchmark!S:S, (ROW()-2)*$B7 + $B7+1)), "") -> 19.8147 | T7: =IFERROR(AVERAGE(INDEX(neos_benchmark!T:T, (ROW()-2)*$B7+2):INDEX(neos_benchmark!T:T, (ROW()-2)*$B7 + $B7+1)), "") -> 2345 | U7: =IFERROR(AVERAGE(INDEX(neos_benchmark!U:U, (ROW()-2)*$B7+2):INDEX(neos_benchmark!U:U, (ROW()-2)*$B7 + $B7+1)), "") -> 2331 | V7: =IFERROR(AVERAGE(INDEX(neos_benchmark!V:V, (ROW()-2)*$B7+2):INDEX(neos_benchmark!V:V, (ROW()-2)*$B7 + $B7+1)), "") -> 206 | W7: =IFERROR(AVERAGE(INDEX(neos_benchmark!W:W, (ROW()-2)*$B7+2):INDEX(neos_benchmark!W:W, (ROW()-2)*$B7 + $B7+1)), "") -> 2.6255252 | X7: =IFERROR(AVERAGE(INDEX(neos_benchmark!X:X, (ROW()-2)*$B7+2):INDEX(neos_benchmark!X:X, (ROW()-2)*$B7 + $B7+1)), "") -> 0.3267402 | Y7: =IFERROR(AVERAGE(INDEX(neos_benchmark!Y:Y, (ROW()-2)*$B7+2):INDEX(neos_benchmark!Y:Y, (ROW()-2)*$B7 + $B7+1)), "") -> 2.3048189 | Z7: =IFERROR(AVERAGE(INDEX(neos_benchmark!Z:Z, (ROW()-2)*$B7+2):INDEX(neos_benchmark!Z:Z, (ROW()-2)*$B7 + $B7+1)), "") -> 2.6315591 | AA7: =IFERROR(AVERAGE(INDEX(neos_benchmark!AA:AA, (ROW()-2)*$B7+2):INDEX(neos_benchmark!AA:AA, (ROW()-2)*$B7 + $B7+1)), "") -> 33.628937 | AB7: =IFERROR(AVERAGE(INDEX(neos_benchmark!AB:AB, (ROW()-2)*$B7+2):INDEX(neos_benchmark!AB:AB, (ROW()-2)*$B7 + $B7+1)), "") -> 0.084947 | AC7: =IFERROR(AVERAGE(INDEX(neos_benchmark!AC:AC, (ROW()-2)*$B7+2):INDEX(neos_benchmark!AC:AC, (ROW()-2)*$B7 + $B7+1)), "") -> 33.438063 | AD7: =IFERROR(AVERAGE(INDEX(neos_benchmark!AD:AD, (ROW()-2)*$B7+2):INDEX(neos_benchmark!AD:AD, (ROW()-2)*$B7 + $B7+1)), "") -> 33.52301 | AE7: =IFERROR(AVERAGE(INDEX(neos_benchmark!AE:AE, (ROW()-2)*$B7+2):INDEX(neos_benchmark!AE:AE, (ROW()-2)*$B7 + $B7+1)), "") -> 371155 | AF7: =IFERROR(AVERAGE(INDEX(neos_benchmark!AF:AF, (ROW()-2)*$B7+2):INDEX(neos_benchmark!AF:AF, (ROW()-2)*$B7 + $B7+1)), "") -> 2345 | AG7: =IFERROR(AVERAGE(INDEX(neos_benchmark!AG:AG, (ROW()-2)*$B7+2):INDEX(neos_benchmark!AG:AG, (ROW()-2)*$B7 + $B7+1)), "") -> 372492 | AH7: =IFERROR(AVERAGE(INDEX(neos_benchmark!AH:AH, (ROW()-2)*$B7+2):INDEX(neos_benchmark!AH:AH, (ROW()-2)*$B7 + $B7+1)), "") -> 2537 | AI7: =IFERROR(AVERAGE(INDEX(neos_benchmark!AI:AI, (ROW()-2)*$B7+2):INDEX(neos_benchmark!AI:AI, (ROW()-2)*$B7 + $B7+1)), "") -> 698863.8 | AJ7: =IFERROR(AVERAGE(INDEX(neos_benchmark!AJ:AJ, (ROW()-2)*$B7+2):INDEX(neos_benchmark!AJ:AJ, (ROW()-2)*$B7 + $B7+1)), "") -> 768875 | AK7: {=IFERROR(AVERAGE(INDEX(neos_benchmark!W:W, (ROW()-2)*$B7+2):INDEX(neos_benchmark!W:W, (ROW()-2)*$B7 + $B7+1) + INDEX(neos_benchmark!AA:AA, (ROW()-2)*$B7+2):INDEX(neos_benchmark!AA:AA, (ROW()-2)*$B7 + $B7+1)), "")} -> 36.254462 | AL7: {=IFERROR(MIN(INDEX(neos_benchmark!W:W, (ROW()-2)*$B7+2):INDEX(neos_benchmark!W:W, (ROW()-2)*$B7 + $B7+1) + INDEX(neos_benchmark!AA:AA, (ROW()-2)*$B7+2):INDEX(neos_benchmark!AA:AA, (ROW()-2)*$B7 + $B7+1)), "")} -> 30.205931 | AM7: {=IFERROR(MAX(INDEX(neos_benchmark!W:W, (ROW()-2)*$B7+2):INDEX(neos_benchmark!W:W, (ROW()-2)*$B7 + $B7+1) + INDEX(neos_benchmark!AA:AA, (ROW()-2)*$B7+2):INDEX(neos_benchmark!AA:AA, (ROW()-2)*$B7 + $B7+1)), "")} -> 53.456733 | AN7: {=IFERROR(AVERAGE((INDEX(neos_benchmark!AJ:AJ, (ROW()-2)*$B7+2):INDEX(neos_benchmark!AJ:AJ, (ROW()-2)*$B7 + $B7+1) - INDEX(neos_benchmark!AI:AI, (ROW()-2)*$B7+2):INDEX(neos_benchmark!AI:AI, (ROW()-2)*$B7 + $B7+1)) / 1000), "")} -> 70.0112 | AO7: {=IFERROR(MIN((INDEX(neos_benchmark!AJ:AJ, (ROW()-2)*$B7+2):INDEX(neos_benchmark!AJ:AJ, (ROW()-2)*$B7 + $B7+1) - INDEX(neos_benchmark!AI:AI, (ROW()-2)*$B7+2):INDEX(neos_benchmark!AI:AI, (ROW()-2)*$B7 + $B7+1)) / 1000), "")} -> 43.081 | AP7: {=IFERROR(MAX((INDEX(neos_benchmark!AJ:AJ, (ROW()-2)*$B7+2):INDEX(neos_benchmark!AJ:AJ, (ROW()-2)*$B7 + $B7+1) - INDEX(neos_benchmark!AI:AI, (ROW()-2)*$B7+2):INDEX(neos_benchmark!AI:AI, (ROW()-2)*$B7 + $B7+1)) / 1000), "")} -> 99.629
A8: {=INDEX(neos_benchmark!A:A, (ROW()-2)*$B8+2)} -> grasp-cbc | B8: =COUNTIF(neos_benchmark!A:A, neos_benchmark!A8) -> 10 | C8: {=INDEX(neos_benchmark!C:C, (ROW()-2)*$B8+2)} -> CBC | D8: {=INDEX(neos_benchmark!D:D, (ROW()-2)*$B8+2)} -> 2.10.10 | E8: {=INDEX(neos_benchmark!E:E, (ROW()-2)*$B8+2)} | F8: =IFERROR(AVERAGE(INDEX(neos_benchmark!F:F, (ROW()-2)*$B8+2):INDEX(neos_benchmark!F:F, (ROW()-2)*$B8 + $B8+1)), "") | G8: =IFERROR(AVERAGE(INDEX(neos_benchmark!G:G, (ROW()-2)*$B8+2):INDEX(neos_benchmark!G:G, (ROW()-2)*$B8 + $B8+1)), "") | H8: =IFERROR(AVERAGE(INDEX(neos_benchmark!H:H, (ROW()-2)*$B8+2):INDEX(neos_benchmark!H:H, (ROW()-2)*$B8 + $B8+1)), "") | I8: =IFERROR(AVERAGE(INDEX(neos_benchmark!I:I, (ROW()-2)*$B8+2):INDEX(neos_benchmark!I:I, (ROW()-2)*$B8 + $B8+1)), "") | J8: =IFERROR(AVERAGE(INDEX(neos_benchmark!J:J, (ROW()-2)*$B8+2):INDEX(neos_benchmark!J:J, (ROW()-2)*$B8 + $B8+1)), "") | K8: =IFERROR(AVERAGE(INDEX(neos_benchmark!K:K, (ROW()-2)*$B8+2):INDEX(neos_benchmark!K:K, (ROW()-2)*$B8 + $B8+1)), "") | L8: =IFERROR(AVERAGE(INDEX(neos_benchmark!L:L, (ROW()-2)*$B8+2):INDEX(neos_benchmark!L:L, (ROW()-2)*$B8 + $B8+1)), "") | M8: =IFERROR(AVERAGE(INDEX(neos_benchmark!M:M, (ROW()-2)*$B8+2):INDEX(neos_benchmark!M:M, (ROW()-2)*$B8 + $B8+1)), "") | N8: =IFERROR(AVERAGE(INDEX(neos_benchmark!N:N, (ROW()-2)*$B8+2):INDEX(neos_benchmark!N:N, (ROW()-2)*$B8 + $B8+1)), "") | O8: =IFERROR(AVERAGE(INDEX(neos_benchmark!O:O, (ROW()-2)*$B8+2):INDEX(neos_benchmark!O:O, (ROW()-2)*$B8 + $B8+1)), "") | P8: =IFERROR(AVERAGE(INDEX(neos_benchmark!P:P, (ROW()-2)*$B8+2):INDEX(neos_benchmark!P:P, (ROW()-2)*$B8 + $B8+1)), "") | Q8: =IFERROR(AVERAGE(INDEX(neos_benchmark!Q:Q, (ROW()-2)*$B8+2):INDEX(neos_benchmark!Q:Q, (ROW()-2)*$B8 + $B8+1)), "") | R8: =IFERROR(AVERAGE(INDEX(neos_benchmark!R:R, (ROW()-2)*$B8+2):INDEX(neos_benchmark!R:R, (ROW()-2)*$B8 + $B8+1)), "") | S8: =IFERROR(AVERAGE(INDEX(neos_benchmark!S:S, (ROW()-2)*$B8+2):INDEX(neos_benchmark!S:S, (ROW()-2)*$B8 + $B8+1)), "") | T8: =IFERROR(AVERAGE(INDEX(neos_benchmark!T:T, (ROW()-2)*$B8+2):INDEX(neos_benchmark!T:T, (ROW()-2)*$B8 + $B8+1)), "") | U8: =IFERROR(AVERAGE(INDEX(neos_benchmark!U:U, (ROW()-2)*$B8+2):INDEX(neos_benchmark!U:U, (ROW()-2)*$B8 + $B8+1)), "") | V8: =IFERROR(AVERAGE(INDEX(neos_benchmark!V:V, (ROW()-2)*$B8+2):INDEX(neos_benchmark!V:V, (ROW()-2)*$B8 + $B8+1)), "") | W8: =IFERROR(AVERAGE(INDEX(neos_benchmark!W:W, (ROW()-2)*$B8+2):INDEX(neos_benchmark!W:W, (ROW()-2)*$B8 + $B8+1)), "") | X8: =IFERROR(AVERAGE(INDEX(neos_benchmark!X:X, (ROW()-2)*$B8+2):INDEX(neos_benchmark!X:X, (ROW()-2)*$B8 + $B8+1)), "") | Y8: =IFERROR(AVERAGE(INDEX(neos_benchmark!Y:Y, (ROW()-2)*$B8+2):INDEX(neos_benchmark!Y:Y, (ROW()-2)*$B8 + $B8+1)), "") | Z8: =IFERROR(AVERAGE(INDEX(neos_benchmark!Z:Z, (ROW()-2)*$B8+2):INDEX(neos_benchmark!Z:Z, (ROW()-2)*$B8 + $B8+1)), "") | AA8: =IFERROR(AVERAGE(INDEX(neos_benchmark!AA:AA, (ROW()-2)*$B8+2):INDEX(neos_benchmark!AA:AA, (ROW()-2)*$B8 + $B8+1)), "") | AB8: =IFERROR(AVERAGE(INDEX(neos_benchmark!AB:AB, (ROW()-2)*$B8+2):INDEX(neos_benchmark!AB:AB, (ROW()-2)*$B8 + $B8+1)), "") | AC8: =IFERROR(AVERAGE(INDEX(neos_benchmark!AC:AC, (ROW()-2)*$B8+2):INDEX(neos_benchmark!AC:AC, (ROW()-2)*$B8 + $B8+1)), "") | AD8: =IFERROR(AVERAGE(INDEX(neos_benchmark!AD:AD, (ROW()-2)*$B8+2):INDEX(neos_benchmark!AD:AD, (ROW()-2)*$B8 + $B8+1)), "") | AE8: =IFERROR(AVERAGE(INDEX(neos_benchmark!AE:AE, (ROW()-2)*$B8+2):INDEX(neos_benchmark!AE:AE, (ROW()-2)*$B8 + $B8+1)), "") | AF8: =IFERROR(AVERAGE(INDEX(neos_benchmark!AF:AF, (ROW()-2)*$B8+2):INDEX(neos_benchmark!AF:AF, (ROW()-2)*$B8 + $B8+1)), "") | AG8: =IFERROR(AVERAGE(INDEX(neos_benchmark!AG:AG, (ROW()-2)*$B8+2):INDEX(neos_benchmark!AG:AG, (ROW()-2)*$B8 + $B8+1)), "") | AH8: =IFERROR(AVERAGE(INDEX(neos_benchmark!AH:AH, (ROW()-2)*$B8+2):INDEX(neos_benchmark!AH:AH, (ROW()-2)*$B8 + $B8+1)), "") | AI8: =IFERROR(AVERAGE(INDEX(neos_benchmark!AI:AI, (ROW()-2)*$B8+2):INDEX(neos_benchmark!AI:AI, (ROW()-2)*$B8 + $B8+1)), "") -> 864273.1 | AJ8: =IFERROR(AVERAGE(INDEX(neos_benchmark!AJ:AJ, (ROW()-2)*$B8+2):INDEX(neos_benchmark!AJ:AJ, (ROW()-2)*$B8 + $B8+1)), "") -> 904922 | AK8: {=IFERROR(AVERAGE(INDEX(neos_benchmark!W:W, (ROW()-2)*$B8+2):INDEX(neos_benchmark!W:W, (ROW()-2)*$B8 + $B8+1) + INDEX(neos_benchmark!AA:AA, (ROW()-2)*$B8+2):INDEX(neos_benchmark!AA:AA, (ROW()-2)*$B8 + $B8+1)), "")} -> 0 | AL8: {=IFERROR(MIN(INDEX(neos_benchmark!W:W, (ROW()-2)*$B8+2):INDEX(neos_benchmark!W:W, (ROW()-2)*$B8 + $B8+1) + INDEX(neos_benchmark!AA:AA, (ROW()-2)*$B8+2):INDEX(neos_benchmark!AA:AA, (ROW()-2)*$B8 + $B8+1)), "")} -> 0 | AM8: {=IFERROR(MAX(INDEX(neos_benchmark!W:W, (ROW()-2)*$B8+2):INDEX(neos_benchmark!W:W, (ROW()-2)*$B8 + $B8+1) + INDEX(neos_benchmark!AA:AA, (ROW()-2)*$B8+2):INDEX(neos_benchmark!AA:AA, (ROW()-2)*$B8 + $B8+1)), "")} -> 0 | AN8: {=IFERROR(AVERAGE((INDEX(neos_benchmark!AJ:AJ, (ROW()-2)*$B8+2):INDEX(neos_benchmark!AJ:AJ, (ROW()-2)*$B8 + $B8+1) - INDEX(neos_benchmark!AI:AI, (ROW()-2)*$B8+2):INDEX(neos_benchmark!AI:AI, (ROW()-2)*$B8 + $B8+1)) / 1000), "")} -> 40.6489 | AO8: {=IFERROR(MIN((INDEX(neos_benchmark!AJ:AJ, (ROW()-2)*$B8+2):INDEX(neos_benchmark!AJ:AJ, (ROW()-2)*$B8 + $B8+1) - INDEX(neos_benchmark!AI:AI, (ROW()-2)*$B8+2):INDEX(neos_benchmark!AI:AI, (ROW()-2)*$B8 + $B8+1)) / 1000), "")} -> 12.898 | AP8: {=IFERROR(MAX((INDEX(neos_benchmark!AJ:AJ, (ROW()-2)*$B8+2):INDEX(neos_benchmark!AJ:AJ, (ROW()-2)*$B8 + $B8+1) - INDEX(neos_benchmark!AI:AI, (ROW()-2)*$B8+2):INDEX(neos_benchmark!AI:AI, (ROW()-2)*$B8 + $B8+1)) / 1000), "")} -> 73.422
A9: {=INDEX(neos_benchmark!A:A, (ROW()-2)*$B9+2)} -> grasp-conopt | B9: =COUNTIF(neos_benchmark!A:A, neos_benchmark!A9) -> 10 | C9: {=INDEX(neos_benchmark!C:C, (ROW()-2)*$B9+2)} -> CONOPT | D9: {=INDEX(neos_benchmark!D:D, (ROW()-2)*$B9+2)} -> 4.38.1 | E9: {=INDEX(neos_benchmark!E:E, (ROW()-2)*$B9+2)} -> solved? | F9: =IFERROR(AVERAGE(INDEX(neos_benchmark!F:F, (ROW()-2)*$B9+2):INDEX(neos_benchmark!F:F, (ROW()-2)*$B9 + $B9+1)), "") -> 100 | G9: =IFERROR(AVERAGE(INDEX(neos_benchmark!G:G, (ROW()-2)*$B9+2):INDEX(neos_benchmark!G:G, (ROW()-2)*$B9 + $B9+1)), "") -> 6 | H9: =IFERROR(AVERAGE(INDEX(neos_benchmark!H:H, (ROW()-2)*$B9+2):INDEX(neos_benchmark!H:H, (ROW()-2)*$B9 + $B9+1)), "") | I9: =IFERROR(AVERAGE(INDEX(neos_benchmark!I:I, (ROW()-2)*$B9+2):INDEX(neos_benchmark!I:I, (ROW()-2)*$B9 + $B9+1)), "") | J9: =IFERROR(AVERAGE(INDEX(neos_benchmark!J:J, (ROW()-2)*$B9+2):INDEX(neos_benchmark!J:J, (ROW()-2)*$B9 + $B9+1)), "") | K9: =IFERROR(AVERAGE(INDEX(neos_benchmark!K:K, (ROW()-2)*$B9+2):INDEX(neos_benchmark!K:K, (ROW()-2)*$B9 + $B9+1)), "") | L9: =IFERROR(AVERAGE(INDEX(neos_benchmark!L:L, (ROW()-2)*$B9+2):INDEX(neos_benchmark!L:L, (ROW()-2)*$B9 + $B9+1)), "") | M9: =IFERROR(AVERAGE(INDEX(neos_benchmark!M:M, (ROW()-2)*$B9+2):INDEX(neos_benchmark!M:M, (ROW()-2)*$B9 + $B9+1)), "") | N9: =IFERROR(AVERAGE(INDEX(neos_benchmark!N:N, (ROW()-2)*$B9+2):INDEX(neos_benchmark!N:N, (ROW()-2)*$B9 + $B9+1)), "") | O9: =IFERROR(AVERAGE(INDEX(neos_benchmark!O:O, (ROW()-2)*$B9+2):INDEX(neos_benchmark!O:O, (ROW()-2)*$B9 + $B9+1)), "") | P9: =IFERROR(AVERAGE(INDEX(neos_benchmark!P:P, (ROW()-2)*$B9+2):INDEX(neos_benchmark!P:P, (ROW()-2)*$B9 + $B9+1)), "") | Q9: =IFERROR(AVERAGE(INDEX(neos_benchmark!Q:Q, (ROW()-2)*$B9+2):INDEX(neos_benchmark!Q:Q, (ROW()-2)*$B9 + $B9+1)), "") | R9: =IFERROR(AVERAGE(INDEX(neos_benchmark!R:R, (ROW()-2)*$B9+2):INDEX(neos_benchmark!R:R, (ROW()-2)*$B9 + $B9+1)), "") | S9: =IFERROR(AVERAGE(INDEX(neos_benchmark!S:S, (ROW()-2)*$B9+2):INDEX(neos_benchmark!S:S, (ROW()-2)*$B9 + $B9+1)), "") | T9: =IFERROR(AVERAGE(INDEX(neos_benchmark!T:T, (ROW()-2)*$B9+2):INDEX(neos_benchmark!T:T, (ROW()-2)*$B9 + $B9+1)), "") | U9: =IFERROR(AVERAGE(INDEX(neos_benchmark!U:U, (ROW()-2)*$B9+2):INDEX(neos_benchmark!U:U, (ROW()-2)*$B9 + $B9+1)), "") | V9: =IFERROR(AVERAGE(INDEX(neos_benchmark!V:V, (ROW()-2)*$B9+2):INDEX(neos_benchmark!V:V, (ROW()-2)*$B9 + $B9+1)), "") | W9: =IFERROR(AVERAGE(INDEX(neos_benchmark!W:W, (ROW()-2)*$B9+2):INDEX(neos_benchmark!W:W, (ROW()-2)*$B9 + $B9+1)), "") -> 0.1504551 | X9: =IFERROR(AVERAGE(INDEX(neos_benchmark!X:X, (ROW()-2)*$B9+2):INDEX(neos_benchmark!X:X, (ROW()-2)*$B9 + $B9+1)), "") -> 0.0228144 | Y9: =IFERROR(AVERAGE(INDEX(neos_benchmark!Y:Y, (ROW()-2)*$B9+2):INDEX(neos_benchmark!Y:Y, (ROW()-2)*$B9 + $B9+1)), "") -> 0.1314911 | Z9: =IFERROR(AVERAGE(INDEX(neos_benchmark!Z:Z, (ROW()-2)*$B9+2):INDEX(neos_benchmark!Z:Z, (ROW()-2)*$B9 + $B9+1)), "") -> 0.1543055 | AA9: =IFERROR(AVERAGE(INDEX(neos_benchmark!AA:AA, (ROW()-2)*$B9+2):INDEX(neos_benchmark!AA:AA, (ROW()-2)*$B9 + $B9+1)), "") -> 0.0211591 | AB9: =IFERROR(AVERAGE(INDEX(neos_benchmark!AB:AB, (ROW()-2)*$B9+2):INDEX(neos_benchmark!AB:AB, (ROW()-2)*$B9 + $B9+1)), "") -> 0.0032305 | AC9: =IFERROR(AVERAGE(INDEX(neos_benchmark!AC:AC, (ROW()-2)*$B9+2):INDEX(neos_benchmark!AC:AC, (ROW()-2)*$B9 + $B9+1)), "") -> 0.0036042 | AD9: =IFERROR(AVERAGE(INDEX(neos_benchmark!AD:AD, (ROW()-2)*$B9+2):INDEX(neos_benchmark!AD:AD, (ROW()-2)*$B9 + $B9+1)), "") -> 0.0068347 | AE9: =IFERROR(AVERAGE(INDEX(neos_benchmark!AE:AE, (ROW()-2)*$B9+2):INDEX(neos_benchmark!AE:AE, (ROW()-2)*$B9 + $B9+1)), "") -> 29729 | AF9: =IFERROR(AVERAGE(INDEX(neos_benchmark!AF:AF, (ROW()-2)*$B9+2):INDEX(neos_benchmark!AF:AF, (ROW()-2)*$B9 + $B9+1)), "") -> 73 | AG9: =IFERROR(AVERAGE(INDEX(neos_benchmark!AG:AG, (ROW()-2)*$B9+2):INDEX(neos_benchmark!AG:AG, (ROW()-2)*$B9 + $B9+1)), "") -> 29766 | AH9: =IFERROR(AVERAGE(INDEX(neos_benchmark!AH:AH, (ROW()-2)*$B9+2):INDEX(neos_benchmark!AH:AH, (ROW()-2)*$B9 + $B9+1)), "") -> 80 | AI9: =IFERROR(AVERAGE(INDEX(neos_benchmark!AI:AI, (ROW()-2)*$B9+2):INDEX(neos_benchmark!AI:AI, (ROW()-2)*$B9 + $B9+1)), "") -> 493932.6 | AJ9: =IFERROR(AVERAGE(INDEX(neos_benchmark!AJ:AJ, (ROW()-2)*$B9+2):INDEX(neos_benchmark!AJ:AJ, (ROW()-2)*$B9 + $B9+1)), "") -> 508530.8 | AK9: {=IFERROR(AVERAGE(INDEX(neos_benchmark!W:W, (ROW()-2)*$B9+2):INDEX(neos_benchmark!W:W, (ROW()-2)*$B9 + $B9+1) + INDEX(neos_benchmark!AA:AA, (ROW()-2)*$B9+2):INDEX(neos_benchmark!AA:AA, (ROW()-2)*$B9 + $B9+1)), "")} -> 0.1716142 | AL9: {=IFERROR(MIN(INDEX(neos_benchmark!W:W, (ROW()-2)*$B9+2):INDEX(neos_benchmark!W:W, (ROW()-2)*$B9 + $B9+1) + INDEX(neos_benchmark!AA:AA, (ROW()-2)*$B9+2):INDEX(neos_benchmark!AA:AA, (ROW()-2)*$B9 + $B9+1)), "")} -> 0.123309 | AM9: {=IFERROR(MAX(INDEX(neos_benchmark!W:W, (ROW()-2)*$B9+2):INDEX(neos_benchmark!W:W, (ROW()-2)*$B9 + $B9+1) + INDEX(neos_benchmark!AA:AA, (ROW()-2)*$B9+2):INDEX(neos_benchmark!AA:AA, (ROW()-2)*$B9 + $B9+1)), "")} -> 0.361378 | AN9: {=IFERROR(AVERAGE((INDEX(neos_benchmark!AJ:AJ, (ROW()-2)*$B9+2):INDEX(neos_benchmark!AJ:AJ, (ROW()-2)*$B9 + $B9+1) - INDEX(neos_benchmark!AI:AI, (ROW()-2)*$B9+2):INDEX(neos_benchmark!AI:AI, (ROW()-2)*$B9 + $B9+1)) / 1000), "")} -> 14.5982 | AO9: {=IFERROR(MIN((INDEX(neos_benchmark!AJ:AJ, (ROW()-2)*$B9+2):INDEX(neos_benchmark!AJ:AJ, (ROW()-2)*$B9 + $B9+1) - INDEX(neos_benchmark!AI:AI, (ROW()-2)*$B9+2):INDEX(neos_benchmark!AI:AI, (ROW()-2)*$B9 + $B9+1)) / 1000), "")} -> 4.718 | AP9: {=IFERROR(MAX((INDEX(neos_benchmark!AJ:AJ, (ROW()-2)*$B9+2):INDEX(neos_benchmark!AJ:AJ, (ROW()-2)*$B9 + $B9+1) - INDEX(neos_benchmark!AI:AI, (ROW()-2)*$B9+2):INDEX(neos_benchmark!AI:AI, (ROW()-2)*$B9 + $B9+1)) / 1000), "")} -> 35.549
